{"connectionID":4395460171836346365,"event":"systemStatus","status":"online","version":"1.9.0"}
{"channelID":560,"channelName":"book-10","event":"subscriptionStatus","pair":"ETH/USD","status":"subscribed","subscription":{"depth":10,"name":"book"}}
{"channelID":561,"channelName":"trade","event":"subscriptionStatus","pair":"ETH/USD","status":"subscribed","subscription":{"name":"trade"}}
{"channelID":564,"channelName":"ticker","event":"subscriptionStatus","pair":"ETH/USD","status":"subscribed","subscription":{"name":"ticker"}}
{"channelID":567,"channelName":"ohlc-1","event":"subscriptionStatus","pair":"ETH/USD","status":"subscribed","subscription":{"interval":1,"name":"ohlc"}}
{"channelID":565,"channelName":"spread","event":"subscriptionStatus","pair":"ETH/USD","status":"subscribed","subscription":{"name":"spread"}}
[564,{"a":["1283.44000",48,"48.65356418"],"b":["1283.43000",5,"5.67410000"],"c":["1283.44000","0.13935831"],"v":["7496.76509557","14903.90276003"],"p":["1288.92766","1293.19087"],"t":[6912,10929],"l":["1278.00000","1278.00000"],"h":["1300.99000","1308.60000"],"o":["1297.07000","1307.29000"]},"ticker","ETH/USD"]
[567,["1665856323.604412","1665856380.000000","1283.44000","1283.44000","1283.44000","1283.44000","1283.44000","0.13935831",1],"ohlc-1","ETH/USD"]
[565,["1283.43000","1283.44000","1665856325 .437481","5.67410000","48.65356418"],"spread","ETH/USD"]
[560,{"as":[["1283.44000","48.65356418","1665856325.437481"],["1283.45000","0.42700784","1665856291.386182"],["1283.53000","0.42131826","1665856294.892060"],["1283.64000","23.65332267","1665856325.182621"],["1283.65000","54.83362190","1665856300.283142"],["1283.71000","12.07437816","1665856261.860659"],["1283.76000","0.63139718","1665856291.639593"],["1283.79000","8.28092603","1665856325.537724"],["1283.80000","4.45000000","1665856300.427455"],["1283.82000","0.43140585","1665856291.718018"]],"bs":[["1283.43000","5.67410000","1665856324.985065"],["1283.00000","12.08106001","1665856325.414507"],["1282.93000","0.01558619","1665856324.128119"],["1282.90000","58.46114640","1665856325.117058"],["1282.88000","1.46275402","1665856277.874533"],["1282.87000","0.01558692","1665856324.129857"],["1282.86000","6.22500000","1665856325.142256"],["1282.77000","9.30157691","1665856277.952790"],["1282.73000","12.08360294","1665856007.161014"],["1282.69000","116.94140392","1665856030.066982"]]},"book-10","ETH/USD"]
{"event":"heartbeat"}
[560,{"a":[["1283.65000","53.36362190","1665856329.693598"]],"c":"4016798065"},"book-10","ETH/USD"]
[560,{"a":[["1283.80000","0.00000000","1665856329.694211"],["1283.84000","6.22500000","1665856325.008505","r"]],"c":"2790491137"},"book-10","ETH/USD"]
[560,{"b":[["1283.43000","9.25480848","1665856329.948557"]],"c":"836671167"},"book-10","ETH/USD"]
[565,["1283.43000","1283.44000","1665856329.948557","9.25480848","48.65356418"],"spread","ETH/USD"]
[560,{"b":[["1283.43000","5.67410000","1665856329.994873"]],"c":"2790491137"},"book-10","ETH/USD"]
[565,["1283.43000","1283.44000","1665856329.994873","5.67410000","48.65356418"],"spread","ETH/USD"]
[560,{"b":[["1283.43000","10.06896528","1665856330.043194"]],"c":"4167939289"},"book-10","ETH/USD"]
[565,["1283.43000","1283.44000","1665856330.043194","10.06896528","48.65356418"],"spread","ETH/USD"]
[560,{"b":[["1283.43000","5.67410000","1665856330.090521"]],"c":"2790491137"},"book-10","ETH/USD"]
[565,["1283.43000","1283.44000","1665856330.090521","5.67410000","48.65356418"],"spread","ETH/USD"]
[560,{"a":[["1283.64000","0.36332267","1665856330.093027"]],"c":"846145594"},"book-10","ETH/USD"]
{"event":"heartbeat"}
[560,{"a":[["1283.72000","23.29000000","1665856330.358163"]],"c":"1083908980"},"book-10","ETH/USD"]
[560,{"a":[["1283.44000","50.12356418","1665856330.364494"]],"c":"4140554293"},"book-10","ETH/USD"]
[565,["1283.43000","1283.44000","1665856330.364494","5.67410000","50.12356418"],"spread","ETH/USD"]
[560,{"b":[["1283.27000","12.07851816","1665856330.467905"]],"c":"2434054800"},"book-10","ETH/USD"]
[560,{"a":[["1283.57000","4.45000000","1665856330.529561"]],"c":"4072714173"},"book-10","ETH/USD"]
{"event":"heartbeat"}
[560,{"a":[["1283.44000","50.27941511","1665856331.456911"]],"c":"4174890871"},"book-10","ETH/USD"]
[565,["1283.43000","1283.44000","1665856331.456911","5.67410000","50.27941511"],"spread","ETH/USD"]
[560,{"b":[["1283.01000","0.15585093","1665856331.457157"]],"c":"2528948189"},"book-10","ETH/USD"]
[560,{"b":[["1283.43000","9.02832208","1665856331.524117"]],"c":"3340746316"},"book-10","ETH/USD"]
[565,["1283.43000","1283.44000","1665856331.524117","9.02832208","50.27941511"],"spread","ETH/USD"]
[560,{"b":[["1283.43000","5.67410000","1665856331.571718"]],"c":"2528948189"},"book-10","ETH/USD"]
[565,["1283.43000","1283.44000","1665856331.571718","5.67410000","50.27941511"],"spread","ETH/USD"]
{"event":"heartbeat"}
{"event":"heartbeat"}
[560,{"a":[["1283.72000","0.00000000","1665856334.183077"],["1283.82000","0.43140585","1665856291.718018","r"],["1283.56000","23.29000000","1665856334.183095"]],"c":"3836806626"},"book-10","ETH/USD"]
[560,{"b":[["1283.27000","0.00000000","1665856334.253677"],["1282.73000","12.08360294","1665856007.161014","r"]],"c":"1069136827"},"book-10","ETH/USD"]
[560,{"b":[["1283.01000","0.00000000","1665856334.277096"],["1282.69000","116.94140392","1665856030.066982","r"]],"c":"3450005138"},"book-10","ETH/USD"]
[560,{"b":[["1282.91000","0.15584198","1665856334.277264"]],"c":"2968132982"},"book-10","ETH/USD"]
[560,{"b":[["1283.01000","0.15584198","1665856334.300864"]],"c":"1659721400"},"book-10","ETH/USD"]
[560,{"b":[["1282.91000","0.00000000","1665856334.301023"],["1282.73000","12.08360294","1665856007.161014","r"]],"c":"217380273"},"book-10","ETH/USD"]
{"event":"heartbeat"}
{"event":"heartbeat"}
{"event":"heartbeat"}
{"event":"heartbeat"}
{"event":"heartbeat"}
[560,{"a":[["1283.79000","0.00000000","1665856339.239783"],["1283.82000","0.43140585","1665856291.718018","r"]],"c":"3905928953"},"book-10","ETH/USD"]
{"event":"heartbeat"}
{"event":"heartbeat"}
{"event":"heartbeat"}
{"event":"heartbeat"}
{"event":"heartbeat"}
{"event":"heartbeat"}
{"event":"heartbeat"}
{"event":"heartbeat"}
{"event":"heartbeat"}
[560,{"a":[["1283.56000","0.00000000","1665856348.173585"],["1283.83000","8.43045421","1665856339.438056","r"],["1283.53000","23.71131826","1665856348.173603"]],"c":"1450977196"},"book-10","ETH/USD"]
[560,{"a":[["1283.71000","13.12783103","1665856348.255839"]],"c":"2054256954"},"book-10","ETH/USD"]
{"event":"heartbeat"}
{"event":"heartbeat"}
{"event":"heartbeat"}
{"event":"heartbeat"}
{"event":"heartbeat"}
{"event":"heartbeat"}
{"event":"heartbeat"}
{"event":"heartbeat"}
[560,{"b":[["1282.88000","0.00000000","1665856355.470044"],["1282.69000","116.94140392","1665856030.066982","r"]],"c":"1456368355"},"book-10","ETH/USD"]
{"event":"heartbeat"}
{"event":"heartbeat"}
{"event":"heartbeat"}
{"event":"heartbeat"}
[560,{"a":[["1283.83000","0.00000000","1665856359.668835"],["1283.84000","6.22500000","1665856325.008505","r"]],"c":"1270283960"},"book-10","ETH/USD"]
[560,{"a":[["1283.83000","8.51851057","1665856359.864434"]],"c":"2252766874"},"book-10","ETH/USD"]
{"event":"heartbeat"}
{"event":"heartbeat"}
{"event":"heartbeat"}
{"event":"heartbeat"}
{"event":"heartbeat"}
{"event":"heartbeat"}
[560,{"a":[["1283.65000","59.58862190","1665856365.518281"]],"c":"2052155505"},"book-10","ETH/USD"]
{"event":"heartbeat"}
{"event":"heartbeat"}
{"event":"heartbeat"}
{"event":"heartbeat"}
{"event":"heartbeat"}
[560,{"b":[["1282.70000","2.87775523","1665856371.191718"]],"c":"1644777712"},"book-10","ETH/USD"]
[560,{"a":[["1283.52000","2.72003254","1665856371.191745"]],"c":"396941433"},"book-10","ETH/USD"]
{"event":"heartbeat"}
{"event":"heartbeat"}
{"event":"heartbeat"}
{"event":"heartbeat"}
{"event":"heartbeat"}
[560,{"a":[["1283.57000","0.00000000","1665856376.253579"],["1283.83000","8.51851057","1665856359.864434","r"]],"c":"517305522"},"book-10","ETH/USD"]
[560,{"a":[["1283.44000","48.80941511","1665856376.253704"]],"c":"1922429369"},"book-10","ETH/USD"]
[565,["1283.43000","1283.44000","1665856376.253704","5.67410000","48.80941511"],"spread","ETH/USD"]
{"event":"heartbeat"}
{"event":"heartbeat"}
[560,{"a":[["1283.44000","54.72941511","1665856378.307985"]],"c":"696672392"},"book-10","ETH/USD"]
[565,["1283.43000","1283.44000","1665856378.307985","5.67410000","54.72941511"],"spread","ETH/USD"]
{"event":"heartbeat"}
[560,{"a":[["1283.79000","15.63000000","1665856378.472904"]],"c":"1204940053"},"book-10","ETH/USD"]
[561,[["1283.44000","0.22914096","1665856379.238939","b","l",""]],"trade","ETH/USD"]
[564,{"a":["1283.44000",54,"54.50027415"],"b":["1283.43000",5,"5.67410000"],"c":["1283.44000","0.22914096"],"v":["7496.99423653","14904.13190099"],"p":["1288.92750","1293.19072"],"t":[6913,10930],"l":["1278.00000","1278.00000"],"h":["1300.99000","1308.60000"],"o":["1297.07000","1307.29000"]},"ticker","ETH/USD"]
[567,["1665856379.238939","1665856380.000000","1283.44000","1283.44000","1283.44000","1283.44000","1283.44000","0.36849927",2],"ohlc-1","ETH/USD"]
[560,{"a":[["1283.44000","54.50027415","1665856379.238939"]],"c":"3995611437"},"book-10","ETH/USD"]
[565,["1283.43000","1283.44000","1665856379.238939","5.67410000","54.50027415"],"spread","ETH/USD"]
{"event":"heartbeat"}
{"event":"heartbeat"}
[560,{"b":[["1283.43000","0.00000000","1665856381.047272"],["1282.69000","116.94140392","1665856030.066982","r"]],"c":"543718305"},"book-10","ETH/USD"]
[565,["1283.01000","1283.44000","1665856379.238939","0.15584198","54.50027415"],"spread","ETH/USD"]
[560,{"a":[["1283.43000","0.15586201","1665856381.071066"]],"c":"3758454382"},"book-10","ETH/USD"]
[565,["1283.01000","1283.43000","1665856381.071066","0.15584198","0.15586201"],"spread","ETH/USD"]
[560,{"a":[["1283.44000","54.34442322","1665856381.071313"]],"c":"3722569981"},"book-10","ETH/USD"]
[560,{"b":[["1283.01000","1.15584198","1665856381.072596"]],"c":"3508063185"},"book-10","ETH/USD"]
[565,["1283.01000","1283.43000","1665856381.072596","1.15584198","0.15586201"],"spread","ETH/USD"]
[560,{"b":[["1283.01000","6.15584198","1665856381.072828"]],"c":"1867279958"},"book-10","ETH/USD"]
[565,["1283.01000","1283.43000","1665856381.072828","6.15584198","0.15586201"],"spread","ETH/USD"]
[560,{"a":[["1283.52000","0.00000000","1665856381.094100"],["1283.82000","0.43140585","1665856291.718018","r"]],"c":"3569467172"},"book-10","ETH/USD"]
[560,{"a":[["1283.44000","49.48442322","1665856381.094993"]],"c":"2499324418"},"book-10","ETH/USD"]
[560,{"a":[["1283.43000","0.52808313","1665856381.095833"]],"c":"3893663478"},"book-10","ETH/USD"]
[565,["1283.01000","1283.43000","1665856381.095833","6.15584198","0.52808313"],"spread","ETH/USD"]
[560,{"b":[["1283.02000","0.15586201","1665856381.099938"]],"c":"3963869012"},"book-10","ETH/USD"]
[565,["1283.02000","1283.43000","1665856381.099938","0.15586201","0.52808313"],"spread","ETH/USD"]
[560,{"b":[["1283.01000","8.30312822","1665856381.099979"]],"c":"1942478040"},"book-10","ETH/USD"]
[560,{"b":[["1283.01000","8.14728624","1665856381.099996"]],"c":"2031642742"},"book-10","ETH/USD"]
[560,{"b":[["1283.02000","0.55307276","1665856381.100703"]],"c":"3531553679"},"book-10","ETH/USD"]
[565,["1283.02000","1283.43000","1665856381.100703","0.55307276","0.52808313"],"spread","ETH/USD"]
[560,{"a":[["1283.43000","5.51808313","1665856381.100941"]],"c":"3388192250"},"book-10","ETH/USD"]
[565,["1283.02000","1283.43000","1665856381.100941","0.55307276","5.51808313"],"spread","ETH/USD"]
[560,{"b":[["1283.02000","0.92867486","1665856381.100996"]],"c":"4013915903"},"book-10","ETH/USD"]
[565,["1283.02000","1283.43000","1665856381.100996","0.92867486","5.51808313"],"spread","ETH/USD"]
[560,{"a":[["1283.63000","15.55800000","1665856381.106916"]],"c":"728245714"},"book-10","ETH/USD"]
[560,{"a":[["1283.42000","0.42421920","1665856381.120550"]],"c":"409051507"},"book-10","ETH/USD"]
[565,["1283.02000","1283.42000","1665856381.120550","0.92867486","0.42421920"],"spread","ETH/USD"]
[560,{"a":[["1283.42000","0.58008121","1665856381.125090"]],"c":"1224843099"},"book-10","ETH/USD"]
[565,["1283.02000","1283.42000","1665856381.125090","0.92867486","0.58008121"],"spread","ETH/USD"]
[560,{"a":[["1283.43000","5.36222112","1665856381.125298"]],"c":"3303497417"},"book-10","ETH/USD"]
[560,{"a":[["1283.44000","44.01356418","1665856381.126127"]],"c":"4094761041"},"book-10","ETH/USD"]
[560,{"a":[["1283.37000","5.70000000","1665856381.126751"]],"c":"3441680385"},"book-10","ETH/USD"]
[565,["1283.02000","1283.37000","1665856381.126751","0.92867486","5.70000000"],"spread","ETH/USD"]
[560,{"a":[["1283.44000","20.72356418","1665856381.145588"],["1283.42000","23.87008121","1665856381.145607"]],"c":"3449705117"},"book-10","ETH/USD"]
[560,{"b":[["1283.02000","2.22168470","1665856381.149344"]],"c":"2892084736"},"book-10","ETH/USD"]
[565,["1283.02000","1283.37000","1665856381.149344","2.22168470","5.70000000"],"spread","ETH/USD"]
[560,{"a":[["1283.36000","0.15586201","1665856381.149934"]],"c":"3233522883"},"book-10","ETH/USD"]
[565,["1283.02000","1283.36000","1665856381.149934","2.22168470","0.15586201"],"spread","ETH/USD"]
[560,{"a":[["1283.42000","23.71421920","1665856381.149961"]],"c":"150476556"},"book-10","ETH/USD"]
[560,{"a":[["1283.41000","0.06243872","1665856381.170081"]],"c":"2712643440"},"book-10","ETH/USD"]
[560,{"a":[["1283.44000","17.99691828","1665856381.203694"],["1283.35000","2.72664590","1665856381.203712"]],"c":"444323928"},"book-10","ETH/USD"]
[565,["1283.02000","1283.35000","1665856381.203712","2.22168470","2.72664590"],"spread","ETH/USD"]
[560,{"b":[["1283.03000","1.00000000","1665856381.228668"]],"c":"389189611"},"book-10","ETH/USD"]
[565,["1283.03000","1283.35000","1665856381.228668","1.00000000","2.72664590"],"spread","ETH/USD"]
[560,{"b":[["1283.03000","4.13140032","1665856381.280783"]],"c":"1443861344"},"book-10","ETH/USD"]
[565,["1283.03000","1283.35000","1665856381.280783","4.13140032","2.72664590"],"spread","ETH/USD"]
[560,{"b":[["1283.02000","2.06582269","1665856381.304173"]],"c":"4124727994"},"book-10","ETH/USD"]
[560,{"b":[["1283.04000","0.15586201","1665856381.304212"]],"c":"760279121"},"book-10","ETH/USD"]
[565,["1283.04000","1283.35000","1665856381.304212","0.15586201","2.72664590"],"spread","ETH/USD"]
[560,{"b":[["1283.01000","7.14728624","1665856381.305417"]],"c":"1248462108"},"book-10","ETH/USD"]
[560,{"b":[["1283.04000","5.15586201","1665856381.306728"]],"c":"228717108"},"book-10","ETH/USD"]
[565,["1283.04000","1283.35000","1665856381.306728","5.15586201","2.72664590"],"spread","ETH/USD"]
[560,{"b":[["1283.04000","5.00000000","1665856381.330019"]],"c":"877787407"},"book-10","ETH/USD"]
[565,["1283.04000","1283.35000","1665856381.330019","5.00000000","2.72664590"],"spread","ETH/USD"]
[560,{"b":[["1283.05000","0.15586201","1665856381.330133"]],"c":"2898302618"},"book-10","ETH/USD"]
[565,["1283.05000","1283.35000","1665856381.330133","0.15586201","2.72664590"],"spread","ETH/USD"]
{"event":"heartbeat"}
[560,{"b":[["1283.04000","7.42296256","1665856381.354596"]],"c":"3689353007"},"book-10","ETH/USD"]
[560,{"b":[["1283.05000","3.69646553","1665856381.379020"]],"c":"532917752"},"book-10","ETH/USD"]
[565,["1283.05000","1283.35000","1665856381.379020","3.69646553","2.72664590"],"spread","ETH/USD"]
[560,{"b":[["1283.01000","5.00000000","1665856381.383743"]],"c":"393730645"},"book-10","ETH/USD"]
[560,{"b":[["1283.04000","2.42296256","1665856381.404705"]],"c":"2215407781"},"book-10","ETH/USD"]
[560,{"b":[["1283.06000","5.00000000","1665856381.404790"]],"c":"1641728234"},"book-10","ETH/USD"]
[565,["1283.06000","1283.35000","1665856381.404790","5.00000000","2.72664590"],"spread","ETH/USD"]
[560,{"b":[["1283.06000","6.00000000","1665856381.404975"]],"c":"1422291059"},"book-10","ETH/USD"]
[565,["1283.06000","1283.35000","1665856381.404975","6.00000000","2.72664590"],"spread","ETH/USD"]
[560,{"b":[["1283.07000","0.15586201","1665856381.428531"]],"c":"2595035096"},"book-10","ETH/USD"]
[565,["1283.07000","1283.35000","1665856381.428531","0.15586201","2.72664590"],"spread","ETH/USD"]
[560,{"b":[["1283.05000","3.54060352","1665856381.428693"]],"c":"2239112551"},"book-10","ETH/USD"]
[560,{"b":[["1283.01000","0.00000000","1665856381.453862"],["1282.87000","0.01558692","1665856324.129857","r"]],"c":"1130938869"},"book-10","ETH/USD"]
[560,{"b":[["1283.03000","3.13140032","1665856381.454563"]],"c":"3490823363"},"book-10","ETH/USD"]
[560,{"b":[["1283.02000","0.77281285","1665856381.457705"]],"c":"16788930"},"book-10","ETH/USD"]
[560,{"b":[["1283.06000","7.92111248","1665856381.457775"]],"c":"2716570178"},"book-10","ETH/USD"]
[560,{"b":[["1283.07000","1.48014065","1665856381.476664"]],"c":"2041554342"},"book-10","ETH/USD"]
[565,["1283.07000","1283.35000","1665856381.476664","1.48014065","2.72664590"],"spread","ETH/USD"]
[560,{"b":[["1283.03000","0.00000000","1665856381.483651"],["1282.86000","6.22500000","1665856325.142256","r"]],"c":"248532543"},"book-10","ETH/USD"]
[560,{"b":[["1283.08000","1.00000000","1665856381.502520"]],"c":"3699269420"},"book-10","ETH/USD"]
[565,["1283.08000","1283.35000","1665856381.502520","1.00000000","2.72664590"],"spread","ETH/USD"]
[560,{"b":[["1283.08000","3.75601504","1665856381.550146"]],"c":"2423181841"},"book-10","ETH/USD"]
[565,["1283.08000","1283.35000","1665856381.550146","3.75601504","2.72664590"],"spread","ETH/USD"]
[560,{"b":[["1283.06000","6.92111248","1665856381.560227"]],"c":"3976964097"},"book-10","ETH/USD"]
[560,{"b":[["1283.04000","0.00000000","1665856381.565713"],["1282.86000","6.22500000","1665856325.142256","r"]],"c":"1110126701"},"book-10","ETH/USD"]
[560,{"b":[["1283.07000","1.32427864","1665856381.573453"]],"c":"3794018644"},"book-10","ETH/USD"]
[560,{"b":[["1283.09000","5.00000000","1665856381.574514"]],"c":"1170351130"},"book-10","ETH/USD"]
[565,["1283.09000","1283.35000","1665856381.574514","5.00000000","2.72664590"],"spread","ETH/USD"]
[560,{"b":[["1283.09000","5.15586201","1665856381.575850"]],"c":"3061505529"},"book-10","ETH/USD"]
[565,["1283.09000","1283.35000","1665856381.575850","5.15586201","2.72664590"],"spread","ETH/USD"]
[560,{"a":[["1283.35000","5.47889537","1665856381.596372"]],"c":"2340839638"},"book-10","ETH/USD"]
[565,["1283.09000","1283.35000","1665856381.596372","5.15586201","5.47889537"],"spread","ETH/USD"]
[560,{"b":[["1283.10000","0.15586201","1665856381.597723"]],"c":"2670009576"},"book-10","ETH/USD"]
[565,["1283.10000","1283.35000","1665856381.597723","0.15586201","5.47889537"],"spread","ETH/USD"]
[560,{"b":[["1283.09000","5.00000000","1665856381.598147"]],"c":"1968272336"},"book-10","ETH/USD"]
[560,{"b":[["1283.03000","3.40028013","1665856381.599913"]],"c":"2748097786"},"book-10","ETH/USD"]
[560,{"a":[["1283.37000","0.00000000","1665856381.619843"],["1283.64000","0.36332267","1665856330.093027","r"]],"c":"874860207"},"book-10","ETH/USD"]
[560,{"a":[["1283.36000","0.00000000","1665856381.619863"],["1283.65000","59.58862190","1665856365.518281","r"]],"c":"2069400424"},"book-10","ETH/USD"]
[560,{"a":[["1283.34000","0.15586201","1665856381.619954"]],"c":"2433089117"},"book-10","ETH/USD"]
[565,["1283.10000","1283.34000","1665856381.619954","0.15586201","0.15586201"],"spread","ETH/USD"]
[560,{"a":[["1283.29000","5.70000000","1665856381.621008"]],"c":"2635333367"},"book-10","ETH/USD"]
[565,["1283.10000","1283.29000","1665856381.621008","0.15586201","5.70000000"],"spread","ETH/USD"]
[560,{"b":[["1283.06000","1.92111248","1665856381.621450"]],"c":"241861569"},"book-10","ETH/USD"]
[560,{"b":[["1283.10000","1.15586201","1665856381.621485"]],"c":"1746089410"},"book-10","ETH/USD"]
[565,["1283.10000","1283.29000","1665856381.621485","1.15586201","5.70000000"],"spread","ETH/USD"]
[560,{"b":[["1283.09000","7.17153152","1665856381.625204"]],"c":"3931706672"},"book-10","ETH/USD"]
[560,{"b":[["1283.05000","0.00000000","1665856381.625377"],["1282.90000","58.46114640","1665856325.117058","r"]],"c":"3969174334"},"book-10","ETH/USD"]
[560,{"a":[["1283.34000","0.00000000","1665856381.645840"],["1283.64000","0.36332267","1665856330.093027","r"]],"c":"3187055294"},"book-10","ETH/USD"]
[560,{"a":[["1283.28000","0.15586201","1665856381.645897"]],"c":"1060150754"},"book-10","ETH/USD"]
[565,["1283.10000","1283.28000","1665856381.645897","1.15586201","0.15586201"],"spread","ETH/USD"]
[560,{"b":[["1283.10000","4.61866745","1665856381.645940"]],"c":"2654976952"},"book-10","ETH/USD"]
[565,["1283.10000","1283.28000","1665856381.645940","4.61866745","0.15586201"],"spread","ETH/USD"]
[560,{"a":[["1283.35000","2.75224947","1665856381.660371"],["1283.28000","2.88250791","1665856381.660385"]],"c":"2440373688"},"book-10","ETH/USD"]
[565,["1283.10000","1283.28000","1665856381.660385","4.61866745","2.88250791"],"spread","ETH/USD"]
[560,{"b":[["1283.06000","0.00000000","1665856381.660939"],["1282.87000","0.01558692","1665856324.129857","r"]],"c":"529125111"},"book-10","ETH/USD"]
[560,{"b":[["1283.11000","0.15586201","1665856381.669797"]],"c":"1428679704"},"book-10","ETH/USD"]
[565,["1283.11000","1283.28000","1665856381.669797","0.15586201","2.88250791"],"spread","ETH/USD"]
[560,{"b":[["1283.10000","4.46280544","1665856381.670005"]],"c":"2490027360"},"book-10","ETH/USD"]
[560,{"b":[["1283.08000","2.75601504","1665856381.671712"]],"c":"2515708808"},"book-10","ETH/USD"]
[560,{"a":[["1283.42000","0.42421920","1665856381.704363"],["1283.27000","23.29000000","1665856381.704377"]],"c":"679122827"},"book-10","ETH/USD"]
[565,["1283.11000","1283.27000","1665856381.704377","0.15586201","23.29000000"],"spread","ETH/USD"]
[560,{"b":[["1283.11000","2.32318345","1665856381.722870"]],"c":"588336856"},"book-10","ETH/USD"]
[565,["1283.11000","1283.27000","1665856381.722870","2.32318345","23.29000000"],"spread","ETH/USD"]
[560,{"a":[["1283.26000","0.15586201","1665856381.728064"]],"c":"374672678"},"book-10","ETH/USD"]
[565,["1283.11000","1283.26000","1665856381.728064","2.32318345","0.15586201"],"spread","ETH/USD"]
[560,{"a":[["1283.28000","2.72664590","1665856381.728116"]],"c":"2283035586"},"book-10","ETH/USD"]
[560,{"b":[["1283.07000","0.00000000","1665856381.728171"],["1282.87000","0.01558692","1665856324.129857","r"]],"c":"3767254487"},"book-10","ETH/USD"]
[560,{"b":[["1283.11000","7.32318345","1665856381.729782"]],"c":"3234471662"},"book-10","ETH/USD"]
[565,["1283.11000","1283.26000","1665856381.729782","7.32318345","0.15586201"],"spread","ETH/USD"]
[560,{"a":[["1283.28000","0.00000000","1665856381.744368"],["1283.53000","23.71131826","1665856348.173603","r"],["1283.26000","2.88250791","1665856381.744383"]],"c":"1009304701"},"book-10","ETH/USD"]
[565,["1283.11000","1283.26000","1665856381.744383","7.32318345","2.88250791"],"spread","ETH/USD"]
[560,{"b":[["1283.11000","7.16732144","1665856381.767575"]],"c":"1450414167"},"book-10","ETH/USD"]
[565,["1283.11000","1283.26000","1665856381.767575","7.16732144","2.88250791"],"spread","ETH/USD"]
[560,{"b":[["1283.12000","0.15586201","1665856381.767787"]],"c":"1586659642"},"book-10","ETH/USD"]
[565,["1283.12000","1283.26000","1665856381.767787","0.15586201","2.88250791"],"spread","ETH/USD"]
[560,{"b":[["1283.09000","2.17153152","1665856381.768740"]],"c":"1500216434"},"book-10","ETH/USD"]
[560,{"b":[["1283.12000","1.15586201","1665856381.769238"]],"c":"2476130978"},"book-10","ETH/USD"]
[565,["1283.12000","1283.26000","1665856381.769238","1.15586201","2.88250791"],"spread","ETH/USD"]
[560,{"b":[["1283.12000","1.00000000","1665856381.791180"]],"c":"581229453"},"book-10","ETH/USD"]
[565,["1283.12000","1283.26000","1665856381.791180","1.00000000","2.88250791"],"spread","ETH/USD"]
[560,{"b":[["1283.09000","2.32739353","1665856381.791418"]],"c":"3052692526"},"book-10","ETH/USD"]
[560,{"b":[["1283.09000","2.17153152","1665856381.814624"]],"c":"581229453"},"book-10","ETH/USD"]
[560,{"b":[["1283.01000","0.15586201","1665856381.814715"]],"c":"3358425547"},"book-10","ETH/USD"]
[560,{"b":[["1283.01000","0.00000000","1665856381.814787"],["1282.90000","58.46114640","1665856325.117058","r"]],"c":"581229453"},"book-10","ETH/USD"]
[560,{"b":[["1283.12000","4.13240576","1665856381.817222"]],"c":"3893957493"},"book-10","ETH/USD"]
[565,["1283.12000","1283.26000","1665856381.817222","4.13240576","2.88250791"],"spread","ETH/USD"]
[560,{"b":[["1283.08000","0.00000000","1665856381.817368"],["1282.87000","0.01558692","1665856324.129857","r"]],"c":"1307367725"},"book-10","ETH/USD"]
[560,{"b":[["1283.01000","0.15586201","1665856381.838609"]],"c":"1666669123"},"book-10","ETH/USD"]
[560,{"b":[["1283.01000","0.00000000","1665856381.840527"],["1282.87000","0.01558692","1665856324.129857","r"]],"c":"1307367725"},"book-10","ETH/USD"]
[560,{"b":[["1283.11000","7.32318345","1665856381.840657"]],"c":"1566032218"},"book-10","ETH/USD"]
[560,{"b":[["1282.93000","0.00000000","1665856381.936272"],["1282.86000","6.22500000","1665856325.142256","r"]],"c":"676592543"},"book-10","ETH/USD"]
[560,{"b":[["1283.13000","5.00000000","1665856381.961385"]],"c":"975551163"},"book-10","ETH/USD"]
[565,["1283.13000","1283.26000","1665856381.961385","5.00000000","2.88250791"],"spread","ETH/USD"]
[560,{"b":[["1283.10000","3.46280544","1665856381.962094"]],"c":"1055689251"},"book-10","ETH/USD"]
[560,{"b":[["1283.11000","7.16732144","1665856381.984812"]],"c":"1700498110"},"book-10","ETH/USD"]
[560,{"b":[["1283.13000","5.15586201","1665856381.984848"]],"c":"3563688849"},"book-10","ETH/USD"]
[565,["1283.13000","1283.26000","1665856381.984848","5.15586201","2.88250791"],"spread","ETH/USD"]
[560,{"b":[["1283.13000","5.00000000","1665856382.007999"]],"c":"1700498110"},"book-10","ETH/USD"]
[565,["1283.13000","1283.26000","1665856382.007999","5.00000000","2.88250791"],"spread","ETH/USD"]
[560,{"b":[["1283.10000","0.00000000","1665856382.010076"],["1282.86000","6.22500000","1665856325.142256","r"]],"c":"4115028389"},"book-10","ETH/USD"]
[560,{"b":[["1283.13000","8.13357408","1665856382.010229"]],"c":"4061894147"},"book-10","ETH/USD"]
[565,["1283.13000","1283.26000","1665856382.010229","8.13357408","2.88250791"],"spread","ETH/USD"]
[560,{"b":[["1283.09000","0.00000000","1665856382.011676"],["1282.77000","9.30157691","1665856277.952790","r"]],"c":"411038152"},"book-10","ETH/USD"]
[560,{"b":[["1283.11000","2.16732144","1665856382.016328"]],"c":"3167016452"},"book-10","ETH/USD"]
[560,{"b":[["1282.81000","0.01558765","1665856382.025677"]],"c":"509942866"},"book-10","ETH/USD"]
[560,{"a":[["1283.26000","7.87250791","1665856382.030937"]],"c":"1167199458"},"book-10","ETH/USD"]
[565,["1283.13000","1283.26000","1665856382.030937","8.13357408","7.87250791"],"spread","ETH/USD"]
[560,{"b":[["1283.04000","0.15586201","1665856382.031725"]],"c":"351963890"},"book-10","ETH/USD"]
[560,{"a":[["1283.43000","0.37222112","1665856382.032588"]],"c":"566220908"},"book-10","ETH/USD"]
[560,{"b":[["1283.14000","1.00000000","1665856382.041199"]],"c":"1273893307"},"book-10","ETH/USD"]
[565,["1283.14000","1283.26000","1665856382.041199","1.00000000","7.87250791"],"spread","ETH/USD"]
[560,{"a":[["1283.26000","7.71664590","1665856382.054228"]],"c":"1478532873"},"book-10","ETH/USD"]
[565,["1283.14000","1283.26000","1665856382.054228","1.00000000","7.71664590"],"spread","ETH/USD"]
[560,{"a":[["1283.25000","0.15586201","1665856382.054287"]],"c":"350044516"},"book-10","ETH/USD"]
[565,["1283.14000","1283.25000","1665856382.054287","1.00000000","0.15586201"],"spread","ETH/USD"]
[560,{"a":[["1283.25000","0.19586201","1665856382.064630"]],"c":"2246733910"},"book-10","ETH/USD"]
[565,["1283.14000","1283.25000","1665856382.064630","1.00000000","0.19586201"],"spread","ETH/USD"]
[560,{"a":[["1283.24000","0.04000000","1665856382.086455"]],"c":"1087656263"},"book-10","ETH/USD"]
[565,["1283.14000","1283.24000","1665856382.086455","1.00000000","0.04000000"],"spread","ETH/USD"]
[560,{"b":[["1283.14000","2.53911008","1665856382.088427"]],"c":"2033134755"},"book-10","ETH/USD"]
[565,["1283.14000","1283.24000","1665856382.088427","2.53911008","0.04000000"],"spread","ETH/USD"]
[560,{"a":[["1283.26000","4.99000000","1665856382.093035"],["1283.24000","2.76664590","1665856382.093049"]],"c":"4188010483"},"book-10","ETH/USD"]
[565,["1283.14000","1283.24000","1665856382.093049","2.53911008","2.76664590"],"spread","ETH/USD"]
[560,{"b":[["1283.12000","3.13240576","1665856382.112598"]],"c":"2833824937"},"book-10","ETH/USD"]
[560,{"a":[["1283.24000","0.04000000","1665856382.204282"],["1283.26000","7.71664590","1665856382.204298"]],"c":"676882425"},"book-10","ETH/USD"]
[565,["1283.14000","1283.24000","1665856382.204282","2.53911008","0.04000000"],"spread","ETH/USD"]
[560,{"b":[["1283.15000","5.00000000","1665856382.228997"]],"c":"3298974024"},"book-10","ETH/USD"]
[565,["1283.15000","1283.24000","1665856382.228997","5.00000000","0.04000000"],"spread","ETH/USD"]
[560,{"b":[["1283.04000","0.00000000","1665856382.252303"],["1282.87000","0.01558692","1665856324.129857","r"]],"c":"2693240960"},"book-10","ETH/USD"]
[560,{"b":[["1283.14000","2.69497209","1665856382.252491"]],"c":"2980595328"},"book-10","ETH/USD"]
[560,{"a":[["1283.27000","0.00000000","1665856382.273091"],["1283.45000","0.42700784","1665856291.386182","r"],["1283.25000","23.48586201","1665856382.273105"]],"c":"2251151532"},"book-10","ETH/USD"]
[560,{"b":[["1283.14000","2.53911008","1665856382.276171"]],"c":"2533492396"},"book-10","ETH/USD"]
[560,{"b":[["1283.15000","5.15586201","1665856382.276274"]],"c":"640688003"},"book-10","ETH/USD"]
[565,["1283.15000","1283.24000","1665856382.276274","5.15586201","0.04000000"],"spread","ETH/USD"]
[560,{"b":[["1283.15000","6.90521385","1665856382.278766"]],"c":"2650749431"},"book-10","ETH/USD"]
[565,["1283.15000","1283.24000","1665856382.278766","6.90521385","0.04000000"],"spread","ETH/USD"]
[560,{"a":[["1283.24000","0.19586201","1665856382.296659"]],"c":"1467061295"},"book-10","ETH/USD"]
[565,["1283.15000","1283.24000","1665856382.296659","6.90521385","0.19586201"],"spread","ETH/USD"]
[560,{"a":[["1283.25000","23.33000000","1665856382.296789"]],"c":"2124524803"},"book-10","ETH/USD"]
[560,{"b":[["1283.15000","6.74935184","1665856382.299794"]],"c":"2725239832"},"book-10","ETH/USD"]
[565,["1283.15000","1283.24000","1665856382.299794","6.74935184","0.19586201"],"spread","ETH/USD"]
[560,{"b":[["1283.11000","0.00000000","1665856382.301101"],["1282.86000","6.22500000","1665856325.142256","r"]],"c":"1656916617"},"book-10","ETH/USD"]
[560,{"a":[["1283.24000","0.04000000","1665856382.324112"]],"c":"2823563089"},"book-10","ETH/USD"]
[565,["1283.15000","1283.24000","1665856382.324112","6.74935184","0.04000000"],"spread","ETH/USD"]
{"event":"heartbeat"}
[560,{"b":[["1283.13000","3.13357408","1665856382.516209"]],"c":"3227097502"},"book-10","ETH/USD"]
[560,{"a":[["1283.29000","0.00000000","1665856382.531660"],["1283.53000","23.71131826","1665856348.173603","r"]],"c":"2382228898"},"book-10","ETH/USD"]
[560,{"a":[["1283.25000","29.03000000","1665856382.532236"]],"c":"1968526751"},"book-10","ETH/USD"]
[560,{"b":[["1283.16000","1.00000000","1665856382.541404"]],"c":"4215627766"},"book-10","ETH/USD"]
[565,["1283.16000","1283.24000","1665856382.541404","1.00000000","0.04000000"],"spread","ETH/USD"]
[560,{"b":[["1283.16000","3.03376432","1665856382.591573"]],"c":"380736907"},"book-10","ETH/USD"]
[565,["1283.16000","1283.24000","1665856382.591573","3.03376432","0.04000000"],"spread","ETH/USD"]
[560,{"b":[["1283.12000","0.00000000","1665856382.607196"],["1282.86000","6.22500000","1665856325.142256","r"]],"c":"255037743"},"book-10","ETH/USD"]
[560,{"b":[["1283.14000","1.53911008","1665856382.615633"]],"c":"3665137236"},"book-10","ETH/USD"]
[560,{"b":[["1283.17000","5.00000000","1665856382.616139"]],"c":"1286799290"},"book-10","ETH/USD"]
[565,["1283.17000","1283.24000","1665856382.616139","5.00000000","0.04000000"],"spread","ETH/USD"]
[560,{"b":[["1283.16000","1.00000000","1665856382.817949"]],"c":"4193754075"},"book-10","ETH/USD"]
[560,{"b":[["1283.17000","0.00000000","1665856382.842541"],["1282.86000","6.22500000","1665856325.142256","r"]],"c":"931218473"},"book-10","ETH/USD"]
[565,["1283.16000","1283.24000","1665856382.817949","1.00000000","0.04000000"],"spread","ETH/USD"]
[560,{"b":[["1283.18000","1.00000000","1665856382.843987"]],"c":"3510012183"},"book-10","ETH/USD"]
[565,["1283.18000","1283.24000","1665856382.843987","1.00000000","0.04000000"],"spread","ETH/USD"]
[560,{"b":[["1282.95000","0.01558595","1665856382.955952"]],"c":"2117694355"},"book-10","ETH/USD"]
[560,{"b":[["1283.14000","0.00000000","1665856382.959445"],["1282.87000","0.01558692","1665856324.129857","r"]],"c":"1590606370"},"book-10","ETH/USD"]
[560,{"b":[["1283.15000","5.00000000","1665856382.960786"]],"c":"3838185724"},"book-10","ETH/USD"]
[560,{"b":[["1283.18000","0.00000000","1665856383.059317"],["1282.86000","6.22500000","1665856325.142256","r"]],"c":"4210788344"},"book-10","ETH/USD"]
[565,["1283.16000","1283.24000","1665856382.817949","1.00000000","0.04000000"],"spread","ETH/USD"]
[560,{"a":[["1283.24000","5.03000000","1665856383.079463"]],"c":"3727570144"},"book-10","ETH/USD"]
[565,["1283.16000","1283.24000","1665856383.079463","1.00000000","5.03000000"],"spread","ETH/USD"]
[560,{"a":[["1283.25000","23.33000000","1665856383.083044"]],"c":"1924686609"},"book-10","ETH/USD"]
[560,{"a":[["1283.26000","2.72664590","1665856383.083422"]],"c":"1869404181"},"book-10","ETH/USD"]
[560,{"a":[["1283.24000","10.73000000","1665856383.083542"]],"c":"1349226549"},"book-10","ETH/USD"]
[565,["1283.16000","1283.24000","1665856383.083542","1.00000000","10.73000000"],"spread","ETH/USD"]
[560,{"a":[["1283.25000","0.04000000","1665856383.123636"],["1283.23000","23.29000000","1665856383.123657"]],"c":"4234464232"},"book-10","ETH/USD"]
[565,["1283.16000","1283.23000","1665856383.123657","1.00000000","23.29000000"],"spread","ETH/USD"]
[560,{"b":[["1283.02000","0.39721075","1665856383.138157"]],"c":"3090553556"},"book-10","ETH/USD"]
[560,{"b":[["1283.02000","0.00000000","1665856383.140991"],["1282.81000","0.01558765","1665856382.025677","r"]],"c":"3922286596"},"book-10","ETH/USD"]
[560,{"b":[["1283.16000","3.62759744","1665856383.333015"]],"c":"3428955454"},"book-10","ETH/USD"]
[565,["1283.16000","1283.23000","1665856383.333015","3.62759744","23.29000000"],"spread","ETH/USD"]
{"event":"heartbeat"}
[560,{"b":[["1283.17000","5.00000000","1665856383.357602"]],"c":"1020985896"},"book-10","ETH/USD"]
[565,["1283.17000","1283.23000","1665856383.357602","5.00000000","23.29000000"],"spread","ETH/USD"]
[560,{"b":[["1283.16000","1.00000000","1665856383.382038"]],"c":"3421855694"},"book-10","ETH/USD"]
[560,{"b":[["1283.17000","0.00000000","1665856383.407136"],["1282.81000","0.01558765","1665856382.025677","r"]],"c":"3922286596"},"book-10","ETH/USD"]
[565,["1283.16000","1283.23000","1665856383.382038","1.00000000","23.29000000"],"spread","ETH/USD"]
[560,{"b":[["1283.18000","1.00000000","1665856383.407258"]],"c":"140447222"},"book-10","ETH/USD"]
[565,["1283.18000","1283.23000","1665856383.407258","1.00000000","23.29000000"],"spread","ETH/USD"]
[560,{"b":[["1283.18000","0.00000000","1665856383.560634"],["1282.81000","0.01558765","1665856382.025677","r"]],"c":"3922286596"},"book-10","ETH/USD"]
[565,["1283.16000","1283.23000","1665856383.382038","1.00000000","23.29000000"],"spread","ETH/USD"]
[560,{"b":[["1283.17000","0.39721075","1665856383.811806"]],"c":"2528198964"},"book-10","ETH/USD"]
[565,["1283.17000","1283.23000","1665856383.811806","0.39721075","23.29000000"],"spread","ETH/USD"]
[560,{"b":[["1283.17000","0.77281285","1665856383.812051"]],"c":"2535444586"},"book-10","ETH/USD"]
[565,["1283.17000","1283.23000","1665856383.812051","0.77281285","23.29000000"],"spread","ETH/USD"]
[560,{"b":[["1283.13000","0.00000000","1665856383.913448"],["1282.81000","0.01558765","1665856382.025677","r"]],"c":"2316167307"},"book-10","ETH/USD"]
[560,{"b":[["1283.18000","1.00000000","1665856383.939293"]],"c":"2450874434"},"book-10","ETH/USD"]
[565,["1283.18000","1283.23000","1665856383.939293","1.00000000","23.29000000"],"spread","ETH/USD"]
[560,{"b":[["1283.17000","5.77281285","1665856384.016308"]],"c":"865434266"},"book-10","ETH/USD"]
[560,{"a":[["1283.22000","4.99000000","1665856384.034368"]],"c":"258149951"},"book-10","ETH/USD"]
[565,["1283.18000","1283.22000","1665856384.034368","1.00000000","4.99000000"],"spread","ETH/USD"]
[560,{"a":[["1283.24000","5.74000000","1665856384.035775"]],"c":"2754481149"},"book-10","ETH/USD"]
[560,{"b":[["1283.15000","0.00000000","1665856384.040459"],["1282.81000","0.01558765","1665856382.025677","r"]],"c":"1285772633"},"book-10","ETH/USD"]
[560,{"b":[["1283.16000","0.00000000","1665856384.041211"],["1282.77000","9.30157691","1665856277.952790","r"]],"c":"144731042"},"book-10","ETH/USD"]
[560,{"a":[["1283.24000","0.04000000","1665856384.310846"]],"c":"2763052625"},"book-10","ETH/USD"]
[560,{"a":[["1283.22000","10.69000000","1665856384.311071"]],"c":"1913930113"},"book-10","ETH/USD"]
[565,["1283.18000","1283.22000","1665856384.311071","1.00000000","10.69000000"],"spread","ETH/USD"]
{"event":"heartbeat"}
[560,{"a":[["1283.23000","0.00000000","1665856384.354846"],["1283.45000","0.42700784","1665856291.386182","r"],["1283.25000","23.33000000","1665856384.354863"]],"c":"1679811010"},"book-10","ETH/USD"]
[560,{"b":[["1283.20000","3.46552000","1665856384.428205"]],"c":"3091586829"},"book-10","ETH/USD"]
[565,["1283.20000","1283.22000","1665856384.428205","3.46552000","10.69000000"],"spread","ETH/USD"]
[560,{"b":[["1283.21000","5.00000000","1665856384.452786"]],"c":"1157266319"},"book-10","ETH/USD"]
[565,["1283.21000","1283.22000","1665856384.452786","5.00000000","10.69000000"],"spread","ETH/USD"]
[560,{"b":[["1283.21000","6.00000000","1665856384.454203"]],"c":"1910948630"},"book-10","ETH/USD"]
[565,["1283.21000","1283.22000","1665856384.454203","6.00000000","10.69000000"],"spread","ETH/USD"]
[560,{"b":[["1283.17000","0.77281285","1665856384.517220"]],"c":"2827710771"},"book-10","ETH/USD"]
[560,{"b":[["1283.18000","0.00000000","1665856384.542256"],["1282.81000","0.01558765","1665856382.025677","r"]],"c":"2773202730"},"book-10","ETH/USD"]
[560,{"a":[["1283.25000","0.04000000","1665856385.162593"],["1283.22000","33.98000000","1665856385.162608"]],"c":"2933312174"},"book-10","ETH/USD"]
[565,["1283.21000","1283.22000","1665856385.162608","6.00000000","33.98000000"],"spread","ETH/USD"]
[560,{"b":[["1283.21000","5.00000000","1665856385.187981"]],"c":"3746850437"},"book-10","ETH/USD"]
[565,["1283.21000","1283.22000","1665856385.187981","5.00000000","33.98000000"],"spread","ETH/USD"]
[560,{"b":[["1283.21000","0.00000000","1665856385.188074"],["1282.77000","9.30157691","1665856277.952790","r"]],"c":"839913206"},"book-10","ETH/USD"]
[565,["1283.20000","1283.22000","1665856385.162608","3.46552000","33.98000000"],"spread","ETH/USD"]
{"event":"heartbeat"}
[560,{"b":[["1282.77000","0.00000000","1665856385.666556"],["1282.73000","12.08360294","1665856007.161014","r"]],"c":"622605048"},"book-10","ETH/USD"]
[560,{"b":[["1283.17000","0.37560210","1665856385.853298"]],"c":"1045393451"},"book-10","ETH/USD"]
[560,{"b":[["1283.17000","0.00000000","1665856385.856764"],["1282.70000","2.87775523","1665856371.191718","r"]],"c":"4121074777"},"book-10","ETH/USD"]
[560,{"a":[["1283.26000","0.00000000","1665856385.920203"],["1283.53000","23.71131826","1665856348.173603","r"],["1283.21000","2.72664590","1665856385.920227"]],"c":"4284827746"},"book-10","ETH/USD"]
[565,["1283.20000","1283.21000","1665856385.920227","3.46552000","2.72664590"],"spread","ETH/USD"]
[560,{"b":[["1283.20000","4.46552000","1665856385.945269"]],"c":"2817239892"},"book-10","ETH/USD"]
[565,["1283.20000","1283.21000","1665856385.945269","4.46552000","2.72664590"],"spread","ETH/USD"]
[560,{"b":[["1283.20000","9.46552000","1665856385.945521"]],"c":"3219525136"},"book-10","ETH/USD"]
[565,["1283.20000","1283.21000","1665856385.945521","9.46552000","2.72664590"],"spread","ETH/USD"]
[560,{"a":[["1283.22000","10.69000000","1665856385.963863"],["1283.21000","26.01664590","1665856385.963886"]],"c":"681124095"},"book-10","ETH/USD"]
[565,["1283.20000","1283.21000","1665856385.963886","9.46552000","26.01664590"],"spread","ETH/USD"]
[560,{"a":[["1283.21000","31.00664590","1665856386.083397"]],"c":"4132776143"},"book-10","ETH/USD"]
[565,["1283.20000","1283.21000","1665856386.083397","9.46552000","31.00664590"],"spread","ETH/USD"]
[560,{"a":[["1283.22000","5.70000000","1665856386.085072"]],"c":"3740219953"},"book-10","ETH/USD"]
[561,[["1283.20000","3.46552000","1665856386.273855","s","m",""],["1283.20000","1.00000000","1665856386.274852","s","m",""],["1283.20000","5.00000000","1665856386.275669","s","m",""],["1283.03000","0.53188000","1665856386.277758","s","m",""]],"trade","ETH/USD"]
[564,{"a":["1283.21000",31,"31.00664590"],"b":["1283.03000",2,"2.86840013"],"c":["1283.03000","0.53188000"],"v":["7506.99163653","14914.12930099"],"p":["1288.91986","1293.18402"],"t":[6917,10934],"l":["1278.00000","1278.00000"],"h":["1300.99000","1308.60000"],"o":["1297.07000","1307.29000"]},"ticker","ETH/USD"]
[567,["1665856386.277758","1665856440.000000","1283.20000","1283.20000","1283.03000","1283.03000","1283.19095","9.99740000",4],"ohlc-1","ETH/USD"]
[560,{"b":[["1283.20000","6.00000000","1665856386.273855"],["1283.20000","5.00000000","1665856386.274852"],["1283.20000","0.00000000","1665856386.275670"],["1282.69000","116.94140392","1665856030.066982","r"],["1283.03000","2.86840013","1665856386.277758"]],"c":"993893413"},"book-10","ETH/USD"]
[565,["1283.03000","1283.21000","1665856386.277758","2.86840013","31.00664590"],"spread","ETH/USD"]
[560,{"a":[["1283.17000","5.70000000","1665856386.304581"]],"c":"4247399780"},"book-10","ETH/USD"]
[565,["1283.03000","1283.17000","1665856386.304581","2.86840013","5.70000000"],"spread","ETH/USD"]
[560,{"a":[["1283.22000","0.00000000","1665856386.305485"],["1283.45000","0.42700784","1665856291.386182","r"]],"c":"3120546414"},"book-10","ETH/USD"]
[560,{"b":[["1283.04000","0.39721075","1665856386.319957"]],"c":"4064401971"},"book-10","ETH/USD"]
[565,["1283.04000","1283.17000","1665856386.319957","0.39721075","5.70000000"],"spread","ETH/USD"]
[560,{"b":[["1283.03000","5.00853053","1665856386.326646"]],"c":"1095871120"},"book-10","ETH/USD"]
{"event":"heartbeat"}
[560,{"b":[["1283.03000","2.86840013","1665856386.373387"]],"c":"4064401971"},"book-10","ETH/USD"]
[560,{"b":[["1283.04000","2.48061123","1665856386.444722"]],"c":"4198881714"},"book-10","ETH/USD"]
[565,["1283.04000","1283.17000","1665856386.444722","2.48061123","5.70000000"],"spread","ETH/USD"]
[560,{"b":[["1283.05000","0.37560210","1665856386.582284"]],"c":"2066839105"},"book-10","ETH/USD"]
[565,["1283.05000","1283.17000","1665856386.582284","0.37560210","5.70000000"],"spread","ETH/USD"]
[560,{"b":[["1283.05000","2.21970658","1665856386.632401"]],"c":"2305967507"},"book-10","ETH/USD"]
[565,["1283.05000","1283.17000","1665856386.632401","2.21970658","5.70000000"],"spread","ETH/USD"]
[560,{"b":[["1282.74000","0.01558850","1665856387.018567"]],"c":"3083157782"},"book-10","ETH/USD"]
[560,{"a":[["1283.21000","26.01664590","1665856387.118954"]],"c":"1579434997"},"book-10","ETH/USD"]
[560,{"a":[["1283.17000","10.69000000","1665856387.121819"]],"c":"1258059445"},"book-10","ETH/USD"]
[565,["1283.05000","1283.17000","1665856387.121819","2.21970658","10.69000000"],"spread","ETH/USD"]
{"event":"heartbeat"}
[560,{"b":[["1283.05000","7.21970658","1665856387.518521"]],"c":"528912505"},"book-10","ETH/USD"]
[565,["1283.05000","1283.17000","1665856387.518521","7.21970658","10.69000000"],"spread","ETH/USD"]
[560,{"b":[["1283.06000","1.00000000","1665856387.543844"]],"c":"2705446585"},"book-10","ETH/USD"]
[565,["1283.06000","1283.17000","1665856387.543844","1.00000000","10.69000000"],"spread","ETH/USD"]
[560,{"b":[["1283.06000","3.47177200","1665856387.592852"]],"c":"1118142987"},"book-10","ETH/USD"]
[565,["1283.06000","1283.17000","1665856387.592852","3.47177200","10.69000000"],"spread","ETH/USD"]
[560,{"b":[["1283.07000","5.00000000","1665856387.617690"]],"c":"3429677202"},"book-10","ETH/USD"]
[565,["1283.07000","1283.17000","1665856387.617690","5.00000000","10.69000000"],"spread","ETH/USD"]
[560,{"b":[["1283.07000","7.48610912","1665856387.665182"]],"c":"3759989228"},"book-10","ETH/USD"]
[565,["1283.07000","1283.17000","1665856387.665182","7.48610912","10.69000000"],"spread","ETH/USD"]
[560,{"b":[["1282.91000","20.50000000","1665856387.674298"]],"c":"805533539"},"book-10","ETH/USD"]
[560,{"b":[["1283.08000","1.00000000","1665856387.690169"]],"c":"335203454"},"book-10","ETH/USD"]
[565,["1283.08000","1283.17000","1665856387.690169","1.00000000","10.69000000"],"spread","ETH/USD"]
[560,{"b":[["1283.05000","2.21970658","1665856387.690287"]],"c":"3897983019"},"book-10","ETH/USD"]
[560,{"b":[["1283.08000","3.19120128","1665856387.770374"]],"c":"1349794646"},"book-10","ETH/USD"]
[565,["1283.08000","1283.17000","1665856387.770374","3.19120128","10.69000000"],"spread","ETH/USD"]
[560,{"b":[["1283.07000","5.00000000","1665856387.770885"]],"c":"3772523334"},"book-10","ETH/USD"]
[560,{"b":[["1283.09000","5.00000000","1665856387.795970"]],"c":"567262696"},"book-10","ETH/USD"]
[565,["1283.09000","1283.17000","1665856387.795970","5.00000000","10.69000000"],"spread","ETH/USD"]
[560,{"b":[["1283.06000","2.47177200","1665856387.796379"]],"c":"2401193924"},"book-10","ETH/USD"]
[560,{"b":[["1283.08000","1.00000000","1665856387.818662"]],"c":"1836158605"},"book-10","ETH/USD"]
[560,{"b":[["1283.10000","1.00000000","1665856387.843376"]],"c":"2642577152"},"book-10","ETH/USD"]
[565,["1283.10000","1283.17000","1665856387.843376","1.00000000","10.69000000"],"spread","ETH/USD"]
[560,{"b":[["1283.09000","6.80441760","1665856387.845083"]],"c":"2639934939"},"book-10","ETH/USD"]
[560,{"b":[["1283.09000","1.80441760","1665856387.852907"]],"c":"3678933326"},"book-10","ETH/USD"]
[560,{"b":[["1283.08000","0.00000000","1665856387.877393"],["1282.91000","20.50000000","1665856387.674298","r"]],"c":"2654209252"},"book-10","ETH/USD"]
[560,{"b":[["1283.10000","6.00000000","1665856387.877580"]],"c":"3246494614"},"book-10","ETH/USD"]
[565,["1283.10000","1283.17000","1665856387.877580","6.00000000","10.69000000"],"spread","ETH/USD"]
[560,{"b":[["1283.10000","8.48067584","1665856387.891605"]],"c":"3982899852"},"book-10","ETH/USD"]
[565,["1283.10000","1283.17000","1665856387.891605","8.48067584","10.69000000"],"spread","ETH/USD"]
[560,{"b":[["1283.07000","0.00000000","1665856387.915803"],["1282.90000","58.46114640","1665856325.117058","r"]],"c":"3478544658"},"book-10","ETH/USD"]
[560,{"b":[["1283.10000","6.00000000","1665856387.940580"]],"c":"840466369"},"book-10","ETH/USD"]
[565,["1283.10000","1283.17000","1665856387.940580","6.00000000","10.69000000"],"spread","ETH/USD"]
[560,{"a":[["1283.17000","5.70000000","1665856388.086772"]],"c":"1146775798"},"book-10","ETH/USD"]
[565,["1283.10000","1283.17000","1665856388.086772","6.00000000","5.70000000"],"spread","ETH/USD"]
[560,{"a":[["1283.16000","4.99000000","1665856388.087586"]],"c":"3870562031"},"book-10","ETH/USD"]
[565,["1283.10000","1283.16000","1665856388.087586","6.00000000","4.99000000"],"spread","ETH/USD"]
[560,{"b":[["1283.10000","8.37997808","1665856388.091625"]],"c":"2080905105"},"book-10","ETH/USD"]
[565,["1283.10000","1283.16000","1665856388.091625","8.37997808","4.99000000"],"spread","ETH/USD"]
[560,{"a":[["1283.16000","0.00000000","1665856388.132048"],["1283.45000","0.42700784","1665856291.386182","r"]],"c":"3739642248"},"book-10","ETH/USD"]
[565,["1283.10000","1283.17000","1665856388.091625","8.37997808","5.70000000"],"spread","ETH/USD"]
[560,{"b":[["1283.10000","6.00000000","1665856388.137879"]],"c":"1146775798"},"book-10","ETH/USD"]
[565,["1283.10000","1283.17000","1665856388.137879","6.00000000","5.70000000"],"spread","ETH/USD"]
[560,{"a":[["1283.17000","10.69000000","1665856388.138136"]],"c":"840466369"},"book-10","ETH/USD"]
[565,["1283.10000","1283.17000","1665856388.138136","6.00000000","10.69000000"],"spread","ETH/USD"]
[560,{"b":[["1282.91000","0.00000000","1665856388.165696"],["1282.87000","0.01558692","1665856324.129857","r"]],"c":"1508312168"},"book-10","ETH/USD"]
[560,{"b":[["1283.10000","9.48506560","1665856388.185474"]],"c":"3194667593"},"book-10","ETH/USD"]
[565,["1283.10000","1283.17000","1665856388.185474","9.48506560","10.69000000"],"spread","ETH/USD"]
[560,{"b":[["1283.04000","0.39721075","1665856388.186882"]],"c":"4077884465"},"book-10","ETH/USD"]
[560,{"b":[["1283.10000","6.00000000","1665856388.232951"]],"c":"3336876607"},"book-10","ETH/USD"]
[565,["1283.10000","1283.17000","1665856388.232951","6.00000000","10.69000000"],"spread","ETH/USD"]
[560,{"b":[["1283.10000","8.70662912","1665856388.289262"]],"c":"3481857515"},"book-10","ETH/USD"]
[565,["1283.10000","1283.17000","1665856388.289262","8.70662912","10.69000000"],"spread","ETH/USD"]
[560,{"b":[["1283.10000","6.00000000","1665856388.335040"]],"c":"3336876607"},"book-10","ETH/USD"]
[565,["1283.10000","1283.17000","1665856388.335040","6.00000000","10.69000000"],"spread","ETH/USD"]
{"event":"heartbeat"}
[560,{"a":[["1283.16000","0.15586870","1665856388.358238"]],"c":"4092124260"},"book-10","ETH/USD"]
[565,["1283.10000","1283.16000","1665856388.358238","6.00000000","0.15586870"],"spread","ETH/USD"]
[560,{"b":[["1282.91000","0.15586870","1665856388.358355"]],"c":"3224634836"},"book-10","ETH/USD"]
[560,{"b":[["1283.04000","0.00000000","1665856388.366925"],["1282.87000","0.01558692","1665856324.129857","r"]],"c":"4081261861"},"book-10","ETH/USD"]
[560,{"b":[["1283.10000","7.41837808","1665856388.412863"]],"c":"130488966"},"book-10","ETH/USD"]
[565,["1283.10000","1283.16000","1665856388.412863","7.41837808","0.15586870"],"spread","ETH/USD"]
[560,{"b":[["1283.10000","6.00000000","1665856388.459699"]],"c":"4081261861"},"book-10","ETH/USD"]
[565,["1283.10000","1283.16000","1665856388.459699","6.00000000","0.15586870"],"spread","ETH/USD"]
[560,{"b":[["1283.10000","7.73796128","1665856388.543640"]],"c":"1863493963"},"book-10","ETH/USD"]
[565,["1283.10000","1283.16000","1665856388.543640","7.73796128","0.15586870"],"spread","ETH/USD"]
[560,{"b":[["1282.91000","0.00000000","1665856388.566977"],["1282.86000","6.22500000","1665856325.142256","r"]],"c":"275413353"},"book-10","ETH/USD"]
[560,{"b":[["1283.01000","0.15586870","1665856388.567134"]],"c":"1940928333"},"book-10","ETH/USD"]
[560,{"b":[["1283.10000","6.00000000","1665856388.590966"]],"c":"4024533795"},"book-10","ETH/USD"]
[565,["1283.10000","1283.16000","1665856388.590966","6.00000000","0.15586870"],"spread","ETH/USD"]
[560,{"b":[["1283.01000","0.00000000","1665856388.614613"],["1282.86000","6.22500000","1665856325.142256","r"]],"c":"3137102978"},"book-10","ETH/USD"]
[560,{"b":[["1282.91000","0.15586870","1665856388.614639"]],"c":"4081261861"},"book-10","ETH/USD"]
[560,{"b":[["1283.09000","0.00000000","1665856388.623892"],["1282.86000","6.22500000","1665856325.142256","r"]],"c":"2850670445"},"book-10","ETH/USD"]
[560,{"b":[["1283.05000","1.84410448","1665856388.628562"]],"c":"3441257931"},"book-10","ETH/USD"]
[560,{"b":[["1283.10000","8.10132064","1665856388.821576"]],"c":"1159351093"},"book-10","ETH/USD"]
[565,["1283.10000","1283.16000","1665856388.821576","8.10132064","0.15586870"],"spread","ETH/USD"]
[560,{"b":[["1283.10000","6.00000000","1665856388.867554"]],"c":"3441257931"},"book-10","ETH/USD"]
[565,["1283.10000","1283.16000","1665856388.867554","6.00000000","0.15586870"],"spread","ETH/USD"]
[560,{"b":[["1283.10000","9.08941536","1665856389.013873"]],"c":"4091721030"},"book-10","ETH/USD"]
[565,["1283.10000","1283.16000","1665856389.013873","9.08941536","0.15586870"],"spread","ETH/USD"]
[560,{"b":[["1283.10000","4.08941536","1665856389.016957"]],"c":"3958312962"},"book-10","ETH/USD"]
[565,["1283.10000","1283.16000","1665856389.016957","4.08941536","0.15586870"],"spread","ETH/USD"]
[560,{"b":[["1283.07000","5.00000000","1665856389.017276"]],"c":"2344800303"},"book-10","ETH/USD"]
[560,{"a":[["1283.16000","5.14586870","1665856389.028146"]],"c":"1931858913"},"book-10","ETH/USD"]
[565,["1283.10000","1283.16000","1665856389.028146","4.08941536","5.14586870"],"spread","ETH/USD"]
[560,{"b":[["1282.91000","0.00000000","1665856389.037241"],["1282.86000","6.22500000","1665856325.142256","r"]],"c":"645203173"},"book-10","ETH/USD"]
[560,{"b":[["1283.00000","12.23692871","1665856389.037624"]],"c":"3292576500"},"book-10","ETH/USD"]
[560,{"a":[["1283.17000","5.70000000","1665856389.038091"]],"c":"3610892614"},"book-10","ETH/USD"]
[560,{"b":[["1283.00000","12.08106001","1665856389.040399"]],"c":"890005335"},"book-10","ETH/USD"]
[560,{"a":[["1283.15000","0.15586870","1665856389.051271"]],"c":"3983720768"},"book-10","ETH/USD"]
[565,["1283.10000","1283.15000","1665856389.051271","4.08941536","0.15586870"],"spread","ETH/USD"]
[560,{"a":[["1283.16000","4.99000000","1665856389.051368"]],"c":"305531871"},"book-10","ETH/USD"]
[560,{"b":[["1282.91000","0.15586870","1665856389.064187"]],"c":"1592989064"},"book-10","ETH/USD"]
[560,{"b":[["1283.00000","12.23692871","1665856389.074574"]],"c":"3543601217"},"book-10","ETH/USD"]
[560,{"b":[["1282.91000","0.00000000","1665856389.074593"],["1282.86000","6.22500000","1665856325.142256","r"]],"c":"4026774990"},"book-10","ETH/USD"]
[560,{"b":[["1283.11000","5.00000000","1665856389.076456"]],"c":"353791593"},"book-10","ETH/USD"]
[565,["1283.11000","1283.15000","1665856389.076456","5.00000000","0.15586870"],"spread","ETH/USD"]
[560,{"b":[["1283.00000","12.08106001","1665856389.087273"]],"c":"3210487616"},"book-10","ETH/USD"]
[560,{"a":[["1283.15000","0.00000000","1665856389.099756"],["1283.44000","17.99691828","1665856381.203694","r"]],"c":"2012616414"},"book-10","ETH/USD"]
[565,["1283.11000","1283.16000","1665856389.076456","5.00000000","4.99000000"],"spread","ETH/USD"]
[560,{"b":[["1283.11000","5.57394208","1665856389.124243"]],"c":"299180275"},"book-10","ETH/USD"]
[565,["1283.11000","1283.16000","1665856389.124243","5.57394208","4.99000000"],"spread","ETH/USD"]
[560,{"b":[["1283.07000","0.00000000","1665856389.149059"],["1282.86000","6.22500000","1665856325.142256","r"]],"c":"2847962365"},"book-10","ETH/USD"]
[560,{"b":[["1283.12000","1.00000000","1665856389.151199"]],"c":"3555480971"},"book-10","ETH/USD"]
[565,["1283.12000","1283.16000","1665856389.151199","1.00000000","4.99000000"],"spread","ETH/USD"]
[560,{"b":[["1283.12000","3.66102464","1665856389.198066"]],"c":"3890706915"},"book-10","ETH/USD"]
[565,["1283.12000","1283.16000","1665856389.198066","3.66102464","4.99000000"],"spread","ETH/USD"]
[560,{"b":[["1283.10000","3.08941536","1665856389.222735"]],"c":"3062903481"},"book-10","ETH/USD"]
{"event":"heartbeat"}
[560,{"b":[["1282.97000","20.00000000","1665856389.357703"]],"c":"644090721"},"book-10","ETH/USD"]
[560,{"a":[["1283.44000","12.07691828","1665856389.823797"]],"c":"3135047792"},"book-10","ETH/USD"]
[560,{"b":[["1282.97000","0.00000000","1665856389.832538"],["1282.87000","0.01558692","1665856324.129857","r"]],"c":"4130843803"},"book-10","ETH/USD"]
[560,{"a":[["1283.28000","1.47000000","1665856390.009131"]],"c":"3657833947"},"book-10","ETH/USD"]
[560,{"a":[["1283.42000","4.87421920","1665856390.158683"]],"c":"2378942398"},"book-10","ETH/USD"]
{"event":"heartbeat"}
{"event":"heartbeat"}
[560,{"b":[["1283.12000","1.00000000","1665856391.557060"]],"c":"3116428246"},"book-10","ETH/USD"]
[565,["1283.12000","1283.16000","1665856391.557060","1.00000000","4.99000000"],"spread","ETH/USD"]
[560,{"b":[["1283.11000","5.00000000","1665856391.557116"]],"c":"3313790989"},"book-10","ETH/USD"]
[560,{"b":[["1283.12000","3.62362768","1665856391.606358"]],"c":"3135703013"},"book-10","ETH/USD"]
[565,["1283.12000","1283.16000","1665856391.606358","3.62362768","4.99000000"],"spread","ETH/USD"]
[560,{"b":[["1283.12000","1.00000000","1665856391.786033"]],"c":"3313790989"},"book-10","ETH/USD"]
[565,["1283.12000","1283.16000","1665856391.786033","1.00000000","4.99000000"],"spread","ETH/USD"]
[560,{"b":[["1283.12000","4.19242048","1665856392.140904"]],"c":"2657472478"},"book-10","ETH/USD"]
[565,["1283.12000","1283.16000","1665856392.140904","4.19242048","4.99000000"],"spread","ETH/USD"]
[560,{"b":[["1283.12000","1.00000000","1665856392.191071"]],"c":"3313790989"},"book-10","ETH/USD"]
[565,["1283.12000","1283.16000","1665856392.191071","1.00000000","4.99000000"],"spread","ETH/USD"]
{"event":"heartbeat"}
[560,{"b":[["1283.10000","0.00000000","1665856392.623720"],["1282.86000","6.22500000","1665856325.142256","r"]],"c":"2799744477"},"book-10","ETH/USD"]
[560,{"b":[["1283.11000","0.00000000","1665856392.649537"],["1282.81000","0.01558765","1665856382.025677","r"]],"c":"2857070106"},"book-10","ETH/USD"]
[560,{"b":[["1283.07000","5.00000000","1665856392.649678"]],"c":"2833953082"},"book-10","ETH/USD"]
[560,{"b":[["1282.91000","20.50000000","1665856392.913224"]],"c":"1610348242"},"book-10","ETH/USD"]
[560,{"b":[["1283.08000","1.00000000","1665856392.938858"]],"c":"4064930489"},"book-10","ETH/USD"]
[560,{"b":[["1283.12000","0.00000000","1665856392.939571"],["1282.87000","0.01558692","1665856324.129857","r"]],"c":"1606100250"},"book-10","ETH/USD"]
[565,["1283.08000","1283.16000","1665856392.938858","1.00000000","4.99000000"],"spread","ETH/USD"]
[560,{"b":[["1283.08000","2.50618800","1665856392.987059"]],"c":"1619179857"},"book-10","ETH/USD"]
[565,["1283.08000","1283.16000","1665856392.987059","2.50618800","4.99000000"],"spread","ETH/USD"]
[560,{"b":[["1283.09000","5.00000000","1665856393.013534"]],"c":"2032240643"},"book-10","ETH/USD"]
[565,["1283.09000","1283.16000","1665856393.013534","5.00000000","4.99000000"],"spread","ETH/USD"]
[560,{"b":[["1283.10000","1.00000000","1665856393.060875"]],"c":"1255141862"},"book-10","ETH/USD"]
[565,["1283.10000","1283.16000","1665856393.060875","1.00000000","4.99000000"],"spread","ETH/USD"]
[560,{"b":[["1283.09000","7.23477072","1665856393.063988"]],"c":"1711394924"},"book-10","ETH/USD"]
[560,{"b":[["1283.07000","0.00000000","1665856393.085039"],["1282.90000","58.46114640","1665856325.117058","r"]],"c":"604827190"},"book-10","ETH/USD"]
[560,{"b":[["1283.08000","1.50618800","1665856393.085482"]],"c":"1708103352"},"book-10","ETH/USD"]
[560,{"b":[["1283.09000","5.00000000","1665856393.111155"]],"c":"1754149543"},"book-10","ETH/USD"]
{"event":"heartbeat"}
[560,{"a":[["1283.17000","0.00000000","1665856393.570588"],["1283.44000","12.07691828","1665856389.823797","r"]],"c":"4148099820"},"book-10","ETH/USD"]
[560,{"b":[["1283.10000","3.34162704","1665856393.619646"]],"c":"3751190359"},"book-10","ETH/USD"]
[565,["1283.10000","1283.16000","1665856393.619646","3.34162704","4.99000000"],"spread","ETH/USD"]
[560,{"b":[["1283.11000","5.00000000","1665856393.643990"]],"c":"421085086"},"book-10","ETH/USD"]
[565,["1283.11000","1283.16000","1665856393.643990","5.00000000","4.99000000"],"spread","ETH/USD"]
[560,{"b":[["1283.11000","7.36862576","1665856393.694533"]],"c":"2375524409"},"book-10","ETH/USD"]
[565,["1283.11000","1283.16000","1665856393.694533","7.36862576","4.99000000"],"spread","ETH/USD"]
[560,{"b":[["1283.09000","0.00000000","1665856393.718846"],["1282.90000","58.46114640","1665856325.117058","r"]],"c":"4003908243"},"book-10","ETH/USD"]
[560,{"b":[["1283.12000","1.00000000","1665856393.719758"]],"c":"2943636568"},"book-10","ETH/USD"]
[565,["1283.12000","1283.16000","1665856393.719758","1.00000000","4.99000000"],"spread","ETH/USD"]
[560,{"b":[["1283.11000","5.00000000","1665856393.875579"]],"c":"1897839524"},"book-10","ETH/USD"]
[560,{"b":[["1283.08000","0.00000000","1665856393.893505"],["1282.90000","58.46114640","1665856325.117058","r"]],"c":"3837983987"},"book-10","ETH/USD"]
[560,{"b":[["1283.10000","1.00000000","1665856393.894656"]],"c":"1812781839"},"book-10","ETH/USD"]
[560,{"b":[["1283.06000","0.00000000","1665856393.895061"],["1282.87000","0.01558692","1665856324.129857","r"]],"c":"1340297828"},"book-10","ETH/USD"]
[560,{"b":[["1283.10000","0.00000000","1665856393.900106"],["1282.86000","6.22500000","1665856325.142256","r"]],"c":"1032932990"},"book-10","ETH/USD"]
{"event":"heartbeat"}
[560,{"b":[["1283.11000","0.00000000","1665856395.015812"],["1282.81000","0.01558765","1665856382.025677","r"]],"c":"1061739897"},"book-10","ETH/USD"]
[560,{"b":[["1283.06000","5.00000000","1665856395.016467"]],"c":"514653669"},"book-10","ETH/USD"]
[560,{"b":[["1283.12000","0.00000000","1665856395.041507"],["1282.81000","0.01558765","1665856382.025677","r"]],"c":"1707964098"},"book-10","ETH/USD"]
[565,["1283.06000","1283.16000","1665856395.016467","5.00000000","4.99000000"],"spread","ETH/USD"]
[560,{"b":[["1283.06000","6.00000000","1665856395.042634"]],"c":"3437041130"},"book-10","ETH/USD"]
[565,["1283.06000","1283.16000","1665856395.042634","6.00000000","4.99000000"],"spread","ETH/USD"]
[560,{"b":[["1283.06000","7.64168432","1665856395.090807"]],"c":"3986784661"},"book-10","ETH/USD"]
[565,["1283.06000","1283.16000","1665856395.090807","7.64168432","4.99000000"],"spread","ETH/USD"]
[560,{"a":[["1283.15000","0.15586505","1665856395.114052"]],"c":"1285974244"},"book-10","ETH/USD"]
[565,["1283.06000","1283.15000","1665856395.114052","7.64168432","0.15586505"],"spread","ETH/USD"]
[560,{"b":[["1282.92000","0.15586505","1665856395.114364"]],"c":"1240677133"},"book-10","ETH/USD"]
[560,{"a":[["1283.15000","5.14586505","1665856395.159396"]],"c":"1707404872"},"book-10","ETH/USD"]
[565,["1283.06000","1283.15000","1665856395.159396","7.64168432","5.14586505"],"spread","ETH/USD"]
[560,{"a":[["1283.15000","4.99000000","1665856395.182233"]],"c":"2537789360"},"book-10","ETH/USD"]
[565,["1283.06000","1283.15000","1665856395.182233","7.64168432","4.99000000"],"spread","ETH/USD"]
[560,{"a":[["1283.14000","0.15586505","1665856395.182366"]],"c":"250952524"},"book-10","ETH/USD"]
[565,["1283.06000","1283.14000","1665856395.182366","7.64168432","0.15586505"],"spread","ETH/USD"]
[560,{"b":[["1283.00000","12.23692506","1665856395.205709"]],"c":"2789967190"},"book-10","ETH/USD"]
[560,{"b":[["1282.92000","0.00000000","1665856395.205886"],["1282.81000","0.01558765","1665856382.025677","r"]],"c":"554178983"},"book-10","ETH/USD"]
[560,{"b":[["1283.01000","0.15586505","1665856395.229238"]],"c":"3023449870"},"book-10","ETH/USD"]
[560,{"b":[["1283.00000","12.08106001","1665856395.229387"]],"c":"2073527493"},"book-10","ETH/USD"]
{"event":"heartbeat"}
[560,{"a":[["1283.16000","0.00000000","1665856395.344868"],["1283.43000","0.37222112","1665856382.032588","r"]],"c":"59421561"},"book-10","ETH/USD"]
[560,{"a":[["1283.14000","5.14586505","1665856396.053451"]],"c":"1676858437"},"book-10","ETH/USD"]
[565,["1283.06000","1283.14000","1665856396.053451","7.64168432","5.14586505"],"spread","ETH/USD"]
[560,{"a":[["1283.15000","0.00000000","1665856396.054064"],["1283.44000","12.07691828","1665856389.823797","r"]],"c":"3759115107"},"book-10","ETH/USD"]
[560,{"a":[["1283.14000","4.99000000","1665856396.077939"]],"c":"1402697268"},"book-10","ETH/USD"]
[565,["1283.06000","1283.14000","1665856396.077939","7.64168432","4.99000000"],"spread","ETH/USD"]
[560,{"a":[["1283.13000","0.15586551","1665856396.078315"]],"c":"437583575"},"book-10","ETH/USD"]
[565,["1283.06000","1283.13000","1665856396.078315","7.64168432","0.15586551"],"spread","ETH/USD"]
[560,{"b":[["1283.03000","0.00000000","1665856396.099547"],["1282.81000","0.01558765","1665856382.025677","r"]],"c":"3745459785"},"book-10","ETH/USD"]
[560,{"a":[["1283.13000","0.00000000","1665856396.101169"],["1283.44000","12.07691828","1665856389.823797","r"]],"c":"1942866182"},"book-10","ETH/USD"]
[565,["1283.06000","1283.14000","1665856396.077939","7.64168432","4.99000000"],"spread","ETH/USD"]
[560,{"b":[["1283.04000","0.15586551","1665856396.101195"]],"c":"309213586"},"book-10","ETH/USD"]
[560,{"b":[["1283.01000","0.00000000","1665856396.101239"],["1282.81000","0.01558765","1665856382.025677","r"]],"c":"118947737"},"book-10","ETH/USD"]
[560,{"a":[["1283.20000","0.15586551","1665856396.101259"]],"c":"2832895100"},"book-10","ETH/USD"]
[560,{"b":[["1283.04000","0.00000000","1665856396.123086"],["1282.74000","0.01558850","1665856387.018567","r"]],"c":"123095992"},"book-10","ETH/USD"]
[560,{"a":[["1283.20000","0.00000000","1665856396.125675"],["1283.44000","12.07691828","1665856389.823797","r"]],"c":"3242123793"},"book-10","ETH/USD"]
{"event":"heartbeat"}
[560,{"a":[["1283.43000","23.66222112","1665856397.293951"]],"c":"2226476071"},"book-10","ETH/USD"]
[560,{"b":[["1283.05000","0.00000000","1665856397.295054"],["1282.73000","12.08360294","1665856007.161014","r"]],"c":"1875710011"},"book-10","ETH/USD"]
[560,{"a":[["1283.21000","2.72664590","1665856397.295550"],["1283.13000","23.29000000","1665856397.295567"]],"c":"500240305"},"book-10","ETH/USD"]
[565,["1283.06000","1283.13000","1665856397.295567","7.64168432","23.29000000"],"spread","ETH/USD"]
[560,{"b":[["1283.06000","6.00000000","1665856397.295717"]],"c":"3585197445"},"book-10","ETH/USD"]
[565,["1283.06000","1283.13000","1665856397.295717","6.00000000","23.29000000"],"spread","ETH/USD"]
[560,{"a":[["1283.37000","53.37510376","1665856397.302990"]],"c":"2789257947"},"book-10","ETH/USD"]
[560,{"b":[["1282.91000","0.00000000","1665856397.330377"],["1282.70000","2.87775523","1665856371.191718","r"]],"c":"1319011633"},"book-10","ETH/USD"]
[560,{"b":[["1282.74000","3.51383747","1665856397.332677"]],"c":"2046082315"},"book-10","ETH/USD"]
{"event":"heartbeat"}
[560,{"b":[["1283.06000","1.00000000","1665856397.355329"]],"c":"561667645"},"book-10","ETH/USD"]
[565,["1283.06000","1283.13000","1665856397.355329","1.00000000","23.29000000"],"spread","ETH/USD"]
[560,{"b":[["1283.01000","5.00000000","1665856397.355361"]],"c":"538296799"},"book-10","ETH/USD"]
[560,{"b":[["1283.06000","0.00000000","1665856397.560756"],["1282.70000","2.87775523","1665856371.191718","r"]],"c":"1857059748"},"book-10","ETH/USD"]
[565,["1283.01000","1283.13000","1665856397.355361","5.00000000","23.29000000"],"spread","ETH/USD"]
[560,{"b":[["1283.02000","1.00000000","1665856397.561707"]],"c":"1419681773"},"book-10","ETH/USD"]
[565,["1283.02000","1283.13000","1665856397.561707","1.00000000","23.29000000"],"spread","ETH/USD"]
[560,{"a":[["1283.34000","24.00000000","1665856397.775864"]],"c":"3410350790"},"book-10","ETH/USD"]
[560,{"b":[["1283.02000","2.88738928","1665856397.907505"]],"c":"3092224019"},"book-10","ETH/USD"]
[565,["1283.02000","1283.13000","1665856397.907505","2.88738928","23.29000000"],"spread","ETH/USD"]
[560,{"b":[["1283.03000","5.00000000","1665856397.931953"]],"c":"743128647"},"book-10","ETH/USD"]
[565,["1283.03000","1283.13000","1665856397.931953","5.00000000","23.29000000"],"spread","ETH/USD"]
[560,{"b":[["1283.02000","1.00000000","1665856397.954269"]],"c":"1180417211"},"book-10","ETH/USD"]
[560,{"b":[["1283.03000","0.00000000","1665856397.978862"],["1282.73000","12.08360294","1665856007.161014","r"]],"c":"3410350790"},"book-10","ETH/USD"]
[565,["1283.02000","1283.13000","1665856397.954269","1.00000000","23.29000000"],"spread","ETH/USD"]
[560,{"b":[["1283.04000","1.00000000","1665856397.979861"]],"c":"1401714456"},"book-10","ETH/USD"]
[565,["1283.04000","1283.13000","1665856397.979861","1.00000000","23.29000000"],"spread","ETH/USD"]
[560,{"a":[["1283.14000","0.00000000","1665856398.030518"],["1283.42000","4.87421920","1665856390.158683","r"]],"c":"2243666156"},"book-10","ETH/USD"]
[560,{"a":[["1283.12000","4.99000000","1665856398.033173"]],"c":"3518827256"},"book-10","ETH/USD"]
[565,["1283.04000","1283.12000","1665856398.033173","1.00000000","4.99000000"],"spread","ETH/USD"]
[560,{"b":[["1283.04000","0.00000000","1665856398.056660"],["1282.73000","12.08360294","1665856007.161014","r"]],"c":"1808597443"},"book-10","ETH/USD"]
[565,["1283.02000","1283.12000","1665856398.033173","1.00000000","4.99000000"],"spread","ETH/USD"]
[560,{"a":[["1283.13000","0.00000000","1665856398.077000"],["1283.42000","4.87421920","1665856390.158683","r"],["1283.12000","28.28000000","1665856398.077015"]],"c":"117329113"},"book-10","ETH/USD"]
[565,["1283.02000","1283.12000","1665856398.077015","1.00000000","28.28000000"],"spread","ETH/USD"]
{"event":"heartbeat"}
[560,{"b":[["1283.02000","3.23586672","1665856398.401199"]],"c":"3817306455"},"book-10","ETH/USD"]
[565,["1283.02000","1283.12000","1665856398.401199","3.23586672","28.28000000"],"spread","ETH/USD"]
[560,{"b":[["1283.03000","5.00000000","1665856398.425620"]],"c":"3768318895"},"book-10","ETH/USD"]
[565,["1283.03000","1283.12000","1665856398.425620","5.00000000","28.28000000"],"spread","ETH/USD"]
[560,{"b":[["1283.02000","1.00000000","1665856398.448220"]],"c":"717434958"},"book-10","ETH/USD"]
[560,{"b":[["1283.04000","1.00000000","1665856398.473376"]],"c":"1610406879"},"book-10","ETH/USD"]
[565,["1283.04000","1283.12000","1665856398.473376","1.00000000","28.28000000"],"spread","ETH/USD"]
[560,{"b":[["1283.01000","0.00000000","1665856398.482256"],["1282.74000","3.51383747","1665856397.332677","r"]],"c":"1453428748"},"book-10","ETH/USD"]
[560,{"b":[["1283.03000","0.00000000","1665856398.506690"],["1282.73000","12.08360294","1665856007.161014","r"]],"c":"3871154160"},"book-10","ETH/USD"]
[560,{"b":[["1283.02000","0.00000000","1665856398.506713"],["1282.70000","2.87775523","1665856371.191718","r"]],"c":"1230971408"},"book-10","ETH/USD"]
[560,{"b":[["1283.01000","5.00000000","1665856398.537426"]],"c":"1211153906"},"book-10","ETH/USD"]
[560,{"a":[["1283.12000","23.29000000","1665856399.052207"]],"c":"770910006"},"book-10","ETH/USD"]
[565,["1283.04000","1283.12000","1665856399.052207","1.00000000","23.29000000"],"spread","ETH/USD"]
[560,{"a":[["1283.11000","4.99000000","1665856399.058319"]],"c":"1547750296"},"book-10","ETH/USD"]
[565,["1283.04000","1283.11000","1665856399.058319","1.00000000","4.99000000"],"spread","ETH/USD"]
[560,{"a":[["1283.12000","0.00000000","1665856399.095808"],["1283.42000","4.87421920","1665856390.158683","r"],["1283.20000","23.29000000","1665856399.095831"]],"c":"1992437539"},"book-10","ETH/USD"]
[560,{"b":[["1283.02000","1.00000000","1665856399.111768"]],"c":"2750542090"},"book-10","ETH/USD"]
[560,{"b":[["1283.04000","0.00000000","1665856399.111871"],["1282.73000","12.08360294","1665856007.161014","r"]],"c":"940367368"},"book-10","ETH/USD"]
[565,["1283.02000","1283.11000","1665856399.111768","1.00000000","4.99000000"],"spread","ETH/USD"]
{"event":"heartbeat"}
{"event":"heartbeat"}
[560,{"b":[["1283.02000","3.46742848","1665856400.722040"]],"c":"1583173658"},"book-10","ETH/USD"]
[565,["1283.02000","1283.11000","1665856400.722040","3.46742848","4.99000000"],"spread","ETH/USD"]
[560,{"b":[["1283.03000","5.00000000","1665856400.746703"]],"c":"3303078384"},"book-10","ETH/USD"]
[565,["1283.03000","1283.11000","1665856400.746703","5.00000000","4.99000000"],"spread","ETH/USD"]
[560,{"b":[["1283.02000","1.00000000","1665856400.770053"]],"c":"3055958697"},"book-10","ETH/USD"]
[560,{"b":[["1283.03000","0.00000000","1665856400.794121"],["1282.73000","12.08360294","1665856007.161014","r"]],"c":"940367368"},"book-10","ETH/USD"]
[565,["1283.02000","1283.11000","1665856400.770053","1.00000000","4.99000000"],"spread","ETH/USD"]
[560,{"b":[["1283.04000","1.00000000","1665856400.795012"]],"c":"2750542090"},"book-10","ETH/USD"]
[565,["1283.04000","1283.11000","1665856400.795012","1.00000000","4.99000000"],"spread","ETH/USD"]
[560,{"b":[["1283.04000","0.00000000","1665856401.061434"],["1282.73000","12.08360294","1665856007.161014","r"]],"c":"940367368"},"book-10","ETH/USD"]
[565,["1283.02000","1283.11000","1665856400.770053","1.00000000","4.99000000"],"spread","ETH/USD"]
{"event":"heartbeat"}
[560,{"b":[["1283.02000","3.34844560","1665856401.436458"]],"c":"2080967615"},"book-10","ETH/USD"]
[565,["1283.02000","1283.11000","1665856401.436458","3.34844560","4.99000000"],"spread","ETH/USD"]
[560,{"b":[["1283.03000","5.00000000","1665856401.461742"]],"c":"1238652720"},"book-10","ETH/USD"]
[565,["1283.03000","1283.11000","1665856401.461742","5.00000000","4.99000000"],"spread","ETH/USD"]
[560,{"b":[["1283.01000","0.00000000","1665856401.516775"],["1282.73000","12.08360294","1665856007.161014","r"]],"c":"514421045"},"book-10","ETH/USD"]
[560,{"b":[["1283.04000","1.00000000","1665856401.541741"]],"c":"1177687957"},"book-10","ETH/USD"]
[565,["1283.04000","1283.11000","1665856401.541741","1.00000000","4.99000000"],"spread","ETH/USD"]
[560,{"b":[["1283.02000","2.34844560","1665856402.060298"]],"c":"618051098"},"book-10","ETH/USD"]
[560,{"b":[["1283.02000","0.00000000","1665856402.240735"],["1282.73000","12.08360294","1665856007.161014","r"]],"c":"1611430955"},"book-10","ETH/USD"]
[560,{"a":[["1283.10000","0.15587067","1665856402.242217"]],"c":"872219266"},"book-10","ETH/USD"]
[565,["1283.04000","1283.10000","1665856402.242217","1.00000000","0.15587067"],"spread","ETH/USD"]
[560,{"b":[["1282.91000","0.15587067","1665856402.242463"]],"c":"1960881854"},"book-10","ETH/USD"]
[560,{"a":[["1283.10000","5.14587067","1665856402.290039"]],"c":"208551424"},"book-10","ETH/USD"]
[565,["1283.04000","1283.10000","1665856402.290039","1.00000000","5.14587067"],"spread","ETH/USD"]
[560,{"a":[["1283.11000","0.00000000","1665856402.298034"],["1283.41000","0.06243872","1665856381.170081","r"]],"c":"465140172"},"book-10","ETH/USD"]
[560,{"a":[["1283.09000","0.15587067","1665856402.313560"]],"c":"1740927158"},"book-10","ETH/USD"]
[565,["1283.04000","1283.09000","1665856402.313560","1.00000000","0.15587067"],"spread","ETH/USD"]
[560,{"a":[["1283.10000","4.99000000","1665856402.313576"]],"c":"425988872"},"book-10","ETH/USD"]
{"event":"heartbeat"}
[560,{"b":[["1283.03000","0.00000000","1665856402.518084"],["1282.73000","12.08360294","1665856007.161014","r"]],"c":"4136695413"},"book-10","ETH/USD"]
[560,{"b":[["1283.01000","5.00000000","1665856402.518938"]],"c":"3797466667"},"book-10","ETH/USD"]
[560,{"b":[["1283.01000","6.00000000","1665856402.543560"]],"c":"1965953925"},"book-10","ETH/USD"]
[560,{"b":[["1283.04000","0.00000000","1665856402.543688"],["1282.73000","12.08360294","1665856007.161014","r"]],"c":"3212087643"},"book-10","ETH/USD"]
[565,["1283.01000","1283.09000","1665856402.543560","6.00000000","0.15587067"],"spread","ETH/USD"]
{"event":"heartbeat"}
[560,{"a":[["1283.09000","5.14587067","1665856404.077233"]],"c":"3412576307"},"book-10","ETH/USD"]
[565,["1283.01000","1283.09000","1665856404.077233","6.00000000","5.14587067"],"spread","ETH/USD"]
[560,{"a":[["1283.10000","0.00000000","1665856404.078842"],["1283.41000","0.06243872","1665856381.170081","r"]],"c":"20628293"},"book-10","ETH/USD"]
[560,{"a":[["1283.09000","4.99000000","1665856404.100586"]],"c":"878660137"},"book-10","ETH/USD"]
[565,["1283.01000","1283.09000","1665856404.100586","6.00000000","4.99000000"],"spread","ETH/USD"]
[560,{"a":[["1283.08000","0.15587188","1665856404.100772"]],"c":"1134870175"},"book-10","ETH/USD"]
[565,["1283.01000","1283.08000","1665856404.100772","6.00000000","0.15587188"],"spread","ETH/USD"]
[560,{"a":[["1283.08000","0.00000000","1665856404.123697"],["1283.41000","0.06243872","1665856381.170081","r"]],"c":"878660137"},"book-10","ETH/USD"]
[565,["1283.01000","1283.09000","1665856404.100586","6.00000000","4.99000000"],"spread","ETH/USD"]
[560,{"a":[["1283.19000","0.15587188","1665856404.123980"]],"c":"532416929"},"book-10","ETH/USD"]
[560,{"a":[["1283.19000","0.00000000","1665856404.147229"],["1283.41000","0.06243872","1665856381.170081","r"]],"c":"878660137"},"book-10","ETH/USD"]
[560,{"a":[["1283.09000","5.14587188","1665856404.147515"]],"c":"3876551029"},"book-10","ETH/USD"]
[565,["1283.01000","1283.09000","1665856404.147515","6.00000000","5.14587188"],"spread","ETH/USD"]
[560,{"a":[["1283.09000","4.99000000","1665856404.170696"]],"c":"878660137"},"book-10","ETH/USD"]
[565,["1283.01000","1283.09000","1665856404.170696","6.00000000","4.99000000"],"spread","ETH/USD"]
[560,{"a":[["1283.08000","0.15587188","1665856404.170776"]],"c":"1134870175"},"book-10","ETH/USD"]
[565,["1283.01000","1283.08000","1665856404.170776","6.00000000","0.15587188"],"spread","ETH/USD"]
{"event":"heartbeat"}
[560,{"b":[["1283.01000","7.99672928","1665856404.661658"]],"c":"986405353"},"book-10","ETH/USD"]
[565,["1283.01000","1283.08000","1665856404.661658","7.99672928","0.15587188"],"spread","ETH/USD"]
[560,{"b":[["1283.01000","6.00000000","1665856404.706999"]],"c":"1134870175"},"book-10","ETH/USD"]
[565,["1283.01000","1283.08000","1665856404.706999","6.00000000","0.15587188"],"spread","ETH/USD"]
[560,{"a":[["1283.09000","0.00000000","1665856405.040394"],["1283.41000","0.06243872","1665856381.170081","r"]],"c":"3958724389"},"book-10","ETH/USD"]
[560,{"a":[["1283.08000","5.14587188","1665856405.041758"]],"c":"786636844"},"book-10","ETH/USD"]
[565,["1283.01000","1283.08000","1665856405.041758","6.00000000","5.14587188"],"spread","ETH/USD"]
[560,{"a":[["1283.08000","4.99000000","1665856405.063708"]],"c":"4256371568"},"book-10","ETH/USD"]
[565,["1283.01000","1283.08000","1665856405.063708","6.00000000","4.99000000"],"spread","ETH/USD"]
[560,{"a":[["1283.19000","0.15587188","1665856405.063855"]],"c":"230821032"},"book-10","ETH/USD"]
[560,{"a":[["1283.19000","0.00000000","1665856405.064903"],["1283.41000","0.06243872","1665856381.170081","r"]],"c":"4256371568"},"book-10","ETH/USD"]
[560,{"a":[["1283.07000","0.15587188","1665856405.087258"]],"c":"1963062284"},"book-10","ETH/USD"]
[565,["1283.01000","1283.07000","1665856405.087258","6.00000000","0.15587188"],"spread","ETH/USD"]
{"event":"heartbeat"}
[560,{"a":[["1283.08000","0.00000000","1665856406.052835"],["1283.41000","0.06243872","1665856381.170081","r"]],"c":"1224844067"},"book-10","ETH/USD"]
[560,{"a":[["1283.07000","5.14587188","1665856406.060979"]],"c":"3340923373"},"book-10","ETH/USD"]
[565,["1283.01000","1283.07000","1665856406.060979","6.00000000","5.14587188"],"spread","ETH/USD"]
[560,{"a":[["1283.07000","4.99000000","1665856406.075918"]],"c":"343032497"},"book-10","ETH/USD"]
[565,["1283.01000","1283.07000","1665856406.075918","6.00000000","4.99000000"],"spread","ETH/USD"]
[560,{"a":[["1283.19000","0.15587188","1665856406.076488"]],"c":"3779608543"},"book-10","ETH/USD"]
[560,{"a":[["1283.16000","5.70000000","1665856406.080614"]],"c":"2904515966"},"book-10","ETH/USD"]
[560,{"a":[["1283.19000","0.00000000","1665856406.084212"],["1283.37000","53.37510376","1665856397.302990","r"]],"c":"3233917496"},"book-10","ETH/USD"]
[560,{"a":[["1283.19000","0.15587188","1665856406.099219"]],"c":"2904515966"},"book-10","ETH/USD"]
[560,{"a":[["1283.19000","0.00000000","1665856406.099508"],["1283.37000","53.37510376","1665856397.302990","r"]],"c":"3233917496"},"book-10","ETH/USD"]
[560,{"a":[["1283.06000","0.15587188","1665856406.107497"]],"c":"234128958"},"book-10","ETH/USD"]
[565,["1283.01000","1283.06000","1665856406.107497","6.00000000","0.15587188"],"spread","ETH/USD"]
[560,{"a":[["1283.20000","0.00000000","1665856406.124912"],["1283.37000","53.37510376","1665856397.302990","r"],["1283.15000","23.29000000","1665856406.124930"]],"c":"692101227"},"book-10","ETH/USD"]
[560,{"b":[["1283.02000","0.39721075","1665856406.279618"]],"c":"1875648617"},"book-10","ETH/USD"]
[565,["1283.02000","1283.06000","1665856406.279618","0.39721075","0.15587188"],"spread","ETH/USD"]
{"event":"heartbeat"}
[560,{"a":[["1283.07000","0.00000000","1665856407.058485"],["1283.37000","53.37510376","1665856397.302990","r"]],"c":"3814313239"},"book-10","ETH/USD"]
[560,{"a":[["1283.06000","5.14587188","1665856407.069362"]],"c":"1156553203"},"book-10","ETH/USD"]
[565,["1283.02000","1283.06000","1665856407.069362","0.39721075","5.14587188"],"spread","ETH/USD"]
[560,{"a":[["1283.06000","4.99000000","1665856407.081955"]],"c":"2545920687"},"book-10","ETH/USD"]
[565,["1283.02000","1283.06000","1665856407.081955","0.39721075","4.99000000"],"spread","ETH/USD"]
[560,{"a":[["1283.14000","0.15587128","1665856407.082039"]],"c":"2602803166"},"book-10","ETH/USD"]
[560,{"a":[["1283.14000","0.00000000","1665856407.092209"],["1283.37000","53.37510376","1665856397.302990","r"]],"c":"2545920687"},"book-10","ETH/USD"]
[560,{"a":[["1283.05000","0.15587128","1665856407.105260"]],"c":"1824352944"},"book-10","ETH/USD"]
[565,["1283.02000","1283.05000","1665856407.105260","0.39721075","0.15587128"],"spread","ETH/USD"]
{"event":"heartbeat"}
[560,{"b":[["1283.04000","3.03148672","1665856407.431650"]],"c":"1338782658"},"book-10","ETH/USD"]
[565,["1283.04000","1283.05000","1665856407.431650","3.03148672","0.15587128"],"spread","ETH/USD"]
[560,{"b":[["1283.00000","12.23693129","1665856407.455053"]],"c":"1053501558"},"book-10","ETH/USD"]
[560,{"a":[["1283.05000","0.00000000","1665856407.455070"],["1283.37000","53.37510376","1665856397.302990","r"]],"c":"3318343785"},"book-10","ETH/USD"]
[565,["1283.04000","1283.06000","1665856407.431650","3.03148672","4.99000000"],"spread","ETH/USD"]
[560,{"a":[["1283.14000","0.15587128","1665856407.455278"]],"c":"3377847576"},"book-10","ETH/USD"]
[560,{"b":[["1282.91000","0.00000000","1665856407.455291"],["1282.74000","3.51383747","1665856397.332677","r"]],"c":"103657081"},"book-10","ETH/USD"]
[560,{"b":[["1283.04000","8.03148672","1665856407.456960"]],"c":"3610059995"},"book-10","ETH/USD"]
[565,["1283.04000","1283.06000","1665856407.456960","8.03148672","4.99000000"],"spread","ETH/USD"]
[560,{"b":[["1283.04000","9.03148672","1665856407.457101"]],"c":"4166205634"},"book-10","ETH/USD"]
[565,["1283.04000","1283.06000","1665856407.457101","9.03148672","4.99000000"],"spread","ETH/USD"]
[560,{"b":[["1283.00000","12.08106001","1665856407.478719"]],"c":"875442252"},"book-10","ETH/USD"]
[560,{"a":[["1283.14000","0.00000000","1665856407.480081"],["1283.37000","53.37510376","1665856397.302990","r"]],"c":"320925139"},"book-10","ETH/USD"]
[560,{"b":[["1283.04000","6.00000000","1665856407.480205"]],"c":"151326575"},"book-10","ETH/USD"]
[565,["1283.04000","1283.06000","1665856407.480205","6.00000000","4.99000000"],"spread","ETH/USD"]
[560,{"b":[["1283.05000","2.98672768","1665856407.504586"]],"c":"4171062200"},"book-10","ETH/USD"]
[565,["1283.05000","1283.06000","1665856407.504586","2.98672768","4.99000000"],"spread","ETH/USD"]
[560,{"b":[["1283.04000","1.00000000","1665856407.516606"]],"c":"2144559679"},"book-10","ETH/USD"]
[560,{"b":[["1283.05000","7.98672768","1665856407.517430"]],"c":"3981743682"},"book-10","ETH/USD"]
[565,["1283.05000","1283.06000","1665856407.517430","7.98672768","4.99000000"],"spread","ETH/USD"]
[560,{"b":[["1283.04000","0.00000000","1665856407.541631"],["1282.74000","3.51383747","1665856397.332677","r"]],"c":"1453339090"},"book-10","ETH/USD"]
[560,{"a":[["1283.34000","0.00000000","1665856407.550613"],["1283.41000","0.06243872","1665856381.170081","r"]],"c":"3679655311"},"book-10","ETH/USD"]
[560,{"b":[["1283.05000","5.00000000","1665856407.555109"]],"c":"2379650513"},"book-10","ETH/USD"]
[565,["1283.05000","1283.06000","1665856407.555109","5.00000000","4.99000000"],"spread","ETH/USD"]
[560,{"b":[["1283.05000","0.00000000","1665856407.576408"],["1282.73000","12.08360294","1665856007.161014","r"]],"c":"1914624185"},"book-10","ETH/USD"]
[565,["1283.02000","1283.06000","1665856407.081955","0.39721075","4.99000000"],"spread","ETH/USD"]
[560,{"b":[["1283.05000","1.00000000","1665856407.577292"]],"c":"808388021"},"book-10","ETH/USD"]
[565,["1283.05000","1283.06000","1665856407.577292","1.00000000","4.99000000"],"spread","ETH/USD"]
[560,{"b":[["1283.05000","3.97406112","1665856407.602042"]],"c":"1112383863"},"book-10","ETH/USD"]
[565,["1283.05000","1283.06000","1665856407.602042","3.97406112","4.99000000"],"spread","ETH/USD"]
[560,{"a":[["1283.16000","0.00000000","1665856407.606983"],["1283.42000","4.87421920","1665856390.158683","r"]],"c":"4236639256"},"book-10","ETH/USD"]
[560,{"b":[["1283.05000","8.97406112","1665856407.627156"]],"c":"763721402"},"book-10","ETH/USD"]
[565,["1283.05000","1283.06000","1665856407.627156","8.97406112","4.99000000"],"spread","ETH/USD"]
[560,{"b":[["1283.01000","5.00000000","1665856407.627382"]],"c":"2326303787"},"book-10","ETH/USD"]
[560,{"a":[["1283.15000","0.00000000","1665856407.650967"],["1283.43000","23.66222112","1665856397.293951","r"],["1283.20000","23.29000000","1665856407.650986"]],"c":"1953132875"},"book-10","ETH/USD"]
[560,{"b":[["1283.01000","0.00000000","1665856407.676086"],["1282.73000","12.08360294","1665856007.161014","r"]],"c":"3645073319"},"book-10","ETH/USD"]
[560,{"b":[["1282.91000","20.50000000","1665856407.745687"]],"c":"3351987792"},"book-10","ETH/USD"]
[560,{"a":[["1283.21000","0.00000000","1665856407.761858"],["1283.43000","0.37222112","1665856407.675374","r"],["1283.23000","2.72664590","1665856407.761874"]],"c":"4061398347"},"book-10","ETH/USD"]
[560,{"b":[["1283.05000","6.00000000","1665856407.855959"]],"c":"1504321792"},"book-10","ETH/USD"]
[565,["1283.05000","1283.06000","1665856407.855959","6.00000000","4.99000000"],"spread","ETH/USD"]
[560,{"b":[["1282.91000","0.00000000","1665856407.906821"],["1282.73000","12.08360294","1665856007.161014","r"]],"c":"1193410807"},"book-10","ETH/USD"]
[560,{"b":[["1283.05000","9.81584576","1665856408.265511"]],"c":"1846968819"},"book-10","ETH/USD"]
[565,["1283.05000","1283.06000","1665856408.265511","9.81584576","4.99000000"],"spread","ETH/USD"]
[560,{"b":[["1283.05000","6.00000000","1665856408.312486"]],"c":"1193410807"},"book-10","ETH/USD"]
[565,["1283.05000","1283.06000","1665856408.312486","6.00000000","4.99000000"],"spread","ETH/USD"]
[560,{"b":[["1283.02000","0.00000000","1665856408.325492"],["1282.70000","2.87775523","1665856371.191718","r"]],"c":"3413006150"},"book-10","ETH/USD"]
{"event":"heartbeat"}
[560,{"a":[["1283.34000","24.00000000","1665856408.464329"]],"c":"2683188394"},"book-10","ETH/USD"]
[560,{"b":[["1283.05000","1.00000000","1665856409.016362"]],"c":"3345012636"},"book-10","ETH/USD"]
[565,["1283.05000","1283.06000","1665856409.016362","1.00000000","4.99000000"],"spread","ETH/USD"]
[560,{"b":[["1283.01000","5.00000000","1665856409.017379"]],"c":"3322890366"},"book-10","ETH/USD"]
[560,{"b":[["1283.01000","6.00000000","1665856409.041346"]],"c":"1592561978"},"book-10","ETH/USD"]
[560,{"b":[["1283.05000","0.00000000","1665856409.041529"],["1282.70000","2.87775523","1665856371.191718","r"]],"c":"3949292184"},"book-10","ETH/USD"]
[565,["1283.01000","1283.06000","1665856409.041346","6.00000000","4.99000000"],"spread","ETH/USD"]
[560,{"a":[["1283.20000","0.00000000","1665856409.060464"],["1283.42000","4.87421920","1665856390.158683","r"],["1283.22000","23.29000000","1665856409.060481"]],"c":"1961296462"},"book-10","ETH/USD"]
[560,{"a":[["1283.23000","0.00000000","1665856409.139753"],["1283.42000","4.87421920","1665856390.158683","r"],["1283.21000","2.72664590","1665856409.139768"]],"c":"406815334"},"book-10","ETH/USD"]
{"event":"heartbeat"}
{"event":"heartbeat"}
[560,{"a":[["1283.22000","0.00000000","1665856411.186889"],["1283.42000","4.87421920","1665856390.158683","r"],["1283.20000","23.29000000","1665856411.186904"]],"c":"2911274231"},"book-10","ETH/USD"]
{"event":"heartbeat"}
{"event":"heartbeat"}
{"event":"heartbeat"}
[560,{"b":[["1282.91000","0.15586900","1665856413.489204"]],"c":"3286198237"},"book-10","ETH/USD"]
[560,{"a":[["1283.19000","0.15586900","1665856413.489278"]],"c":"2212221535"},"book-10","ETH/USD"]
[560,{"a":[["1283.28000","0.00000000","1665856413.500016"],["1283.41000","0.06243872","1665856381.170081","r"]],"c":"2100425014"},"book-10","ETH/USD"]
[560,{"a":[["1283.41000","1.53243872","1665856413.988986"]],"c":"3734135361"},"book-10","ETH/USD"]
{"event":"heartbeat"}
{"event":"heartbeat"}
{"event":"heartbeat"}
{"event":"heartbeat"}
{"event":"heartbeat"}
{"event":"heartbeat"}
{"event":"heartbeat"}
{"event":"heartbeat"}
{"event":"heartbeat"}
{"event":"heartbeat"}
{"event":"heartbeat"}
{"event":"heartbeat"}
{"event":"heartbeat"}
{"event":"heartbeat"}
{"event":"heartbeat"}
[560,{"a":[["1283.15000","12.07964774","1665856429.065186"]],"c":"3338933658"},"book-10","ETH/USD"]
[560,{"a":[["1283.19000","0.00000000","1665856429.089140"],["1283.41000","1.53243872","1665856413.988986","r"]],"c":"2999139122"},"book-10","ETH/USD"]
[560,{"a":[["1283.14000","0.15587021","1665856429.089232"]],"c":"2031139761"},"book-10","ETH/USD"]
[560,{"a":[["1283.20000","0.00000000","1665856429.109216"],["1283.41000","1.53243872","1665856413.988986","r"],["1283.14000","23.44587021","1665856429.109239"]],"c":"2676315256"},"book-10","ETH/USD"]
[560,{"a":[["1283.14000","23.29000000","1665856429.112874"]],"c":"4149244630"},"book-10","ETH/USD"]
[560,{"a":[["1283.06000","5.14587021","1665856429.113089"]],"c":"489669070"},"book-10","ETH/USD"]
[565,["1283.01000","1283.06000","1665856429.113089","6.00000000","5.14587021"],"spread","ETH/USD"]
[560,{"a":[["1283.06000","4.99000000","1665856429.132877"]],"c":"4149244630"},"book-10","ETH/USD"]
[565,["1283.01000","1283.06000","1665856429.132877","6.00000000","4.99000000"],"spread","ETH/USD"]
[560,{"b":[["1282.87000","0.17145713","1665856429.136308"]],"c":"2369551565"},"book-10","ETH/USD"]
[560,{"a":[["1283.05000","0.15587021","1665856429.136408"]],"c":"1672578898"},"book-10","ETH/USD"]
[565,["1283.01000","1283.05000","1665856429.136408","6.00000000","0.15587021"],"spread","ETH/USD"]
[560,{"b":[["1282.91000","0.00000000","1665856429.158608"],["1282.70000","2.87775523","1665856371.191718","r"]],"c":"4173755581"},"book-10","ETH/USD"]
[560,{"b":[["1282.87000","0.01558692","1665856429.158691"]],"c":"3572312565"},"book-10","ETH/USD"]
[560,{"b":[["1282.87000","0.17145713","1665856429.183163"]],"c":"4173755581"},"book-10","ETH/USD"]
[560,{"a":[["1283.06000","0.00000000","1665856429.183241"],["1283.41000","1.53243872","1665856413.988986","r"]],"c":"1696072833"},"book-10","ETH/USD"]
[560,{"b":[["1282.86000","0.00000000","1665856429.191882"],["1282.66000","0.01558947","1665856387.017883","r"]],"c":"186627404"},"book-10","ETH/USD"]
[560,{"a":[["1283.05000","5.14587021","1665856429.196329"]],"c":"3942377492"},"book-10","ETH/USD"]
[565,["1283.01000","1283.05000","1665856429.196329","6.00000000","5.14587021"],"spread","ETH/USD"]
[560,{"a":[["1283.36000","23.29000000","1665856429.201516"]],"c":"2724889157"},"book-10","ETH/USD"]
[560,{"b":[["1282.90000","58.61701661","1665856429.206930"]],"c":"9570354"},"book-10","ETH/USD"]
[560,{"a":[["1283.13000","0.15587021","1665856429.207042"]],"c":"410325266"},"book-10","ETH/USD"]
[560,{"a":[["1283.05000","4.99000000","1665856429.207162"]],"c":"2994811030"},"book-10","ETH/USD"]
[565,["1283.01000","1283.05000","1665856429.207162","6.00000000","4.99000000"],"spread","ETH/USD"]
[560,{"b":[["1282.87000","0.01558692","1665856429.207290"]],"c":"1615971481"},"book-10","ETH/USD"]
[560,{"a":[["1283.02000","0.33635488","1665856429.215156"]],"c":"3905285802"},"book-10","ETH/USD"]
[565,["1283.01000","1283.02000","1665856429.215156","6.00000000","0.33635488"],"spread","ETH/USD"]
[560,{"a":[["1283.11000","5.70000000","1665856429.221956"]],"c":"175013322"},"book-10","ETH/USD"]
[560,{"a":[["1283.13000","0.00000000","1665856429.228349"],["1283.35000","2.75224947","1665856381.660371","r"]],"c":"2719509223"},"book-10","ETH/USD"]
[560,{"b":[["1282.90000","58.46114640","1665856429.230604"]],"c":"1038315460"},"book-10","ETH/USD"]
[560,{"b":[["1282.90000","58.61701661","1665856429.238716"]],"c":"2719509223"},"book-10","ETH/USD"]
[560,{"a":[["1283.04000","0.15587021","1665856429.241594"]],"c":"1372504579"},"book-10","ETH/USD"]
[560,{"b":[["1282.90000","58.46114640","1665856429.247087"]],"c":"3459630880"},"book-10","ETH/USD"]
[560,{"b":[["1283.01000","1.00000000","1665856429.249354"]],"c":"38730607"},"book-10","ETH/USD"]
[565,["1283.01000","1283.02000","1665856429.249354","1.00000000","0.33635488"],"spread","ETH/USD"]
[560,{"b":[["1282.75000","0.15587021","1665856429.254976"]],"c":"1945315360"},"book-10","ETH/USD"]
[560,{"b":[["1282.75000","0.00000000","1665856429.264475"],["1282.67000","6.22500000","1665856429.255764","r"]],"c":"1031420340"},"book-10","ETH/USD"]
[560,{"b":[["1282.75000","0.15587021","1665856429.271152"]],"c":"1945315360"},"book-10","ETH/USD"]
[560,{"b":[["1282.90000","0.00000000","1665856429.272566"],["1282.67000","6.22500000","1665856429.255764","r"]],"c":"2363338270"},"book-10","ETH/USD"]
[560,{"b":[["1282.75000","0.00000000","1665856429.279795"],["1282.66000","0.01558947","1665856387.017883","r"]],"c":"1361407581"},"book-10","ETH/USD"]
[560,{"b":[["1282.75000","0.15587021","1665856429.290333"]],"c":"2363338270"},"book-10","ETH/USD"]
[560,{"b":[["1282.75000","0.00000000","1665856429.297417"],["1282.66000","0.01558947","1665856387.017883","r"]],"c":"1361407581"},"book-10","ETH/USD"]
[560,{"a":[["1283.21000","0.00000000","1665856429.300839"],["1283.35000","2.75224947","1665856381.660371","r"],["1283.10000","2.72664590","1665856429.300854"]],"c":"3191069786"},"book-10","ETH/USD"]
[560,{"b":[["1282.75000","0.15587021","1665856429.303804"]],"c":"307637519"},"book-10","ETH/USD"]
[560,{"b":[["1283.01000","0.00000000","1665856429.314791"],["1282.66000","0.01558947","1665856387.017883","r"]],"c":"3981635201"},"book-10","ETH/USD"]
[565,["1283.00000","1283.02000","1665856429.215156","12.08106001","0.33635488"],"spread","ETH/USD"]
[560,{"b":[["1282.75000","0.00000000","1665856429.318196"],["1282.60000","0.01559020","1665856387.017361","r"]],"c":"1459919501"},"book-10","ETH/USD"]
[560,{"b":[["1282.75000","0.15587021","1665856429.328248"]],"c":"3981635201"},"book-10","ETH/USD"]
[560,{"b":[["1283.00000","0.00000000","1665856429.331239"],["1282.60000","0.01559020","1665856387.017361","r"]],"c":"11385359"},"book-10","ETH/USD"]
[565,["1282.95000","1283.02000","1665856429.215156","0.01558595","0.33635488"],"spread","ETH/USD"]
[560,{"b":[["1282.75000","0.00000000","1665856429.339360"],["1282.59000","58.47528394","1665856429.298154","r"]],"c":"48069365"},"book-10","ETH/USD"]
[560,{"a":[["1283.11000","0.00000000","1665856429.343278"],["1283.35000","2.75224947","1665856381.660371","r"]],"c":"1421102361"},"book-10","ETH/USD"]
[560,{"b":[["1282.75000","0.15587021","1665856429.343468"]],"c":"2480562020"},"book-10","ETH/USD"]
[560,{"b":[["1282.75000","0.00000000","1665856429.352466"],["1282.59000","58.47528394","1665856429.298154","r"]],"c":"1421102361"},"book-10","ETH/USD"]
[560,{"a":[["1283.02000","6.03635488","1665856429.356026"]],"c":"1674880230"},"book-10","ETH/USD"]
[565,["1282.95000","1283.02000","1665856429.356026","0.01558595","6.03635488"],"spread","ETH/USD"]
[560,{"b":[["1282.75000","1.00000000","1665856429.365236"]],"c":"992092360"},"book-10","ETH/USD"]
[560,{"b":[["1282.73000","12.23947315","1665856429.368319"]],"c":"2407963624"},"book-10","ETH/USD"]
[560,{"b":[["1282.73000","12.08360294","1665856429.376213"]],"c":"992092360"},"book-10","ETH/USD"]
[560,{"a":[["1283.01000","0.63120224","1665856429.376596"]],"c":"4053706470"},"book-10","ETH/USD"]
[565,["1282.95000","1283.01000","1665856429.376596","0.01558595","0.63120224"],"spread","ETH/USD"]
[560,{"b":[["1282.75000","1.15587021","1665856429.378738"]],"c":"1626407176"},"book-10","ETH/USD"]
[560,{"b":[["1282.75000","1.00000000","1665856429.380569"]],"c":"4053706470"},"book-10","ETH/USD"]
[560,{"a":[["1283.04000","0.00000000","1665856429.387447"],["1283.35000","2.75224947","1665856381.660371","r"]],"c":"528398508"},"book-10","ETH/USD"]
[560,{"a":[["1283.01000","0.78707245","1665856429.387949"]],"c":"1259900018"},"book-10","ETH/USD"]
[565,["1282.95000","1283.01000","1665856429.387949","0.01558595","0.78707245"],"spread","ETH/USD"]
[560,{"b":[["1282.75000","6.00000000","1665856429.392732"]],"c":"3934018091"},"book-10","ETH/USD"]
[560,{"b":[["1282.71000","0.15587021","1665856429.408448"]],"c":"612510753"},"book-10","ETH/USD"]
[560,{"b":[["1282.71000","0.00000000","1665856429.418278"],["1282.60000","0.01559020","1665856387.017361","r"]],"c":"3934018091"},"book-10","ETH/USD"]
[560,{"b":[["1282.68000","0.15587021","1665856429.419272"]],"c":"798674720"},"book-10","ETH/USD"]
[560,{"b":[["1282.68000","0.00000000","1665856429.425682"],["1282.60000","0.01559020","1665856387.017361","r"]],"c":"3934018091"},"book-10","ETH/USD"]
[560,{"b":[["1282.71000","0.15587021","1665856429.442379"]],"c":"612510753"},"book-10","ETH/USD"]
[560,{"a":[["1283.00000","1.61076896","1665856429.455412"]],"c":"3356933215"},"book-10","ETH/USD"]
[565,["1282.95000","1283.00000","1665856429.455412","0.01558595","1.61076896"],"spread","ETH/USD"]
[560,{"b":[["1282.71000","0.00000000","1665856429.467393"],["1282.60000","0.01559020","1665856387.017361","r"]],"c":"488506090"},"book-10","ETH/USD"]
[560,{"b":[["1282.73000","12.23947315","1665856429.467610"]],"c":"2847586762"},"book-10","ETH/USD"]
[560,{"b":[["1282.73000","12.08360294","1665856429.478896"]],"c":"488506090"},"book-10","ETH/USD"]
[560,{"a":[["1283.01000","0.63120224","1665856429.478981"]],"c":"4279083491"},"book-10","ETH/USD"]
[560,{"a":[["1282.99000","0.15587021","1665856429.479078"]],"c":"1791121672"},"book-10","ETH/USD"]
[565,["1282.95000","1282.99000","1665856429.479078","0.01558595","0.15587021"],"spread","ETH/USD"]
{"event":"heartbeat"}
[560,{"a":[["1282.99000","0.00000000","1665856429.502835"],["1283.34000","24.00000000","1665856408.464329","r"]],"c":"4279083491"},"book-10","ETH/USD"]
[565,["1282.95000","1283.00000","1665856429.455412","0.01558595","1.61076896"],"spread","ETH/USD"]
[560,{"a":[["1282.99000","0.27973856","1665856429.507495"]],"c":"2716326739"},"book-10","ETH/USD"]
[565,["1282.95000","1282.99000","1665856429.507495","0.01558595","0.27973856"],"spread","ETH/USD"]
[560,{"a":[["1283.14000","0.00000000","1665856429.848269"],["1283.34000","24.00000000","1665856408.464329","r"],["1282.99000","23.56973856","1665856429.848292"]],"c":"5873352"},"book-10","ETH/USD"]
[565,["1282.95000","1282.99000","1665856429.848292","0.01558595","23.56973856"],"spread","ETH/USD"]
[560,{"a":[["1283.02000","0.33635488","1665856429.871657"]],"c":"924882897"},"book-10","ETH/USD"]
[560,{"a":[["1282.97000","5.70000000","1665856429.872893"]],"c":"3527592079"},"book-10","ETH/USD"]
[565,["1282.95000","1282.97000","1665856429.872893","0.01558595","5.70000000"],"spread","ETH/USD"]
[560,{"b":[["1282.81000","0.00000000","1665856429.936145"],["1282.59000","58.47528394","1665856429.298154","r"]],"c":"1587766525"},"book-10","ETH/USD"]
[560,{"b":[["1282.95000","0.00000000","1665856429.950673"],["1282.54000","0.01559093","1665856387.063542","r"]],"c":"1446053651"},"book-10","ETH/USD"]
[565,["1282.87000","1282.97000","1665856429.872893","0.01558692","5.70000000"],"spread","ETH/USD"]
[560,{"a":[["1282.97000","10.69000000","1665856430.049287"]],"c":"719916470"},"book-10","ETH/USD"]
[565,["1282.87000","1282.97000","1665856430.049287","0.01558692","10.69000000"],"spread","ETH/USD"]
[560,{"a":[["1283.05000","0.00000000","1665856430.057480"],["1283.32000","3.65783629","1665856429.969247","r"]],"c":"4254043730"},"book-10","ETH/USD"]
[560,{"a":[["1283.31000","23.29000000","1665856430.101772"]],"c":"1691860906"},"book-10","ETH/USD"]
[560,{"a":[["1283.09000","53.38689121","1665856430.175547"]],"c":"3132688398"},"book-10","ETH/USD"]
{"event":"heartbeat"}
[560,{"b":[["1282.70000","0.00000000","1665856430.601225"],["1282.46000","12.10173883","1665856429.472833","r"]],"c":"1650541434"},"book-10","ETH/USD"]
[560,{"a":[["1282.99000","0.27973856","1665856430.645462"],["1282.96000","23.29000000","1665856430.645480"]],"c":"243078743"},"book-10","ETH/USD"]
[565,["1282.87000","1282.96000","1665856430.645480","0.01558692","23.29000000"],"spread","ETH/USD"]
[560,{"a":[["1282.97000","4.99000000","1665856430.671488"]],"c":"1613313600"},"book-10","ETH/USD"]
[560,{"a":[["1282.93000","5.70000000","1665856430.671881"]],"c":"1233600725"},"book-10","ETH/USD"]
[565,["1282.87000","1282.93000","1665856430.671881","0.01558692","5.70000000"],"spread","ETH/USD"]
[560,{"b":[["1282.88000","0.01558680","1665856430.965705"]],"c":"853796171"},"book-10","ETH/USD"]
[565,["1282.88000","1282.93000","1665856430.965705","0.01558680","5.70000000"],"spread","ETH/USD"]
[560,{"b":[["1282.79000","0.01558789","1665856430.969674"]],"c":"3413626184"},"book-10","ETH/USD"]
[560,{"a":[["1283.10000","0.00000000","1665856431.037623"],["1283.24000","0.04000000","1665856384.310846","r"],["1283.00000","4.33741486","1665856431.037642"]],"c":"597772963"},"book-10","ETH/USD"]
[560,{"a":[["1282.93000","10.69000000","1665856431.082437"]],"c":"3320962178"},"book-10","ETH/USD"]
[565,["1282.88000","1282.93000","1665856431.082437","0.01558680","10.69000000"],"spread","ETH/USD"]
[560,{"a":[["1282.97000","0.00000000","1665856431.084371"],["1283.25000","0.04000000","1665856385.162593","r"]],"c":"1669856326"},"book-10","ETH/USD"]
[560,{"b":[["1282.67000","0.00000000","1665856431.205715"],["1282.54000","0.01559093","1665856387.063542","r"]],"c":"2327099203"},"book-10","ETH/USD"]
[560,{"b":[["1282.73000","0.00000000","1665856431.242010"],["1282.46000","12.10173883","1665856429.472833","r"]],"c":"2043358263"},"book-10","ETH/USD"]
[560,{"a":[["1282.96000","0.00000000","1665856431.249310"],["1283.31000","23.29000000","1665856430.101772","r"],["1282.92000","23.29000000","1665856431.249326"]],"c":"3087469505"},"book-10","ETH/USD"]
[565,["1282.88000","1282.92000","1665856431.249326","0.01558680","23.29000000"],"spread","ETH/USD"]
[560,{"b":[["1282.52000","6.22500000","1665856431.269395"]],"c":"2311421519"},"book-10","ETH/USD"]
[560,{"a":[["1282.93000","4.99000000","1665856431.273363"]],"c":"1086610431"},"book-10","ETH/USD"]
[560,{"a":[["1282.91000","5.70000000","1665856431.273817"]],"c":"943923073"},"book-10","ETH/USD"]
[565,["1282.88000","1282.91000","1665856431.273817","0.01558680","5.70000000"],"spread","ETH/USD"]
[560,{"a":[["1283.00000","1.61076896","1665856431.437774"],["1282.91000","8.42664590","1665856431.437791"]],"c":"103942384"},"book-10","ETH/USD"]
[565,["1282.88000","1282.91000","1665856431.437791","0.01558680","8.42664590"],"spread","ETH/USD"]
{"event":"heartbeat"}
[560,{"a":[["1282.92000","0.00000000","1665856431.812600"],["1283.25000","0.04000000","1665856385.162593","r"],["1282.90000","23.29000000","1665856431.812619"]],"c":"2873927503"},"book-10","ETH/USD"]
[565,["1282.88000","1282.90000","1665856431.812619","0.01558680","23.29000000"],"spread","ETH/USD"]
[560,{"a":[["1282.89000","4.99000000","1665856432.048066"]],"c":"305253095"},"book-10","ETH/USD"]
[565,["1282.88000","1282.89000","1665856432.048066","0.01558680","4.99000000"],"spread","ETH/USD"]
[560,{"a":[["1282.93000","0.00000000","1665856432.053976"],["1283.24000","0.04000000","1665856384.310846","r"]],"c":"2176359385"},"book-10","ETH/USD"]
[560,{"a":[["1283.08000","2.85357296","1665856432.144643"]],"c":"3926387274"},"book-10","ETH/USD"]
[560,{"a":[["1283.08000","4.32357296","1665856432.416555"]],"c":"1033169644"},"book-10","ETH/USD"]
{"event":"heartbeat"}
{"event":"heartbeat"}
{"event":"heartbeat"}
{"event":"heartbeat"}
[560,{"a":[["1282.89000","5.14590393","1665856435.812143"]],"c":"3386797013"},"book-10","ETH/USD"]
[565,["1282.88000","1282.89000","1665856435.812143","0.01558680","5.14590393"],"spread","ETH/USD"]
[560,{"b":[["1282.60000","0.17149413","1665856435.812485"]],"c":"2345059338"},"book-10","ETH/USD"]
[560,{"b":[["1282.88000","3.67525656","1665856436.209852"]],"c":"616754329"},"book-10","ETH/USD"]
[565,["1282.88000","1282.89000","1665856436.209852","3.67525656","5.14590393"],"spread","ETH/USD"]
[560,{"b":[["1282.88000","0.01558680","1665856436.257541"]],"c":"2345059338"},"book-10","ETH/USD"]
[565,["1282.88000","1282.89000","1665856436.257541","0.01558680","5.14590393"],"spread","ETH/USD"]
{"event":"heartbeat"}
[560,{"b":[["1282.88000","2.76273496","1665856436.575720"]],"c":"3743447836"},"book-10","ETH/USD"]
[565,["1282.88000","1282.89000","1665856436.575720","2.76273496","5.14590393"],"spread","ETH/USD"]
[560,{"b":[["1282.88000","0.01558680","1665856436.623056"]],"c":"2345059338"},"book-10","ETH/USD"]
[565,["1282.88000","1282.89000","1665856436.623056","0.01558680","5.14590393"],"spread","ETH/USD"]
{"event":"heartbeat"}
[560,{"a":[["1282.91000","2.72664590","1665856438.376095"]],"c":"410311847"},"book-10","ETH/USD"]
[560,{"a":[["1282.89000","10.84590393","1665856438.377074"]],"c":"3366529471"},"book-10","ETH/USD"]
[565,["1282.88000","1282.89000","1665856438.377074","0.01558680","10.84590393"],"spread","ETH/USD"]
{"event":"heartbeat"}
[560,{"b":[["1282.74000","0.01558850","1665856438.504358"]],"c":"2234149067"},"book-10","ETH/USD"]
[560,{"b":[["1282.60000","5.17149413","1665856438.530182"]],"c":"3310859580"},"book-10","ETH/USD"]
[560,{"b":[["1282.75000","1.00000000","1665856438.530256"]],"c":"1354704257"},"book-10","ETH/USD"]
[560,{"b":[["1282.61000","0.15590393","1665856438.553551"]],"c":"75314153"},"book-10","ETH/USD"]
[560,{"b":[["1282.60000","5.01559020","1665856438.553610"]],"c":"4023432800"},"book-10","ETH/USD"]
[560,{"b":[["1282.75000","0.00000000","1665856438.558999"],["1282.52000","6.22500000","1665856431.269395","r"]],"c":"4053639408"},"book-10","ETH/USD"]
[560,{"b":[["1282.61000","1.15590393","1665856438.559171"]],"c":"3159757418"},"book-10","ETH/USD"]
[560,{"a":[["1282.90000","0.00000000","1665856438.568662"],["1283.22000","4.45000000","1665856432.586287","r"],["1282.89000","34.13590393","1665856438.568678"]],"c":"2304003742"},"book-10","ETH/USD"]
[565,["1282.88000","1282.89000","1665856438.568678","0.01558680","34.13590393"],"spread","ETH/USD"]
[560,{"b":[["1282.61000","1.00000000","1665856438.592064"]],"c":"3607497583"},"book-10","ETH/USD"]
[560,{"b":[["1282.53000","0.15590393","1665856438.592486"]],"c":"3255567132"},"book-10","ETH/USD"]
[560,{"b":[["1282.59000","58.63118787","1665856438.629003"]],"c":"791081799"},"book-10","ETH/USD"]
[560,{"b":[["1282.53000","0.00000000","1665856438.629022"],["1282.52000","6.22500000","1665856431.269395","r"]],"c":"726837731"},"book-10","ETH/USD"]
[560,{"b":[["1282.88000","4.05243512","1665856438.631083"]],"c":"1148949774"},"book-10","ETH/USD"]
[565,["1282.88000","1282.89000","1665856438.631083","4.05243512","34.13590393"],"spread","ETH/USD"]
[560,{"b":[["1282.60000","5.17149413","1665856438.652581"]],"c":"3438578544"},"book-10","ETH/USD"]
[560,{"b":[["1282.59000","58.47528394","1665856438.652790"]],"c":"815802876"},"book-10","ETH/USD"]
[560,{"b":[["1282.60000","5.01559020","1665856438.653976"]],"c":"3090102146"},"book-10","ETH/USD"]
[560,{"b":[["1282.61000","1.15590393","1665856438.676985"]],"c":"3866980979"},"book-10","ETH/USD"]
[560,{"b":[["1282.88000","0.01558680","1665856438.829644"]],"c":"2304003742"},"book-10","ETH/USD"]
[565,["1282.88000","1282.89000","1665856438.829644","0.01558680","34.13590393"],"spread","ETH/USD"]
[560,{"b":[["1282.88000","3.66232792","1665856438.960303"]],"c":"175266324"},"book-10","ETH/USD"]
[565,["1282.88000","1282.89000","1665856438.960303","3.66232792","34.13590393"],"spread","ETH/USD"]
{"event":"heartbeat"}
[560,{"b":[["1282.52000","0.00000000","1665856440.338613"],["1282.48000","0.01559166","1665856433.965813","r"]],"c":"1897023592"},"book-10","ETH/USD"]
[560,{"a":[["1283.17000","6.22500000","1665856440.363770"]],"c":"96967391"},"book-10","ETH/USD"]
{"event":"heartbeat"}
[560,{"b":[["1282.88000","5.89122792","1665856441.111655"]],"c":"2687675886"},"book-10","ETH/USD"]
[565,["1282.88000","1282.89000","1665856441.111655","5.89122792","34.13590393"],"spread","ETH/USD"]
{"event":"heartbeat"}
[560,{"b":[["1282.88000","2.24448680","1665856441.515272"]],"c":"3857473034"},"book-10","ETH/USD"]
[565,["1282.88000","1282.89000","1665856441.515272","2.24448680","34.13590393"],"spread","ETH/USD"]
[560,{"b":[["1282.62000","5.00000000","1665856441.539903"]],"c":"2700426637"},"book-10","ETH/USD"]
[560,{"b":[["1282.63000","0.15590408","1665856441.563241"]],"c":"3383948875"},"book-10","ETH/USD"]
[560,{"b":[["1282.61000","1.00000000","1665856441.563339"]],"c":"4028985391"},"book-10","ETH/USD"]
[560,{"b":[["1282.88000","5.14212040","1665856441.563971"]],"c":"336477416"},"book-10","ETH/USD"]
[565,["1282.88000","1282.89000","1665856441.563971","5.14212040","34.13590393"],"spread","ETH/USD"]
[560,{"b":[["1282.62000","0.00000000","1665856442.016024"],["1282.54000","0.01559093","1665856387.063542","r"]],"c":"486218854"},"book-10","ETH/USD"]
[560,{"b":[["1282.61000","1.15591396","1665856442.039642"]],"c":"2190457516"},"book-10","ETH/USD"]
[560,{"b":[["1282.63000","0.00000000","1665856442.039809"],["1282.48000","0.01559166","1665856433.965813","r"]],"c":"2289125699"},"book-10","ETH/USD"]
[560,{"a":[["1283.08000","2.85357296","1665856442.057291"]],"c":"3173898108"},"book-10","ETH/USD"]
[560,{"b":[["1282.88000","2.24448680","1665856442.152995"]],"c":"3237168061"},"book-10","ETH/USD"]
[565,["1282.88000","1282.89000","1665856442.152995","2.24448680","34.13590393"],"spread","ETH/USD"]
[560,{"b":[["1282.62000","5.00000000","1665856442.177372"]],"c":"4026876324"},"book-10","ETH/USD"]
[560,{"b":[["1282.61000","1.00000000","1665856442.200755"]],"c":"1852958574"},"book-10","ETH/USD"]
[560,{"b":[["1282.88000","5.23378440","1665856442.200788"]],"c":"825815824"},"book-10","ETH/USD"]
[565,["1282.88000","1282.89000","1665856442.200788","5.23378440","34.13590393"],"spread","ETH/USD"]
[560,{"b":[["1282.63000","0.15591396","1665856442.201008"]],"c":"600540485"},"book-10","ETH/USD"]
[560,{"b":[["1282.88000","2.24448680","1665856442.246755"]],"c":"2485751914"},"book-10","ETH/USD"]
[565,["1282.88000","1282.89000","1665856442.246755","2.24448680","34.13590393"],"spread","ETH/USD"]
[560,{"b":[["1282.60000","0.01559020","1665856442.271386"]],"c":"2427728320"},"book-10","ETH/USD"]
{"event":"heartbeat"}
[560,{"b":[["1282.88000","5.04870920","1665856442.583048"]],"c":"2416674958"},"book-10","ETH/USD"]
[565,["1282.88000","1282.89000","1665856442.583048","5.04870920","34.13590393"],"spread","ETH/USD"]
[560,{"b":[["1282.88000","2.24448680","1665856442.631080"]],"c":"2427728320"},"book-10","ETH/USD"]
[565,["1282.88000","1282.89000","1665856442.631080","2.24448680","34.13590393"],"spread","ETH/USD"]
[560,{"a":[["1283.08000","26.14357296","1665856443.348339"]],"c":"91187857"},"book-10","ETH/USD"]
{"event":"heartbeat"}
[560,{"a":[["1282.99000","1.74973856","1665856444.392184"]],"c":"3163962358"},"book-10","ETH/USD"]
[560,{"a":[["1283.13000","4.45000000","1665856444.496315"]],"c":"1484993890"},"book-10","ETH/USD"]
{"event":"heartbeat"}
{"event":"heartbeat"}
{"event":"heartbeat"}
[560,{"b":[["1282.59000","0.00000000","1665856446.714969"],["1282.54000","0.01559093","1665856387.063542","r"]],"c":"851465645"},"book-10","ETH/USD"]
[560,{"a":[["1283.07000","5.78895168","1665856447.430205"]],"c":"2521572764"},"book-10","ETH/USD"]
{"event":"heartbeat"}
[560,{"b":[["1282.62000","0.00000000","1665856448.220035"],["1282.48000","0.01559166","1665856433.965813","r"]],"c":"1309138228"},"book-10","ETH/USD"]
[560,{"b":[["1282.63000","0.00000000","1665856448.243240"],["1282.47000","3.24350895","1665856438.605785","r"]],"c":"26408861"},"book-10","ETH/USD"]
[560,{"b":[["1282.48000","0.17151914","1665856448.243637"]],"c":"3864993414"},"book-10","ETH/USD"]
[560,{"a":[["1283.08000","2.85357296","1665856448.349081"],["1283.06000","23.29000000","1665856448.349103"]],"c":"2027734394"},"book-10","ETH/USD"]
[560,{"a":[["1283.07000","0.00000000","1665856448.372522"],["1283.13000","4.45000000","1665856444.496315","r"]],"c":"1853394531"},"book-10","ETH/USD"]
[560,{"a":[["1283.03000","6.22500000","1665856448.374658"]],"c":"1280608702"},"book-10","ETH/USD"]
[560,{"a":[["1283.05000","5.78895168","1665856448.396762"]],"c":"3202393156"},"book-10","ETH/USD"]
{"event":"heartbeat"}
{"event":"heartbeat"}
[560,{"a":[["1283.06000","0.00000000","1665856449.823543"],["1283.09000","53.38689121","1665856430.175547","r"],["1283.02000","23.62635488","1665856449.823562"]],"c":"1591322119"},"book-10","ETH/USD"]
[560,{"a":[["1282.89000","40.36090393","1665856450.017987"]],"c":"290540540"},"book-10","ETH/USD"]
[565,["1282.88000","1282.89000","1665856450.017987","2.24448680","40.36090393"],"spread","ETH/USD"]
[560,{"a":[["1283.03000","0.00000000","1665856450.042450"],["1283.13000","4.45000000","1665856444.496315","r"]],"c":"1104011912"},"book-10","ETH/USD"]
[560,{"a":[["1282.89000","41.36090393","1665856450.042955"]],"c":"2423774637"},"book-10","ETH/USD"]
[565,["1282.88000","1282.89000","1665856450.042955","2.24448680","41.36090393"],"spread","ETH/USD"]
[560,{"a":[["1283.05000","0.00000000","1665856450.066465"],["1283.15000","12.07964774","1665856429.065186","r"]],"c":"2072739828"},"book-10","ETH/USD"]
[560,{"a":[["1283.01000","6.42015392","1665856450.089450"]],"c":"2479603348"},"book-10","ETH/USD"]
{"event":"heartbeat"}
[560,{"a":[["1283.02000","0.33635488","1665856450.807185"],["1283.00000","24.90076896","1665856450.807200"]],"c":"1415991919"},"book-10","ETH/USD"]
[560,{"a":[["1283.07000","3.91786146","1665856450.907948"]],"c":"2496638496"},"book-10","ETH/USD"]
[560,{"a":[["1283.01000","0.63120224","1665856450.931145"]],"c":"3108461201"},"book-10","ETH/USD"]
[560,{"a":[["1283.06000","5.78895168","1665856450.953617"]],"c":"4147558039"},"book-10","ETH/USD"]
{"event":"heartbeat"}
[560,{"a":[["1283.06000","0.00000000","1665856451.571636"],["1283.13000","4.45000000","1665856444.496315","r"]],"c":"3108461201"},"book-10","ETH/USD"]
[560,{"a":[["1282.98000","5.78895168","1665856451.595981"]],"c":"1399672788"},"book-10","ETH/USD"]
[560,{"a":[["1283.00000","1.61076896","1665856451.863893"],["1282.97000","23.29000000","1665856451.863910"]],"c":"1416601956"},"book-10","ETH/USD"]
[560,{"a":[["1282.98000","0.00000000","1665856451.886899"],["1283.09000","53.38689121","1665856430.175547","r"]],"c":"2563014899"},"book-10","ETH/USD"]
[560,{"a":[["1282.96000","5.78895168","1665856451.909459"]],"c":"4093991346"},"book-10","ETH/USD"]
[560,{"a":[["1282.96000","0.00000000","1665856451.979139"],["1283.09000","53.38689121","1665856430.175547","r"]],"c":"2563014899"},"book-10","ETH/USD"]
[560,{"a":[["1283.06000","5.78895168","1665856452.001982"]],"c":"169430145"},"book-10","ETH/USD"]
{"event":"heartbeat"}
{"event":"heartbeat"}
[560,{"a":[["1282.97000","0.00000000","1665856454.127511"],["1283.09000","53.38689121","1665856430.175547","r"],["1282.98000","23.29000000","1665856454.127530"]],"c":"1729579948"},"book-10","ETH/USD"]
{"event":"heartbeat"}
[560,{"a":[["1282.98000","0.00000000","1665856455.280295"],["1283.09000","53.38689121","1665856430.175547","r"],["1282.90000","23.29000000","1665856455.280317"]],"c":"4214987453"},"book-10","ETH/USD"]
[560,{"a":[["1282.91000","0.00000000","1665856455.419869"],["1283.09000","53.38689121","1665856430.175547","r"],["1282.89000","44.08754983","1665856455.419889"]],"c":"1465466932"},"book-10","ETH/USD"]
[565,["1282.88000","1282.89000","1665856455.419889","2.24448680","44.08754983"],"spread","ETH/USD"]
[560,{"a":[["1283.08000","0.00000000","1665856455.439993"],["1283.13000","4.45000000","1665856444.496315","r"]],"c":"153768818"},"book-10","ETH/USD"]
[560,{"a":[["1283.07000","4.96073261","1665856455.456650"]],"c":"3236665658"},"book-10","ETH/USD"]
{"event":"heartbeat"}
[560,{"a":[["1282.99000","0.27973856","1665856455.779975"]],"c":"1364393040"},"book-10","ETH/USD"]
[560,{"a":[["1283.13000","0.00000000","1665856455.780258"],["1283.15000","12.07964774","1665856429.065186","r"]],"c":"844416569"},"book-10","ETH/USD"]
[560,{"a":[["1282.89000","46.86538637","1665856455.952802"]],"c":"542916833"},"book-10","ETH/USD"]
[565,["1282.88000","1282.89000","1665856455.952802","2.24448680","46.86538637"],"spread","ETH/USD"]
{"event":"heartbeat"}
[560,{"a":[["1282.90000","0.00000000","1665856456.870118"],["1283.24000","0.04000000","1665856384.310846","r"],["1282.99000","23.56973856","1665856456.870182"]],"c":"2129408699"},"book-10","ETH/USD"]
[560,{"a":[["1283.06000","0.00000000","1665856456.893008"],["1283.25000","0.04000000","1665856385.162593","r"]],"c":"2011349206"},"book-10","ETH/USD"]
[560,{"a":[["1282.98000","5.78895168","1665856456.915834"]],"c":"346460907"},"book-10","ETH/USD"]
[560,{"a":[["1282.89000","44.13874047","1665856456.921749"],["1282.98000","8.51559758","1665856456.921762"]],"c":"2498150225"},"book-10","ETH/USD"]
[565,["1282.88000","1282.89000","1665856456.921749","2.24448680","44.13874047"],"spread","ETH/USD"]
[560,{"a":[["1282.95000","5.92000000","1665856457.080850"]],"c":"4191697855"},"book-10","ETH/USD"]
[560,{"a":[["1282.98000","5.78895168","1665856457.126938"],["1282.94000","2.72664590","1665856457.126955"]],"c":"3849348365"},"book-10","ETH/USD"]
[561,[["1282.89000","0.03839853","1665856457.127177","b","l",""]],"trade","ETH/USD"]
[564,{"a":["1282.89000",44,"44.10034194"],"b":["1282.88000",2,"2.24448680"],"c":["1282.89000","0.03839853"],"v":["7507.03003506","14914.16769952"],"p":["1288.91982","1293.18399"],"t":[6918,10935],"l":["1278.00000","1278.00000"],"h":["1300.99000","1308.60000"],"o":["1297.07000","1307.29000"]},"ticker","ETH/USD"]
[567,["1665856457.127177","1665856500.000000","1282.89000","1282.89000","1282.89000","1282.89000","1282.89000","0.03839853",1],"ohlc-1","ETH/USD"]
[560,{"a":[["1282.89000","44.10034194","1665856457.127177"]],"c":"3263635536"},"book-10","ETH/USD"]
[565,["1282.88000","1282.89000","1665856457.127177","2.24448680","44.10034194"],"spread","ETH/USD"]
[560,{"a":[["1282.89000","39.14874047","1665856457.182620"]],"c":"733963525"},"book-10","ETH/USD"]
[565,["1282.88000","1282.89000","1665856457.182620","2.24448680","39.14874047"],"spread","ETH/USD"]
[560,{"a":[["1282.89000","44.09874047","1665856457.182963"]],"c":"2370107224"},"book-10","ETH/USD"]
[565,["1282.88000","1282.89000","1665856457.182963","2.24448680","44.09874047"],"spread","ETH/USD"]
{"event":"heartbeat"}
[560,{"a":[["1282.99000","0.27973856","1665856457.780348"],["1282.93000","23.29000000","1665856457.780368"]],"c":"2600173538"},"book-10","ETH/USD"]
[560,{"a":[["1282.98000","0.00000000","1665856457.804032"],["1283.09000","53.38689121","1665856430.175547","r"]],"c":"2354542743"},"book-10","ETH/USD"]
[560,{"a":[["1282.94000","0.00000000","1665856457.823777"],["1283.15000","12.07964774","1665856429.065186","r"],["1282.92000","2.72664590","1665856457.823802"]],"c":"947069623"},"book-10","ETH/USD"]
[560,{"a":[["1282.92000","8.51559758","1665856457.826752"]],"c":"3763879416"},"book-10","ETH/USD"]
[560,{"a":[["1282.92000","2.72664590","1665856457.937729"]],"c":"947069623"},"book-10","ETH/USD"]
[560,{"a":[["1282.91000","5.78895168","1665856457.960198"]],"c":"914542105"},"book-10","ETH/USD"]
{"event":"heartbeat"}
[560,{"b":[["1282.61000","0.00000000","1665856458.806819"],["1282.41000","0.01559251","1665856387.012975","r"]],"c":"2458540956"},"book-10","ETH/USD"]
[560,{"a":[["1282.93000","0.00000000","1665856458.849649"],["1283.09000","53.38689121","1665856430.175547","r"],["1282.89000","67.38874047","1665856458.849665"]],"c":"3438747343"},"book-10","ETH/USD"]
[565,["1282.88000","1282.89000","1665856458.849665","2.24448680","67.38874047"],"spread","ETH/USD"]
[560,{"a":[["1282.91000","0.00000000","1665856458.873383"],["1283.15000","12.07964774","1665856429.065186","r"]],"c":"3333456360"},"book-10","ETH/USD"]
[560,{"a":[["1283.06000","5.78895168","1665856458.896299"]],"c":"4098117014"},"book-10","ETH/USD"]
[560,{"a":[["1283.08000","8.19485337","1665856459.115781"]],"c":"980506069"},"book-10","ETH/USD"]
[560,{"a":[["1283.08000","11.89687791","1665856459.488146"]],"c":"2933189860"},"book-10","ETH/USD"]
{"event":"heartbeat"}
{"event":"heartbeat"}
{"event":"heartbeat"}
[560,{"a":[["1282.95000","0.00000000","1665856462.061713"],["1283.09000","53.38689121","1665856430.175547","r"]],"c":"572974006"},"book-10","ETH/USD"]
[560,{"a":[["1283.07000","3.91786146","1665856462.202808"]],"c":"4023135685"},"book-10","ETH/USD"]
[560,{"a":[["1282.89000","68.45543546","1665856462.254305"]],"c":"1242256557"},"book-10","ETH/USD"]
[565,["1282.88000","1282.89000","1665856462.254305","2.24448680","68.45543546"],"spread","ETH/USD"]
{"event":"heartbeat"}
[560,{"a":[["1282.89000","72.01468466","1665856462.570456"]],"c":"1891259147"},"book-10","ETH/USD"]
[565,["1282.88000","1282.89000","1665856462.570456","2.24448680","72.01468466"],"spread","ETH/USD"]
[560,{"b":[["1282.48000","0.01559166","1665856462.593447"]],"c":"4048872670"},"book-10","ETH/USD"]
[560,{"b":[["1282.47000","3.39944692","1665856462.633432"]],"c":"422339586"},"book-10","ETH/USD"]
[560,{"b":[["1282.48000","0.17152963","1665856462.820846"]],"c":"2329124194"},"book-10","ETH/USD"]
[560,{"b":[["1282.47000","3.24350895","1665856462.820868"]],"c":"1655381438"},"book-10","ETH/USD"]
{"event":"heartbeat"}
[561,[["1282.88000","0.01558680","1665856463.743032","s","l",""],["1282.88000","0.07549593","1665856463.744312","s","l",""]],"trade","ETH/USD"]
[564,{"a":["1282.89000",72,"72.01468466"],"b":["1282.88000",2,"2.15340407"],"c":["1282.88000","0.07549593"],"v":["7507.12111779","14914.25878225"],"p":["1288.91975","1293.18393"],"t":[6920,10937],"l":["1278.00000","1278.00000"],"h":["1300.99000","1308.60000"],"o":["1297.07000","1307.29000"]},"ticker","ETH/USD"]
[567,["1665856463.744312","1665856500.000000","1282.89000","1282.89000","1282.88000","1282.88000","1282.88296","0.12948126",3],"ohlc-1","ETH/USD"]
[560,{"b":[["1282.88000","2.22890000","1665856463.743032"],["1282.88000","2.15340407","1665856463.744312"]],"c":"1124214378"},"book-10","ETH/USD"]
[565,["1282.88000","1282.89000","1665856463.744312","2.15340407","72.01468466"],"spread","ETH/USD"]
[560,{"b":[["1282.48000","0.01559166","1665856463.770227"]],"c":"3969615338"},"book-10","ETH/USD"]
[560,{"a":[["1282.89000","75.01468466","1665856464.278898"]],"c":"2548727671"},"book-10","ETH/USD"]
[565,["1282.88000","1282.89000","1665856464.278898","2.15340407","75.01468466"],"spread","ETH/USD"]
{"event":"heartbeat"}
[560,{"a":[["1282.89000","71.45543546","1665856464.795202"]],"c":"2660787564"},"book-10","ETH/USD"]
[565,["1282.88000","1282.89000","1665856464.795202","2.15340407","71.45543546"],"spread","ETH/USD"]
[560,{"b":[["1282.48000","0.17154589","1665856464.818689"]],"c":"1508259478"},"book-10","ETH/USD"]
{"event":"heartbeat"}
{"event":"heartbeat"}
{"event":"heartbeat"}
[560,{"b":[["1282.48000","0.01559166","1665856468.214881"]],"c":"2660787564"},"book-10","ETH/USD"]
[560,{"a":[["1282.91000","5.92000000","1665856468.499653"]],"c":"375646013"},"book-10","ETH/USD"]
{"event":"heartbeat"}
{"event":"heartbeat"}
[560,{"a":[["1282.89000","70.38874047","1665856469.578004"]],"c":"1471492637"},"book-10","ETH/USD"]
[565,["1282.88000","1282.89000","1665856469.578004","2.15340407","70.38874047"],"spread","ETH/USD"]
[560,{"a":[["1282.99000","1.44406385","1665856469.632772"]],"c":"2512743506"},"book-10","ETH/USD"]
[560,{"a":[["1282.89000","67.38874047","1665856469.699310"]],"c":"359862671"},"book-10","ETH/USD"]
[565,["1282.88000","1282.89000","1665856469.699310","2.15340407","67.38874047"],"spread","ETH/USD"]
[560,{"a":[["1282.90000","3.00000000","1665856469.739371"]],"c":"1741496100"},"book-10","ETH/USD"]
[560,{"a":[["1283.06000","0.00000000","1665856469.761979"],["1283.08000","11.89687791","1665856459.488146","r"]],"c":"1684690554"},"book-10","ETH/USD"]
[560,{"a":[["1282.92000","0.00000000","1665856469.778350"],["1283.09000","53.38689121","1665856430.175547","r"],["1282.89000","70.11538637","1665856469.778366"]],"c":"58802794"},"book-10","ETH/USD"]
[565,["1282.88000","1282.89000","1665856469.778366","2.15340407","70.11538637"],"spread","ETH/USD"]
[560,{"a":[["1283.05000","5.78895168","1665856469.785301"]],"c":"2278275592"},"book-10","ETH/USD"]
[560,{"a":[["1283.05000","0.00000000","1665856469.880766"],["1283.09000","53.38689121","1665856430.175547","r"]],"c":"58802794"},"book-10","ETH/USD"]
[560,{"a":[["1283.07000","9.70681314","1665856469.904226"]],"c":"288629862"},"book-10","ETH/USD"]
[560,{"a":[["1282.90000","0.00000000","1665856470.033277"],["1283.15000","12.07964774","1665856429.065186","r"]],"c":"3987302210"},"book-10","ETH/USD"]
[560,{"a":[["1283.15000","12.87004701","1665856470.442881"]],"c":"4242012317"},"book-10","ETH/USD"]
{"event":"heartbeat"}
{"event":"heartbeat"}
[560,{"a":[["1282.90000","0.21023675","1665856471.977523"]],"c":"1990402269"},"book-10","ETH/USD"]
[560,{"a":[["1282.99000","1.67478945","1665856472.061113"]],"c":"226962088"},"book-10","ETH/USD"]
[560,{"a":[["1283.08000","12.14289083","1665856472.141934"]],"c":"3862218054"},"book-10","ETH/USD"]
[560,{"a":[["1282.89000","69.11538637","1665856472.515683"]],"c":"2422295969"},"book-10","ETH/USD"]
[565,["1282.88000","1282.89000","1665856472.515683","2.15340407","69.11538637"],"spread","ETH/USD"]
[560,{"a":[["1282.89000","62.89038637","1665856472.515914"]],"c":"1813866820"},"book-10","ETH/USD"]
[565,["1282.88000","1282.89000","1665856472.515914","2.15340407","62.89038637"],"spread","ETH/USD"]
[560,{"a":[["1282.89000","39.60038637","1665856472.528492"]],"c":"2198893259"},"book-10","ETH/USD"]
[565,["1282.88000","1282.89000","1665856472.528492","2.15340407","39.60038637"],"spread","ETH/USD"]
[560,{"b":[["1282.48000","5.01559166","1665856472.530750"]],"c":"2111185990"},"book-10","ETH/USD"]
[560,{"b":[["1282.88000","5.01400567","1665856472.550715"]],"c":"790936817"},"book-10","ETH/USD"]
[565,["1282.88000","1282.89000","1665856472.550715","5.01400567","39.60038637"],"spread","ETH/USD"]
[560,{"b":[["1282.49000","0.15595058","1665856472.554065"]],"c":"3302392081"},"book-10","ETH/USD"]
[560,{"a":[["1282.99000","0.51046416","1665856472.568201"]],"c":"2571045005"},"book-10","ETH/USD"]
[560,{"a":[["1282.89000","33.90038637","1665856472.575126"]],"c":"1335068062"},"book-10","ETH/USD"]
[565,["1282.88000","1282.89000","1665856472.575126","5.01400567","33.90038637"],"spread","ETH/USD"]
[560,{"a":[["1283.02000","23.62635488","1665856472.577729"]],"c":"2162869354"},"book-10","ETH/USD"]
[560,{"b":[["1282.48000","0.01559166","1665856472.577917"]],"c":"3727903894"},"book-10","ETH/USD"]
[560,{"b":[["1282.88000","2.15340407","1665856472.596531"]],"c":"1145687333"},"book-10","ETH/USD"]
[565,["1282.88000","1282.89000","1665856472.596531","2.15340407","33.90038637"],"spread","ETH/USD"]
[560,{"b":[["1282.49000","12.24181479","1665856472.599863"]],"c":"41820917"},"book-10","ETH/USD"]
[560,{"b":[["1282.49000","12.08586421","1665856472.603794"]],"c":"17067158"},"book-10","ETH/USD"]
[560,{"a":[["1282.89000","33.74448244","1665856472.606169"]],"c":"2423354809"},"book-10","ETH/USD"]
[565,["1282.88000","1282.89000","1665856472.606169","2.15340407","33.74448244"],"spread","ETH/USD"]
[560,{"a":[["1283.06000","0.15595058","1665856472.607473"]],"c":"2024799517"},"book-10","ETH/USD"]
[560,{"a":[["1283.06000","0.00000000","1665856472.608689"],["1283.09000","53.38689121","1665856430.175547","r"]],"c":"2423354809"},"book-10","ETH/USD"]
[560,{"a":[["1283.08000","3.94803746","1665856472.610567"]],"c":"1679694253"},"book-10","ETH/USD"]
[560,{"b":[["1282.48000","5.01559166","1665856472.623734"]],"c":"2807641092"},"book-10","ETH/USD"]
[560,{"b":[["1282.50000","0.15595058","1665856472.634928"]],"c":"4097404637"},"book-10","ETH/USD"]
[560,{"a":[["1283.07000","3.91786146","1665856472.636215"]],"c":"1972313225"},"book-10","ETH/USD"]
[560,{"a":[["1282.90000","0.36618733","1665856472.639900"]],"c":"3780444318"},"book-10","ETH/USD"]
[560,{"a":[["1282.89000","33.90043302","1665856472.645369"]],"c":"3031807014"},"book-10","ETH/USD"]
[565,["1282.88000","1282.89000","1665856472.645369","2.15340407","33.90043302"],"spread","ETH/USD"]
[560,{"a":[["1282.90000","0.21023675","1665856472.664722"]],"c":"544188465"},"book-10","ETH/USD"]
{"event":"heartbeat"}
[560,{"a":[["1282.91000","0.00000000","1665856472.961051"],["1283.15000","12.87004701","1665856470.442881","r"]],"c":"586631082"},"book-10","ETH/USD"]
[560,{"b":[["1282.48000","0.01559166","1665856472.986714"]],"c":"1041578086"},"book-10","ETH/USD"]
[560,{"b":[["1282.50000","5.15595058","1665856472.986747"]],"c":"3185669992"},"book-10","ETH/USD"]
[560,{"b":[["1282.51000","0.15591502","1665856473.009844"]],"c":"158518069"},"book-10","ETH/USD"]
[560,{"b":[["1282.50000","5.00000000","1665856473.010261"]],"c":"750680449"},"book-10","ETH/USD"]
[560,{"a":[["1282.89000","31.17378712","1665856473.034055"],["1282.98000","2.72664590","1665856473.034082"]],"c":"1092209651"},"book-10","ETH/USD"]
[565,["1282.88000","1282.89000","1665856473.034055","2.15340407","31.17378712"],"spread","ETH/USD"]
[560,{"a":[["1283.02000","0.33635488","1665856473.143340"]],"c":"1506212787"},"book-10","ETH/USD"]
[560,{"b":[["1282.51000","5.15591502","1665856473.169125"]],"c":"2543162394"},"book-10","ETH/USD"]
[560,{"b":[["1282.51000","5.00000000","1665856473.192308"]],"c":"3384164879"},"book-10","ETH/USD"]
[560,{"b":[["1282.52000","0.15591502","1665856473.192429"]],"c":"1478642009"},"book-10","ETH/USD"]
[560,{"a":[["1282.98000","0.00000000","1665856473.434866"],["1283.15000","12.07964774","1665856473.163516","r"],["1282.89000","33.90043302","1665856473.434882"]],"c":"4250866800"},"book-10","ETH/USD"]
[565,["1282.88000","1282.89000","1665856473.434882","2.15340407","33.90043302"],"spread","ETH/USD"]
[560,{"b":[["1282.52000","6.38091502","1665856473.467069"]],"c":"3523468678"},"book-10","ETH/USD"]
[560,{"b":[["1282.52000","6.22500000","1665856473.490061"]],"c":"1948958021"},"book-10","ETH/USD"]
[560,{"b":[["1282.53000","0.15591502","1665856473.490347"]],"c":"3503006675"},"book-10","ETH/USD"]
[560,{"b":[["1282.52000","11.22500000","1665856473.512747"]],"c":"1916903788"},"book-10","ETH/USD"]
[560,{"b":[["1282.51000","0.00000000","1665856473.512780"],["1282.50000","5.00000000","1665856473.010261","r"]],"c":"2950133993"},"book-10","ETH/USD"]
[560,{"b":[["1282.53000","6.38091502","1665856473.518478"]],"c":"4031727083"},"book-10","ETH/USD"]
[560,{"b":[["1282.53000","6.22500000","1665856473.541829"]],"c":"4068802433"},"book-10","ETH/USD"]
[560,{"b":[["1282.54000","0.17150595","1665856473.542229"]],"c":"2882551899"},"book-10","ETH/USD"]
[560,{"b":[["1282.52000","5.00000000","1665856473.562946"]],"c":"265840217"},"book-10","ETH/USD"]
[560,{"b":[["1282.54000","6.39650595","1665856473.589126"]],"c":"1404593448"},"book-10","ETH/USD"]
[560,{"b":[["1282.55000","0.15591502","1665856473.612569"]],"c":"1449674581"},"book-10","ETH/USD"]
[560,{"b":[["1282.54000","6.24059093","1665856473.612635"]],"c":"390050216"},"book-10","ETH/USD"]
[560,{"b":[["1282.55000","5.15591502","1665856473.616075"]],"c":"1604054156"},"book-10","ETH/USD"]
[560,{"b":[["1282.52000","0.00000000","1665856473.616488"],["1282.50000","5.00000000","1665856473.010261","r"]],"c":"1070029255"},"book-10","ETH/USD"]
[560,{"a":[["1283.12000","23.29000000","1665856473.633686"]],"c":"2671503816"},"book-10","ETH/USD"]
[560,{"b":[["1282.56000","0.15591502","1665856473.639279"]],"c":"169619041"},"book-10","ETH/USD"]
[560,{"b":[["1282.55000","5.00000000","1665856473.639716"]],"c":"4147328281"},"book-10","ETH/USD"]
{"event":"heartbeat"}
[560,{"b":[["1282.54000","0.01559093","1665856474.017578"]],"c":"2387117177"},"book-10","ETH/USD"]
[560,{"b":[["1282.57000","3.39062779","1665856474.067171"]],"c":"3714694140"},"book-10","ETH/USD"]
[560,{"b":[["1282.58000","5.00000000","1665856474.091788"]],"c":"2984660676"},"book-10","ETH/USD"]
[560,{"b":[["1282.59000","0.15591502","1665856474.115220"]],"c":"2187948371"},"book-10","ETH/USD"]
[560,{"b":[["1282.56000","0.00000000","1665856474.115577"],["1282.55000","5.00000000","1665856473.639716","r"]],"c":"3812770007"},"book-10","ETH/USD"]
[560,{"a":[["1283.10000","0.74485932","1665856474.361984"]],"c":"162885189"},"book-10","ETH/USD"]
[560,{"b":[["1282.55000","0.00000000","1665856474.388408"],["1282.54000","0.01559093","1665856474.017578","r"]],"c":"1765806772"},"book-10","ETH/USD"]
[560,{"a":[["1282.89000","35.37043302","1665856474.688608"]],"c":"3272729983"},"book-10","ETH/USD"]
[565,["1282.88000","1282.89000","1665856474.688608","2.15340407","35.37043302"],"spread","ETH/USD"]
{"event":"heartbeat"}
[560,{"a":[["1283.02000","4.78635488","1665856474.803905"]],"c":"360559180"},"book-10","ETH/USD"]
[560,{"a":[["1283.02000","0.33635488","1665856474.954038"]],"c":"3272729983"},"book-10","ETH/USD"]
[560,{"a":[["1282.89000","33.90043302","1665856474.954121"]],"c":"1765806772"},"book-10","ETH/USD"]
[565,["1282.88000","1282.89000","1665856474.954121","2.15340407","33.90043302"],"spread","ETH/USD"]
{"event":"heartbeat"}
[560,{"a":[["1282.89000","10.61043302","1665856475.848861"]],"c":"1453483197"},"book-10","ETH/USD"]
[565,["1282.88000","1282.89000","1665856475.848861","2.15340407","10.61043302"],"spread","ETH/USD"]
[560,{"a":[["1283.08000","0.24601292","1665856475.851441"]],"c":"1204100452"},"book-10","ETH/USD"]
[560,{"b":[["1282.88000","3.99482663","1665856475.855893"]],"c":"2364216404"},"book-10","ETH/USD"]
[565,["1282.88000","1282.89000","1665856475.855893","3.99482663","10.61043302"],"spread","ETH/USD"]
[560,{"b":[["1282.59000","58.63122273","1665856475.874651"]],"c":"3630303290"},"book-10","ETH/USD"]
[560,{"a":[["1282.89000","10.45448244","1665856475.879393"]],"c":"2455897424"},"book-10","ETH/USD"]
[565,["1282.88000","1282.89000","1665856475.879393","3.99482663","10.45448244"],"spread","ETH/USD"]
[560,{"a":[["1283.06000","0.15590302","1665856475.879459"]],"c":"3948421375"},"book-10","ETH/USD"]
[560,{"a":[["1283.01000","23.92120224","1665856475.896683"]],"c":"18933105"},"book-10","ETH/USD"]
[560,{"b":[["1282.59000","58.47530771","1665856475.897862"]],"c":"3051765182"},"book-10","ETH/USD"]
[560,{"b":[["1282.60000","0.17149322","1665856475.897998"]],"c":"1470249886"},"book-10","ETH/USD"]
[560,{"b":[["1282.60000","0.01559020","1665856475.902418"]],"c":"3051765182"},"book-10","ETH/USD"]
[560,{"b":[["1282.88000","2.15340407","1665856475.908483"]],"c":"326924487"},"book-10","ETH/USD"]
[565,["1282.88000","1282.89000","1665856475.908483","2.15340407","10.45448244"],"spread","ETH/USD"]
[560,{"a":[["1283.00000","1.76667198","1665856475.919807"]],"c":"2547156894"},"book-10","ETH/USD"]
[560,{"a":[["1283.06000","0.00000000","1665856475.919911"],["1283.10000","0.74485932","1665856474.361984","r"]],"c":"4008223281"},"book-10","ETH/USD"]
[560,{"b":[["1282.60000","0.17149322","1665856475.926268"]],"c":"721333168"},"book-10","ETH/USD"]
[560,{"a":[["1283.00000","1.61076896","1665856475.932409"]],"c":"953019423"},"book-10","ETH/USD"]
[560,{"a":[["1282.89000","10.61038546","1665856475.944502"]],"c":"2470858727"},"book-10","ETH/USD"]
[565,["1282.88000","1282.89000","1665856475.944502","2.15340407","10.61038546"],"spread","ETH/USD"]
[560,{"a":[["1282.89000","7.88373956","1665856475.945837"],["1282.98000","2.72664590","1665856475.945851"]],"c":"4001258824"},"book-10","ETH/USD"]
[565,["1282.88000","1282.89000","1665856475.945837","2.15340407","7.88373956"],"spread","ETH/USD"]
[560,{"b":[["1282.70000","17.00000000","1665856475.976829"]],"c":"1673299184"},"book-10","ETH/USD"]
[560,{"b":[["1282.60000","0.01559020","1665856476.000268"]],"c":"3615599986"},"book-10","ETH/USD"]
[560,{"b":[["1282.71000","0.15590302","1665856476.000544"]],"c":"399926035"},"book-10","ETH/USD"]
[560,{"b":[["1282.71000","5.15590302","1665856476.001867"]],"c":"4048833295"},"book-10","ETH/USD"]
[560,{"a":[["1282.89000","7.72783654","1665856476.024140"]],"c":"4287774318"},"book-10","ETH/USD"]
[565,["1282.88000","1282.89000","1665856476.024140","2.15340407","7.72783654"],"spread","ETH/USD"]
[560,{"a":[["1283.00000","1.76667198","1665856476.024364"]],"c":"2195391504"},"book-10","ETH/USD"]
[560,{"b":[["1282.71000","5.00000000","1665856476.025592"]],"c":"3073102481"},"book-10","ETH/USD"]
[560,{"b":[["1282.72000","0.15590302","1665856476.025783"]],"c":"731471750"},"book-10","ETH/USD"]
[560,{"a":[["1282.89000","7.75548294","1665856476.273748"]],"c":"271408195"},"book-10","ETH/USD"]
[565,["1282.88000","1282.89000","1665856476.273748","2.15340407","7.75548294"],"spread","ETH/USD"]
[560,{"a":[["1282.89000","7.91138596","1665856476.296986"]],"c":"1224308820"},"book-10","ETH/USD"]
[565,["1282.88000","1282.89000","1665856476.296986","2.15340407","7.91138596"],"spread","ETH/USD"]
[560,{"a":[["1283.00000","1.61076896","1665856476.297038"]],"c":"106805211"},"book-10","ETH/USD"]
[560,{"b":[["1282.78000","12.08313194","1665856476.491672"]],"c":"1452949951"},"book-10","ETH/USD"]
[560,{"b":[["1282.71000","0.00000000","1665856476.518244"],["1282.59000","58.47530771","1665856475.897862","r"]],"c":"1034716624"},"book-10","ETH/USD"]
{"event":"heartbeat"}
[560,{"b":[["1282.78000","0.00000000","1665856476.993987"],["1282.57000","3.39062779","1665856474.067171","r"]],"c":"2920134444"},"book-10","ETH/USD"]
[560,{"b":[["1282.71000","5.00000000","1665856477.020520"]],"c":"106805211"},"book-10","ETH/USD"]
[560,{"a":[["1283.01000","0.63120224","1665856477.038831"],["1283.06000","23.29000000","1665856477.038853"]],"c":"1993234114"},"book-10","ETH/USD"]
{"event":"heartbeat"}
{"event":"heartbeat"}
[560,{"b":[["1282.88000","7.00640151","1665856479.448901"]],"c":"2773400891"},"book-10","ETH/USD"]
[565,["1282.88000","1282.89000","1665856479.448901","7.00640151","7.91138596"],"spread","ETH/USD"]
[560,{"a":[["1282.89000","7.88373956","1665856479.450539"]],"c":"1958165381"},"book-10","ETH/USD"]
[565,["1282.88000","1282.89000","1665856479.450539","7.00640151","7.88373956"],"spread","ETH/USD"]
[560,{"a":[["1283.05000","0.15590180","1665856479.472531"]],"c":"2951188565"},"book-10","ETH/USD"]
[560,{"a":[["1282.89000","7.72783654","1665856479.472545"]],"c":"858702129"},"book-10","ETH/USD"]
[565,["1282.88000","1282.89000","1665856479.472545","7.00640151","7.72783654"],"spread","ETH/USD"]
[560,{"b":[["1282.88000","7.16230331","1665856479.495687"]],"c":"3077446056"},"book-10","ETH/USD"]
[565,["1282.88000","1282.89000","1665856479.495687","7.16230331","7.72783654"],"spread","ETH/USD"]
[560,{"b":[["1282.88000","2.30930587","1665856479.495715"]],"c":"2146981998"},"book-10","ETH/USD"]
[565,["1282.88000","1282.89000","1665856479.495715","2.30930587","7.72783654"],"spread","ETH/USD"]
[560,{"b":[["1282.72000","0.00000000","1665856479.495814"],["1282.57000","3.39062779","1665856474.067171","r"]],"c":"1078473374"},"book-10","ETH/USD"]
[560,{"b":[["1282.72000","0.15590180","1665856479.519287"]],"c":"2579427575"},"book-10","ETH/USD"]
[560,{"b":[["1282.88000","2.15340407","1665856479.519429"]],"c":"115901009"},"book-10","ETH/USD"]
[565,["1282.88000","1282.89000","1665856479.519429","2.15340407","7.72783654"],"spread","ETH/USD"]
[560,{"b":[["1282.76000","12.08332034","1665856479.720616"]],"c":"3046208842"},"book-10","ETH/USD"]
[560,{"b":[["1282.72000","0.00000000","1665856479.743628"],["1282.59000","58.47530771","1665856475.897862","r"]],"c":"1647629069"},"book-10","ETH/USD"]
[560,{"b":[["1282.77000","0.15590180","1665856479.743759"]],"c":"506761880"},"book-10","ETH/USD"]
{"event":"heartbeat"}
{"event":"heartbeat"}
[560,{"b":[["1282.88000","7.43524215","1665856481.124703"]],"c":"2438721709"},"book-10","ETH/USD"]
[565,["1282.88000","1282.89000","1665856481.124703","7.43524215","7.72783654"],"spread","ETH/USD"]
[560,{"b":[["1282.77000","0.00000000","1665856481.147792"],["1282.59000","58.47530771","1665856475.897862","r"]],"c":"1673109152"},"book-10","ETH/USD"]
[560,{"b":[["1282.88000","7.59114395","1665856481.148197"]],"c":"1256930132"},"book-10","ETH/USD"]
[565,["1282.88000","1282.89000","1665856481.148197","7.59114395","7.72783654"],"spread","ETH/USD"]
[560,{"b":[["1282.88000","2.30930587","1665856481.170230"]],"c":"610420516"},"book-10","ETH/USD"]
[565,["1282.88000","1282.89000","1665856481.170230","2.30930587","7.72783654"],"spread","ETH/USD"]
[560,{"b":[["1282.77000","0.15590180","1665856481.193114"]],"c":"2170740798"},"book-10","ETH/USD"]
[560,{"b":[["1282.88000","2.15340407","1665856481.193398"]],"c":"506761880"},"book-10","ETH/USD"]
[565,["1282.88000","1282.89000","1665856481.193398","2.15340407","7.72783654"],"spread","ETH/USD"]
[560,{"b":[["1282.88000","5.59396471","1665856481.284660"]],"c":"3083666343"},"book-10","ETH/USD"]
[565,["1282.88000","1282.89000","1665856481.284660","5.59396471","7.72783654"],"spread","ETH/USD"]
[560,{"b":[["1282.88000","5.74986651","1665856481.307589"]],"c":"1388618389"},"book-10","ETH/USD"]
[565,["1282.88000","1282.89000","1665856481.307589","5.74986651","7.72783654"],"spread","ETH/USD"]
[560,{"b":[["1282.77000","0.00000000","1665856481.307830"],["1282.59000","58.47530771","1665856475.897862","r"]],"c":"4047753500"},"book-10","ETH/USD"]
[560,{"b":[["1282.88000","2.30930587","1665856481.482098"]],"c":"610420516"},"book-10","ETH/USD"]
[565,["1282.88000","1282.89000","1665856481.482098","2.30930587","7.72783654"],"spread","ETH/USD"]
[560,{"b":[["1282.77000","0.15590180","1665856481.505324"]],"c":"2170740798"},"book-10","ETH/USD"]
[560,{"b":[["1282.88000","2.15340407","1665856481.506122"]],"c":"506761880"},"book-10","ETH/USD"]
[565,["1282.88000","1282.89000","1665856481.506122","2.15340407","7.72783654"],"spread","ETH/USD"]
[560,{"a":[["1283.01000","2.10120224","1665856481.702962"]],"c":"4041050967"},"book-10","ETH/USD"]
[560,{"a":[["1283.06000","0.00000000","1665856481.746681"],["1283.08000","0.24601292","1665856475.851441","r"],["1283.01000","25.39120224","1665856481.746696"]],"c":"1487532282"},"book-10","ETH/USD"]
[560,{"a":[["1283.00000","1.76667076","1665856481.770044"]],"c":"4132412851"},"book-10","ETH/USD"]
[560,{"a":[["1283.05000","0.00000000","1665856481.770145"],["1283.09000","53.38689121","1665856430.175547","r"]],"c":"3057055816"},"book-10","ETH/USD"]
{"event":"heartbeat"}
[560,{"b":[["1282.70000","0.00000000","1665856482.357770"],["1282.59000","58.47530771","1665856475.897862","r"]],"c":"4131561188"},"book-10","ETH/USD"]
{"event":"heartbeat"}
[560,{"b":[["1282.88000","5.72908663","1665856483.060509"]],"c":"2157235750"},"book-10","ETH/USD"]
[565,["1282.88000","1282.89000","1665856483.060509","5.72908663","7.72783654"],"spread","ETH/USD"]
[560,{"a":[["1283.06000","0.15590135","1665856483.083546"]],"c":"1991230444"},"book-10","ETH/USD"]
[560,{"a":[["1283.00000","1.61076896","1665856483.083758"]],"c":"3628707493"},"book-10","ETH/USD"]
[560,{"b":[["1282.88000","5.88498798","1665856483.083866"]],"c":"2997071989"},"book-10","ETH/USD"]
[565,["1282.88000","1282.89000","1665856483.083866","5.88498798","7.72783654"],"spread","ETH/USD"]
[560,{"b":[["1282.77000","0.00000000","1665856483.083896"],["1282.57000","3.39062779","1665856474.067171","r"]],"c":"2828365172"},"book-10","ETH/USD"]
[560,{"b":[["1282.88000","2.30930542","1665856483.108231"]],"c":"214406975"},"book-10","ETH/USD"]
[565,["1282.88000","1282.89000","1665856483.108231","2.30930542","7.72783654"],"spread","ETH/USD"]
[560,{"a":[["1283.06000","0.00000000","1665856483.131422"],["1283.09000","53.38689121","1665856430.175547","r"]],"c":"2657057923"},"book-10","ETH/USD"]
[560,{"b":[["1282.88000","2.15340407","1665856483.131514"]],"c":"3383282638"},"book-10","ETH/USD"]
[565,["1282.88000","1282.89000","1665856483.131514","2.15340407","7.72783654"],"spread","ETH/USD"]
[560,{"b":[["1282.77000","0.15590135","1665856483.131611"]],"c":"1424990259"},"book-10","ETH/USD"]
[560,{"a":[["1283.00000","1.76667031","1665856483.131648"]],"c":"1542759173"},"book-10","ETH/USD"]
{"event":"heartbeat"}
{"event":"heartbeat"}
[561,[["1282.88000","0.98391000","1665856485.780163","s","l",""]],"trade","ETH/USD"]
[564,{"a":["1282.89000",7,"7.72783654"],"b":["1282.88000",1,"1.16949407"],"c":["1282.88000","0.98391000"],"v":["7508.10502779","14915.24269225"],"p":["1288.91896","1293.18325"],"t":[6921,10938],"l":["1278.00000","1278.00000"],"h":["1300.99000","1308.60000"],"o":["1297.07000","1307.29000"]},"ticker","ETH/USD"]
[567,["1665856485.780163","1665856500.000000","1282.89000","1282.89000","1282.88000","1282.88000","1282.88034","1.11339126",4],"ohlc-1","ETH/USD"]
[560,{"b":[["1282.88000","1.16949407","1665856485.780164"]],"c":"153715821"},"book-10","ETH/USD"]
[565,["1282.88000","1282.89000","1665856485.780164","1.16949407","7.72783654"],"spread","ETH/USD"]
{"event":"heartbeat"}
[560,{"a":[["1282.89000","7.88373850","1665856485.806974"]],"c":"3060788385"},"book-10","ETH/USD"]
[565,["1282.88000","1282.89000","1665856485.806974","1.16949407","7.88373850"],"spread","ETH/USD"]
[560,{"b":[["1282.72000","0.15590196","1665856485.806999"]],"c":"2568087459"},"book-10","ETH/USD"]
[560,{"a":[["1282.89000","7.92373850","1665856485.807481"]],"c":"4045764086"},"book-10","ETH/USD"]
[565,["1282.88000","1282.89000","1665856485.807481","1.16949407","7.92373850"],"spread","ETH/USD"]
[560,{"a":[["1283.00000","1.61076896","1665856485.807498"]],"c":"176310179"},"book-10","ETH/USD"]
[560,{"b":[["1282.77000","0.00000000","1665856485.807571"],["1282.59000","58.47530771","1665856475.897862","r"]],"c":"2903837507"},"book-10","ETH/USD"]
[560,{"b":[["1282.72000","0.00000000","1665856485.830605"],["1282.57000","3.39062779","1665856474.067171","r"]],"c":"273336174"},"book-10","ETH/USD"]
[560,{"b":[["1282.60000","0.17149216","1665856485.832030"]],"c":"4055341441"},"book-10","ETH/USD"]
{"event":"heartbeat"}
[560,{"a":[["1282.98000","0.00000000","1665856487.068207"],["1283.10000","0.74485932","1665856474.361984","r"],["1282.89000","10.65038440","1665856487.068228"]],"c":"708541069"},"book-10","ETH/USD"]
[565,["1282.88000","1282.89000","1665856487.068228","1.16949407","10.65038440"],"spread","ETH/USD"]
[560,{"a":[["1282.89000","7.92373850","1665856487.377020"],["1282.98000","2.72664590","1665856487.377036"]],"c":"4055341441"},"book-10","ETH/USD"]
[565,["1282.88000","1282.89000","1665856487.377020","1.16949407","7.92373850"],"spread","ETH/USD"]
[560,{"b":[["1282.60000","0.01559020","1665856487.400219"]],"c":"273336174"},"book-10","ETH/USD"]
[560,{"b":[["1282.72000","0.15590196","1665856487.400569"]],"c":"2903837507"},"book-10","ETH/USD"]
{"event":"heartbeat"}
[560,{"a":[["1282.89000","7.88373850","1665856487.821339"]],"c":"1960327182"},"book-10","ETH/USD"]
[565,["1282.88000","1282.89000","1665856487.821339","1.16949407","7.88373850"],"spread","ETH/USD"]
[560,{"b":[["1282.72000","0.00000000","1665856487.844473"],["1282.57000","3.39062779","1665856474.067171","r"]],"c":"419313520"},"book-10","ETH/USD"]
[560,{"b":[["1282.77000","0.15590196","1665856487.844849"]],"c":"3555991421"},"book-10","ETH/USD"]
[560,{"a":[["1282.89000","7.72783654","1665856487.867986"]],"c":"1823635377"},"book-10","ETH/USD"]
[565,["1282.88000","1282.89000","1665856487.867986","1.16949407","7.72783654"],"spread","ETH/USD"]
[560,{"a":[["1283.00000","1.76667092","1665856487.868075"]],"c":"1262078991"},"book-10","ETH/USD"]
[560,{"a":[["1282.89000","4.95000000","1665856488.372979"]],"c":"753269790"},"book-10","ETH/USD"]
[565,["1282.88000","1282.89000","1665856488.372979","1.16949407","4.95000000"],"spread","ETH/USD"]
[560,{"a":[["1282.98000","0.00000000","1665856488.774068"],["1283.10000","0.74485932","1665856474.361984","r"],["1282.89000","7.67664590","1665856488.774092"]],"c":"1547152279"},"book-10","ETH/USD"]
[565,["1282.88000","1282.89000","1665856488.774092","1.16949407","7.67664590"],"spread","ETH/USD"]
{"event":"heartbeat"}
[560,{"a":[["1283.00000","1.61076896","1665856488.797296"]],"c":"1367946393"},"book-10","ETH/USD"]
[560,{"b":[["1282.77000","0.00000000","1665856488.797579"],["1282.57000","3.39062779","1665856474.067171","r"]],"c":"3206245434"},"book-10","ETH/USD"]
[560,{"a":[["1282.89000","7.83254786","1665856488.797650"]],"c":"3240428569"},"book-10","ETH/USD"]
[565,["1282.88000","1282.89000","1665856488.797650","1.16949407","7.83254786"],"spread","ETH/USD"]
[560,{"b":[["1282.72000","0.15590196","1665856488.797692"]],"c":"2041679335"},"book-10","ETH/USD"]
[560,{"b":[["1282.72000","0.00000000","1665856488.820355"],["1282.57000","3.39062779","1665856474.067171","r"]],"c":"3240428569"},"book-10","ETH/USD"]
[560,{"a":[["1282.89000","5.10590196","1665856488.874043"],["1282.98000","2.72664590","1665856488.874059"]],"c":"4243917023"},"book-10","ETH/USD"]
[565,["1282.88000","1282.89000","1665856488.874043","1.16949407","5.10590196"],"spread","ETH/USD"]
[560,{"a":[["1282.89000","4.95000000","1665856488.897200"]],"c":"3762553665"},"book-10","ETH/USD"]
[565,["1282.88000","1282.89000","1665856488.897200","1.16949407","4.95000000"],"spread","ETH/USD"]
[560,{"a":[["1283.06000","2.72400311","1665856488.923064"]],"c":"57748296"},"book-10","ETH/USD"]
{"event":"heartbeat"}
[560,{"b":[["1282.77000","5.00000000","1665856490.518475"]],"c":"562981232"},"book-10","ETH/USD"]
[560,{"b":[["1282.71000","0.00000000","1665856490.543385"],["1282.57000","3.39062779","1665856474.067171","r"]],"c":"52192364"},"book-10","ETH/USD"]
{"event":"heartbeat"}
[560,{"b":[["1282.88000","2.16949407","1665856491.560948"]],"c":"3549863319"},"book-10","ETH/USD"]
[565,["1282.88000","1282.89000","1665856491.560948","2.16949407","4.95000000"],"spread","ETH/USD"]
{"event":"heartbeat"}
{"event":"heartbeat"}
{"event":"heartbeat"}
{"event":"heartbeat"}
[560,{"b":[["1282.78000","0.15589846","1665856495.185430"]],"c":"1607755316"},"book-10","ETH/USD"]
[560,{"a":[["1282.98000","2.88254436","1665856495.185657"]],"c":"3162500934"},"book-10","ETH/USD"]
[560,{"a":[["1282.98000","2.72664590","1665856495.208655"]],"c":"1607755316"},"book-10","ETH/USD"]
[560,{"a":[["1283.00000","1.76666742","1665856495.208839"]],"c":"540774551"},"book-10","ETH/USD"]
[560,{"a":[["1283.00000","1.61076896","1665856495.232081"]],"c":"1607755316"},"book-10","ETH/USD"]
[560,{"a":[["1282.97000","0.15589846","1665856495.232227"]],"c":"3539638860"},"book-10","ETH/USD"]
{"event":"heartbeat"}
[560,{"b":[["1282.70000","15.50000000","1665856496.743238"]],"c":"3860138619"},"book-10","ETH/USD"]
{"event":"heartbeat"}
{"event":"heartbeat"}
[560,{"a":[["1282.89000","5.69354781","1665856498.662162"]],"c":"21783816"},"book-10","ETH/USD"]
[565,["1282.88000","1282.89000","1665856498.662162","2.16949407","5.69354781"],"spread","ETH/USD"]
[560,{"a":[["1282.89000","0.74354781","1665856498.739742"]],"c":"1411430961"},"book-10","ETH/USD"]
[565,["1282.88000","1282.89000","1665856498.739742","2.16949407","0.74354781"],"spread","ETH/USD"]
[560,{"b":[["1282.88000","6.81920191","1665856498.746315"]],"c":"3930512288"},"book-10","ETH/USD"]
[565,["1282.88000","1282.89000","1665856498.746315","6.81920191","0.74354781"],"spread","ETH/USD"]
[560,{"b":[["1282.78000","0.00000000","1665856498.769243"],["1282.59000","58.47530771","1665856475.897862","r"]],"c":"1521568024"},"book-10","ETH/USD"]
[560,{"a":[["1282.97000","0.00000000","1665856498.769274"],["1283.08000","0.24601292","1665856475.851441","r"]],"c":"157059583"},"book-10","ETH/USD"]
[560,{"a":[["1283.00000","1.76666560","1665856498.769472"]],"c":"2255752529"},"book-10","ETH/USD"]
[560,{"b":[["1282.88000","6.97509855","1665856498.769497"]],"c":"1087040788"},"book-10","ETH/USD"]
[565,["1282.88000","1282.89000","1665856498.769497","6.97509855","0.74354781"],"spread","ETH/USD"]
[560,{"a":[["1283.00000","1.61076896","1665856498.792974"]],"c":"3487721914"},"book-10","ETH/USD"]
[560,{"a":[["1283.05000","0.15589664","1665856498.793040"]],"c":"2721374298"},"book-10","ETH/USD"]
[560,{"b":[["1282.88000","11.97509855","1665856498.794067"]],"c":"3637056269"},"book-10","ETH/USD"]
[565,["1282.88000","1282.89000","1665856498.794067","11.97509855","0.74354781"],"spread","ETH/USD"]
{"event":"heartbeat"}
[560,{"a":[["1282.98000","0.00000000","1665856498.911824"],["1283.08000","0.24601292","1665856475.851441","r"]],"c":"3308176591"},"book-10","ETH/USD"]
[560,{"a":[["1283.05000","0.00000000","1665856498.934853"],["1283.09000","53.38689121","1665856498.614725","r"]],"c":"2812614657"},"book-10","ETH/USD"]
[560,{"a":[["1283.08000","0.40190667","1665856498.935262"]],"c":"2366717497"},"book-10","ETH/USD"]
[560,{"b":[["1282.77000","0.00000000","1665856498.936001"],["1282.57000","3.39062779","1665856474.067171","r"]],"c":"270450048"},"book-10","ETH/USD"]
[560,{"a":[["1283.07000","4.07375521","1665856498.957987"]],"c":"3812522195"},"book-10","ETH/USD"]
[560,{"a":[["1283.08000","0.24601292","1665856498.958133"]],"c":"3381288683"},"book-10","ETH/USD"]
[560,{"a":[["1283.07000","3.91786146","1665856498.981114"]],"c":"984259512"},"book-10","ETH/USD"]
[560,{"a":[["1283.05000","0.15589375","1665856498.981542"]],"c":"1576012970"},"book-10","ETH/USD"]
[560,{"b":[["1282.88000","7.32539071","1665856499.030457"]],"c":"2394192635"},"book-10","ETH/USD"]
[565,["1282.88000","1282.89000","1665856499.030457","7.32539071","0.74354781"],"spread","ETH/USD"]
[560,{"a":[["1283.05000","0.00000000","1665856499.053544"],["1283.09000","53.38689121","1665856498.614725","r"]],"c":"157918304"},"book-10","ETH/USD"]
[560,{"a":[["1283.00000","1.76666271","1665856499.053627"]],"c":"2366626601"},"book-10","ETH/USD"]
[560,{"b":[["1282.88000","7.16949407","1665856499.053665"]],"c":"1456143591"},"book-10","ETH/USD"]
[565,["1282.88000","1282.89000","1665856499.053665","7.16949407","0.74354781"],"spread","ETH/USD"]
[560,{"b":[["1282.77000","0.15589375","1665856499.053742"]],"c":"1638891745"},"book-10","ETH/USD"]
[560,{"a":[["1283.05000","2.72664590","1665856499.414656"]],"c":"2437627332"},"book-10","ETH/USD"]
[560,{"b":[["1282.70000","0.00000000","1665856499.477808"],["1282.57000","3.39062779","1665856474.067171","r"]],"c":"118440536"},"book-10","ETH/USD"]
{"event":"heartbeat"}
[560,{"b":[["1282.77000","5.15589375","1665856500.017814"]],"c":"1685212561"},"book-10","ETH/USD"]
[560,{"b":[["1282.88000","2.16949407","1665856500.018217"]],"c":"3466346973"},"book-10","ETH/USD"]
[565,["1282.88000","1282.89000","1665856500.018217","2.16949407","0.74354781"],"spread","ETH/USD"]
[560,{"b":[["1282.77000","5.00000000","1665856500.040976"]],"c":"3600315087"},"book-10","ETH/USD"]
[560,{"b":[["1282.78000","0.15589375","1665856500.041308"]],"c":"4016622097"},"book-10","ETH/USD"]
[560,{"b":[["1282.77000","0.00000000","1665856500.043341"],["1282.57000","3.39062779","1665856474.067171","r"]],"c":"3947189998"},"book-10","ETH/USD"]
[560,{"b":[["1282.77000","5.00000000","1665856500.043501"]],"c":"4016622097"},"book-10","ETH/USD"]
[560,{"a":[["1282.89000","0.00000000","1665856500.196733"],["1283.09000","53.38689121","1665856498.614725","r"]],"c":"1004877783"},"book-10","ETH/USD"]
[565,["1282.88000","1282.90000","1665856500.018217","2.16949407","0.21023675"],"spread","ETH/USD"]
[560,{"b":[["1282.78000","5.15589375","1665856500.221118"]],"c":"811755451"},"book-10","ETH/USD"]
[560,{"b":[["1282.89000","1.00000000","1665856500.221233"]],"c":"3068438533"},"book-10","ETH/USD"]
[565,["1282.89000","1282.90000","1665856500.221233","1.00000000","0.21023675"],"spread","ETH/USD"]
[560,{"b":[["1282.79000","0.17148164","1665856500.244578"]],"c":"1341208084"},"book-10","ETH/USD"]
[560,{"b":[["1282.78000","5.00000000","1665856500.244611"]],"c":"771388890"},"book-10","ETH/USD"]
[560,{"a":[["1283.00000","1.61076896","1665856500.267766"]],"c":"3130896696"},"book-10","ETH/USD"]
[560,{"a":[["1282.99000","1.25401197","1665856500.271218"]],"c":"4146531267"},"book-10","ETH/USD"]
[560,{"b":[["1282.79000","0.01558789","1665856500.277958"]],"c":"1764303520"},"book-10","ETH/USD"]
[560,{"b":[["1282.78000","0.00000000","1665856500.516305"],["1282.59000","58.47530771","1665856475.897862","r"]],"c":"3513409041"},"book-10","ETH/USD"]
[560,{"b":[["1282.89000","6.00000000","1665856500.516437"]],"c":"1381499184"},"book-10","ETH/USD"]
[565,["1282.89000","1282.90000","1665856500.516437","6.00000000","0.21023675"],"spread","ETH/USD"]
[560,{"b":[["1282.88000","1.16949407","1665856500.541926"]],"c":"3129674775"},"book-10","ETH/USD"]
[560,{"b":[["1282.77000","0.00000000","1665856500.548453"],["1282.57000","3.39062779","1665856474.067171","r"]],"c":"3198587112"},"book-10","ETH/USD"]
{"event":"heartbeat"}
[560,{"b":[["1282.88000","0.00000000","1665856501.068789"],["1282.54000","0.01559093","1665856474.017578","r"]],"c":"2674584485"},"book-10","ETH/USD"]
[560,{"b":[["1282.88000","2.32220000","1665856501.441993"]],"c":"969296766"},"book-10","ETH/USD"]
{"event":"heartbeat"}
[560,{"a":[["1282.90000","0.25023675","1665856501.980171"]],"c":"2565078207"},"book-10","ETH/USD"]
[565,["1282.89000","1282.90000","1665856501.980171","6.00000000","0.25023675"],"spread","ETH/USD"]
[560,{"a":[["1282.90000","0.29023675","1665856501.990936"]],"c":"2700878525"},"book-10","ETH/USD"]
[565,["1282.89000","1282.90000","1665856501.990936","6.00000000","0.29023675"],"spread","ETH/USD"]
[560,{"a":[["1282.99000","6.95401197","1665856502.025943"]],"c":"4207153471"},"book-10","ETH/USD"]
[560,{"a":[["1282.90000","0.38410075","1665856502.035427"]],"c":"149982540"},"book-10","ETH/USD"]
[565,["1282.89000","1282.90000","1665856502.035427","6.00000000","0.38410075"],"spread","ETH/USD"]
[560,{"a":[["1283.01000","2.10120224","1665856502.047711"],["1283.00000","24.90076896","1665856502.047729"]],"c":"371974535"},"book-10","ETH/USD"]
[560,{"b":[["1282.89000","1.00000000","1665856502.051544"]],"c":"2501492390"},"book-10","ETH/USD"]
[565,["1282.89000","1282.90000","1665856502.051544","1.00000000","0.38410075"],"spread","ETH/USD"]
[560,{"a":[["1282.99000","6.21046416","1665856502.082127"]],"c":"733982370"},"book-10","ETH/USD"]
[560,{"a":[["1282.98000","0.74354781","1665856502.130318"]],"c":"3526720113"},"book-10","ETH/USD"]
[560,{"b":[["1282.89000","0.00000000","1665856502.135858"],["1282.54000","0.01559093","1665856474.017578","r"]],"c":"2829516399"},"book-10","ETH/USD"]
[565,["1282.88000","1282.90000","1665856502.035427","2.32220000","0.38410075"],"spread","ETH/USD"]
[560,{"a":[["1283.05000","0.00000000","1665856502.221897"],["1283.09000","53.38689121","1665856498.614725","r"],["1282.97000","2.72664590","1665856502.221915"]],"c":"1781753704"},"book-10","ETH/USD"]
[560,{"b":[["1282.77000","5.00000000","1665856502.246795"]],"c":"657283464"},"book-10","ETH/USD"]
[560,{"b":[["1282.76000","0.00000000","1665856502.315305"],["1282.54000","0.01559093","1665856474.017578","r"]],"c":"3239700388"},"book-10","ETH/USD"]
[560,{"a":[["1282.96000","24.00000000","1665856502.409647"]],"c":"1559506449"},"book-10","ETH/USD"]
[560,{"a":[["1282.99000","0.51046416","1665856502.433644"]],"c":"1812780626"},"book-10","ETH/USD"]
[560,{"a":[["1282.92000","5.70000000","1665856502.434615"]],"c":"4258289939"},"book-10","ETH/USD"]
[560,{"a":[["1282.97000","0.00000000","1665856502.449778"],["1283.07000","3.91786146","1665856498.981114","r"],["1282.95000","2.72664590","1665856502.449795"]],"c":"2613598590"},"book-10","ETH/USD"]
[560,{"a":[["1283.00000","1.61076896","1665856502.768130"],["1282.94000","23.29000000","1665856502.768147"]],"c":"3404668389"},"book-10","ETH/USD"]
{"event":"heartbeat"}
[560,{"b":[["1282.57000","0.00000000","1665856502.910409"],["1282.49000","12.08586421","1665856472.603794","r"]],"c":"1538209166"},"book-10","ETH/USD"]
[560,{"a":[["1282.90000","5.37410075","1665856503.081559"]],"c":"1059500377"},"book-10","ETH/USD"]
[565,["1282.88000","1282.90000","1665856503.081559","2.32220000","5.37410075"],"spread","ETH/USD"]
[560,{"b":[["1282.60000","3.28055251","1665856503.437479"]],"c":"1838861661"},"book-10","ETH/USD"]
[560,{"b":[["1282.61000","5.00000000","1665856503.479919"]],"c":"1727510044"},"book-10","ETH/USD"]
[560,{"b":[["1282.77000","0.00000000","1665856503.479934"],["1282.49000","12.08586421","1665856472.603794","r"]],"c":"2031479571"},"book-10","ETH/USD"]
[560,{"a":[["1282.96000","0.00000000","1665856503.569889"],["1283.06000","2.72400311","1665856488.923064","r"]],"c":"801613767"},"book-10","ETH/USD"]
[560,{"a":[["1282.98000","0.00000000","1665856503.652359"],["1283.07000","3.91786146","1665856498.981114","r"]],"c":"136147455"},"book-10","ETH/USD"]
[560,{"a":[["1282.89000","0.74354781","1665856503.702440"]],"c":"4245930790"},"book-10","ETH/USD"]
[565,["1282.88000","1282.89000","1665856503.702440","2.32220000","0.74354781"],"spread","ETH/USD"]
{"event":"heartbeat"}
[560,{"a":[["1282.93000","23.50000000","1665856503.977941"]],"c":"2218291143"},"book-10","ETH/USD"]
[560,{"a":[["1282.94000","0.00000000","1665856504.021656"],["1283.06000","2.72400311","1665856488.923064","r"],["1282.93000","46.79000000","1665856504.021671"]],"c":"2521803971"},"book-10","ETH/USD"]
[560,{"a":[["1282.90000","0.38410075","1665856504.046652"]],"c":"926549918"},"book-10","ETH/USD"]
[560,{"a":[["1282.89000","5.73354781","1665856504.047991"]],"c":"661053459"},"book-10","ETH/USD"]
[565,["1282.88000","1282.89000","1665856504.047991","2.32220000","5.73354781"],"spread","ETH/USD"]
[560,{"a":[["1282.93000","23.29000000","1665856504.053008"]],"c":"1384225334"},"book-10","ETH/USD"]
{"event":"heartbeat"}
{"event":"heartbeat"}
{"event":"heartbeat"}
[560,{"b":[["1282.60000","3.43646799","1665856507.121617"]],"c":"3221916123"},"book-10","ETH/USD"]
[560,{"a":[["1282.89000","5.88946329","1665856507.121721"]],"c":"4087600246"},"book-10","ETH/USD"]
[565,["1282.88000","1282.89000","1665856507.121721","2.32220000","5.88946329"],"spread","ETH/USD"]
[560,{"b":[["1282.50000","0.15591548","1665856507.150228"]],"c":"1309045629"},"book-10","ETH/USD"]
[560,{"b":[["1282.60000","3.28055251","1665856507.153264"]],"c":"1615702017"},"book-10","ETH/USD"]
[560,{"a":[["1282.93000","0.00000000","1665856507.165647"],["1283.07000","3.91786146","1665856498.981114","r"],["1282.89000","29.17946329","1665856507.165665"]],"c":"3067029309"},"book-10","ETH/USD"]
[565,["1282.88000","1282.89000","1665856507.165665","2.32220000","29.17946329"],"spread","ETH/USD"]
{"event":"heartbeat"}
[560,{"b":[["1282.50000","0.00000000","1665856508.352049"],["1282.49000","12.08586421","1665856472.603794","r"]],"c":"1876751959"},"book-10","ETH/USD"]
[560,{"b":[["1282.59000","58.63122319","1665856508.352221"]],"c":"3015113580"},"book-10","ETH/USD"]
{"event":"heartbeat"}
[560,{"b":[["1282.59000","58.47530771","1665856509.753388"]],"c":"1876751959"},"book-10","ETH/USD"]
[560,{"b":[["1282.60000","3.43646647","1665856509.753645"]],"c":"1710342476"},"book-10","ETH/USD"]
{"event":"heartbeat"}
{"event":"heartbeat"}
{"event":"heartbeat"}
[560,{"b":[["1282.61000","5.15591335","1665856511.889465"]],"c":"1043920241"},"book-10","ETH/USD"]
[560,{"b":[["1282.60000","3.28055251","1665856511.889894"]],"c":"873841258"},"book-10","ETH/USD"]
{"event":"heartbeat"}
[560,{"b":[["1282.62000","0.15591335","1665856513.160912"]],"c":"4074589252"},"book-10","ETH/USD"]
[560,{"b":[["1282.61000","5.00000000","1665856513.162625"]],"c":"3777816757"},"book-10","ETH/USD"]
